
======================================================================
ERROR: test_analyze_metric (metrics.tests.test_apis.APITests)
----------------------------------------------------------------------
Traceback (most recent call last):
  File "/home/nadeemramli/workspace/github.com/nadeemramli/mapping-of-metrics/metric-map-app/backend/metricMapAPI/metrics/tests/test_apis.py", line 120, in test_analyze_metric
    url = self.get_client_project_url('metric-analyze', pk=self.metric.pk)
  File "/home/nadeemramli/workspace/github.com/nadeemramli/mapping-of-metrics/metric-map-app/backend/metricMapAPI/metrics/tests/test_apis.py", line 42, in get_client_project_url
    return reverse(viewname, kwargs={'client_pk': client_pk, 'project_pk': project_pk, **kwargs})
  File "/home/nadeemramli/.pyenv/versions/3.10.7/lib/python3.10/site-packages/django/urls/base.py", line 88, in reverse
    return resolver._reverse_with_prefix(view, prefix, *args, **kwargs)
  File "/home/nadeemramli/.pyenv/versions/3.10.7/lib/python3.10/site-packages/django/urls/resolvers.py", line 851, in _reverse_with_prefix
    raise NoReverseMatch(msg)
django.urls.exceptions.NoReverseMatch: Reverse for 'metric-analyze' with keyword arguments '{'client_pk': 2, 'project_pk': 1, 'pk': 1}' not found. 6 pattern(s) tried: ['api/clients/(?P<client__pk>[^/.]+)/projects/(?P<project__pk>[^/.]+)/metrics/(?P<pk>[^/.]+)/analyze/$', 'api/clients/(?P<client__pk>[^/.]+)/projects/(?P<project__pk>[^/.]+)/metrics/(?P<pk>[^/.]+)/analyze/$', 'api/clients/(?P<client__pk>[^/.]+)/projects/(?P<project__pk>[^/.]+)/metrics/(?P<pk>[^/.]+)/analyze/$', 'api/clients/(?P<client__pk>[^/.]+)/projects/(?P<project__pk>[^/.]+)/metrics/(?P<pk>[^/.]+)/analyze/$', 'api/clients/(?P<client__pk>[^/.]+)/projects/(?P<project__pk>[^/.]+)/metrics/(?P<pk>[^/.]+)/analyze/$', 'api/clients/(?P<client__pk>[^/.]+)/projects/(?P<project__pk>[^/.]+)/metrics/(?P<pk>[^/.]+)/analyze/$']

======================================================================
ERROR: test_analyze_metric (metrics.tests.test_apis.APITests)
----------------------------------------------------------------------
Traceback (most recent call last):
  File "/home/nadeemramli/.pyenv/versions/3.10.7/lib/python3.10/site-packages/django/db/backends/utils.py", line 103, in _execute
    return self.cursor.execute(sql)
psycopg2.errors.ForeignKeyViolation: insert or update on table "metrics_project" violates foreign key constraint "metrics_project_tenant_id_db4a1170_fk_metrics_client_id"
DETAIL:  Key (tenant_id)=(2) is not present in table "metrics_client".


The above exception was the direct cause of the following exception:

Traceback (most recent call last):
  File "/home/nadeemramli/.pyenv/versions/3.10.7/lib/python3.10/site-packages/django/test/testcases.py", line 296, in _setup_and_call
    self._post_teardown()
  File "/home/nadeemramli/.pyenv/versions/3.10.7/lib/python3.10/site-packages/django/test/testcases.py", line 1102, in _post_teardown
    self._fixture_teardown()
  File "/home/nadeemramli/.pyenv/versions/3.10.7/lib/python3.10/site-packages/django/test/testcases.py", line 1333, in _fixture_teardown
    connections[db_name].check_constraints()
  File "/home/nadeemramli/.pyenv/versions/3.10.7/lib/python3.10/site-packages/django/db/backends/postgresql/base.py", line 385, in check_constraints
    cursor.execute("SET CONSTRAINTS ALL IMMEDIATE")
  File "/home/nadeemramli/.pyenv/versions/3.10.7/lib/python3.10/site-packages/django/db/backends/utils.py", line 79, in execute
    return self._execute_with_wrappers(
  File "/home/nadeemramli/.pyenv/versions/3.10.7/lib/python3.10/site-packages/django/db/backends/utils.py", line 92, in _execute_with_wrappers
    return executor(sql, params, many, context)
  File "/home/nadeemramli/.pyenv/versions/3.10.7/lib/python3.10/site-packages/django/db/backends/utils.py", line 100, in _execute
    with self.db.wrap_database_errors:
  File "/home/nadeemramli/.pyenv/versions/3.10.7/lib/python3.10/site-packages/django/db/utils.py", line 91, in __exit__
    raise dj_exc_value.with_traceback(traceback) from exc_value
  File "/home/nadeemramli/.pyenv/versions/3.10.7/lib/python3.10/site-packages/django/db/backends/utils.py", line 103, in _execute
    return self.cursor.execute(sql)
django.db.utils.IntegrityError: insert or update on table "metrics_project" violates foreign key constraint "metrics_project_tenant_id_db4a1170_fk_metrics_client_id"
DETAIL:  Key (tenant_id)=(2) is not present in table "metrics_client".


======================================================================
ERROR: test_authentication_required (metrics.tests.test_apis.APITests)
----------------------------------------------------------------------
Traceback (most recent call last):
  File "/home/nadeemramli/workspace/github.com/nadeemramli/mapping-of-metrics/metric-map-app/backend/metricMapAPI/metrics/tests/test_apis.py", line 254, in test_authentication_required
    url = self.get_client_project_url('metric-list')
  File "/home/nadeemramli/workspace/github.com/nadeemramli/mapping-of-metrics/metric-map-app/backend/metricMapAPI/metrics/tests/test_apis.py", line 42, in get_client_project_url
    return reverse(viewname, kwargs={'client_pk': client_pk, 'project_pk': project_pk, **kwargs})
  File "/home/nadeemramli/.pyenv/versions/3.10.7/lib/python3.10/site-packages/django/urls/base.py", line 88, in reverse
    return resolver._reverse_with_prefix(view, prefix, *args, **kwargs)
  File "/home/nadeemramli/.pyenv/versions/3.10.7/lib/python3.10/site-packages/django/urls/resolvers.py", line 851, in _reverse_with_prefix
    raise NoReverseMatch(msg)
django.urls.exceptions.NoReverseMatch: Reverse for 'metric-list' with keyword arguments '{'client_pk': 2, 'project_pk': 2}' not found. 6 pattern(s) tried: ['api/clients/(?P<client__pk>[^/.]+)/projects/(?P<project__pk>[^/.]+)/metrics/$', 'api/clients/(?P<client__pk>[^/.]+)/projects/(?P<project__pk>[^/.]+)/metrics/$', 'api/clients/(?P<client__pk>[^/.]+)/projects/(?P<project__pk>[^/.]+)/metrics/$', 'api/clients/(?P<client__pk>[^/.]+)/projects/(?P<project__pk>[^/.]+)/metrics/$', 'api/clients/(?P<client__pk>[^/.]+)/projects/(?P<project__pk>[^/.]+)/metrics/$', 'api/clients/(?P<client__pk>[^/.]+)/projects/(?P<project__pk>[^/.]+)/metrics/$']

======================================================================
ERROR: test_authentication_required (metrics.tests.test_apis.APITests)
----------------------------------------------------------------------
Traceback (most recent call last):
  File "/home/nadeemramli/.pyenv/versions/3.10.7/lib/python3.10/site-packages/django/db/backends/utils.py", line 103, in _execute
    return self.cursor.execute(sql)
psycopg2.errors.ForeignKeyViolation: insert or update on table "metrics_project" violates foreign key constraint "metrics_project_tenant_id_db4a1170_fk_metrics_client_id"
DETAIL:  Key (tenant_id)=(2) is not present in table "metrics_client".


The above exception was the direct cause of the following exception:

Traceback (most recent call last):
  File "/home/nadeemramli/.pyenv/versions/3.10.7/lib/python3.10/site-packages/django/test/testcases.py", line 296, in _setup_and_call
    self._post_teardown()
  File "/home/nadeemramli/.pyenv/versions/3.10.7/lib/python3.10/site-packages/django/test/testcases.py", line 1102, in _post_teardown
    self._fixture_teardown()
  File "/home/nadeemramli/.pyenv/versions/3.10.7/lib/python3.10/site-packages/django/test/testcases.py", line 1333, in _fixture_teardown
    connections[db_name].check_constraints()
  File "/home/nadeemramli/.pyenv/versions/3.10.7/lib/python3.10/site-packages/django/db/backends/postgresql/base.py", line 385, in check_constraints
    cursor.execute("SET CONSTRAINTS ALL IMMEDIATE")
  File "/home/nadeemramli/.pyenv/versions/3.10.7/lib/python3.10/site-packages/django/db/backends/utils.py", line 79, in execute
    return self._execute_with_wrappers(
  File "/home/nadeemramli/.pyenv/versions/3.10.7/lib/python3.10/site-packages/django/db/backends/utils.py", line 92, in _execute_with_wrappers
    return executor(sql, params, many, context)
  File "/home/nadeemramli/.pyenv/versions/3.10.7/lib/python3.10/site-packages/django/db/backends/utils.py", line 100, in _execute
    with self.db.wrap_database_errors:
  File "/home/nadeemramli/.pyenv/versions/3.10.7/lib/python3.10/site-packages/django/db/utils.py", line 91, in __exit__
    raise dj_exc_value.with_traceback(traceback) from exc_value
  File "/home/nadeemramli/.pyenv/versions/3.10.7/lib/python3.10/site-packages/django/db/backends/utils.py", line 103, in _execute
    return self.cursor.execute(sql)
django.db.utils.IntegrityError: insert or update on table "metrics_project" violates foreign key constraint "metrics_project_tenant_id_db4a1170_fk_metrics_client_id"
DETAIL:  Key (tenant_id)=(2) is not present in table "metrics_client".


======================================================================
ERROR: test_create_action_remark (metrics.tests.test_apis.APITests)
----------------------------------------------------------------------
Traceback (most recent call last):
  File "/home/nadeemramli/workspace/github.com/nadeemramli/mapping-of-metrics/metric-map-app/backend/metricMapAPI/metrics/tests/test_apis.py", line 140, in test_create_action_remark
    url = self.get_client_project_url('metric-action_remarks', pk=self.metric.pk)
  File "/home/nadeemramli/workspace/github.com/nadeemramli/mapping-of-metrics/metric-map-app/backend/metricMapAPI/metrics/tests/test_apis.py", line 42, in get_client_project_url
    return reverse(viewname, kwargs={'client_pk': client_pk, 'project_pk': project_pk, **kwargs})
  File "/home/nadeemramli/.pyenv/versions/3.10.7/lib/python3.10/site-packages/django/urls/base.py", line 88, in reverse
    return resolver._reverse_with_prefix(view, prefix, *args, **kwargs)
  File "/home/nadeemramli/.pyenv/versions/3.10.7/lib/python3.10/site-packages/django/urls/resolvers.py", line 851, in _reverse_with_prefix
    raise NoReverseMatch(msg)
django.urls.exceptions.NoReverseMatch: Reverse for 'metric-action_remarks' not found. 'metric-action_remarks' is not a valid view function or pattern name.

======================================================================
ERROR: test_create_action_remark (metrics.tests.test_apis.APITests)
----------------------------------------------------------------------
Traceback (most recent call last):
  File "/home/nadeemramli/.pyenv/versions/3.10.7/lib/python3.10/site-packages/django/db/backends/utils.py", line 103, in _execute
    return self.cursor.execute(sql)
psycopg2.errors.ForeignKeyViolation: insert or update on table "metrics_project" violates foreign key constraint "metrics_project_tenant_id_db4a1170_fk_metrics_client_id"
DETAIL:  Key (tenant_id)=(2) is not present in table "metrics_client".


The above exception was the direct cause of the following exception:

Traceback (most recent call last):
  File "/home/nadeemramli/.pyenv/versions/3.10.7/lib/python3.10/site-packages/django/test/testcases.py", line 296, in _setup_and_call
    self._post_teardown()
  File "/home/nadeemramli/.pyenv/versions/3.10.7/lib/python3.10/site-packages/django/test/testcases.py", line 1102, in _post_teardown
    self._fixture_teardown()
  File "/home/nadeemramli/.pyenv/versions/3.10.7/lib/python3.10/site-packages/django/test/testcases.py", line 1333, in _fixture_teardown
    connections[db_name].check_constraints()
  File "/home/nadeemramli/.pyenv/versions/3.10.7/lib/python3.10/site-packages/django/db/backends/postgresql/base.py", line 385, in check_constraints
    cursor.execute("SET CONSTRAINTS ALL IMMEDIATE")
  File "/home/nadeemramli/.pyenv/versions/3.10.7/lib/python3.10/site-packages/django/db/backends/utils.py", line 79, in execute
    return self._execute_with_wrappers(
  File "/home/nadeemramli/.pyenv/versions/3.10.7/lib/python3.10/site-packages/django/db/backends/utils.py", line 92, in _execute_with_wrappers
    return executor(sql, params, many, context)
  File "/home/nadeemramli/.pyenv/versions/3.10.7/lib/python3.10/site-packages/django/db/backends/utils.py", line 100, in _execute
    with self.db.wrap_database_errors:
  File "/home/nadeemramli/.pyenv/versions/3.10.7/lib/python3.10/site-packages/django/db/utils.py", line 91, in __exit__
    raise dj_exc_value.with_traceback(traceback) from exc_value
  File "/home/nadeemramli/.pyenv/versions/3.10.7/lib/python3.10/site-packages/django/db/backends/utils.py", line 103, in _execute
    return self.cursor.execute(sql)
django.db.utils.IntegrityError: insert or update on table "metrics_project" violates foreign key constraint "metrics_project_tenant_id_db4a1170_fk_metrics_client_id"
DETAIL:  Key (tenant_id)=(2) is not present in table "metrics_client".


======================================================================
ERROR: test_create_dashboard (metrics.tests.test_apis.APITests)
----------------------------------------------------------------------
Traceback (most recent call last):
  File "/home/nadeemramli/workspace/github.com/nadeemramli/mapping-of-metrics/metric-map-app/backend/metricMapAPI/metrics/tests/test_apis.py", line 164, in test_create_dashboard
    url = self.get_client_project_url('dashboard-list')
  File "/home/nadeemramli/workspace/github.com/nadeemramli/mapping-of-metrics/metric-map-app/backend/metricMapAPI/metrics/tests/test_apis.py", line 42, in get_client_project_url
    return reverse(viewname, kwargs={'client_pk': client_pk, 'project_pk': project_pk, **kwargs})
  File "/home/nadeemramli/.pyenv/versions/3.10.7/lib/python3.10/site-packages/django/urls/base.py", line 88, in reverse
    return resolver._reverse_with_prefix(view, prefix, *args, **kwargs)
  File "/home/nadeemramli/.pyenv/versions/3.10.7/lib/python3.10/site-packages/django/urls/resolvers.py", line 851, in _reverse_with_prefix
    raise NoReverseMatch(msg)
django.urls.exceptions.NoReverseMatch: Reverse for 'dashboard-list' with keyword arguments '{'client_pk': 2, 'project_pk': 4}' not found. 6 pattern(s) tried: ['api/clients/(?P<client__pk>[^/.]+)/projects/(?P<project__pk>[^/.]+)/dashboards/$', 'api/clients/(?P<client__pk>[^/.]+)/projects/(?P<project__pk>[^/.]+)/dashboards/$', 'api/clients/(?P<client__pk>[^/.]+)/projects/(?P<project__pk>[^/.]+)/dashboards/$', 'api/clients/(?P<client__pk>[^/.]+)/projects/(?P<project__pk>[^/.]+)/dashboards/$', 'api/clients/(?P<client__pk>[^/.]+)/projects/(?P<project__pk>[^/.]+)/dashboards/$', 'api/clients/(?P<client__pk>[^/.]+)/projects/(?P<project__pk>[^/.]+)/dashboards/$']

======================================================================
ERROR: test_create_dashboard (metrics.tests.test_apis.APITests)
----------------------------------------------------------------------
Traceback (most recent call last):
  File "/home/nadeemramli/.pyenv/versions/3.10.7/lib/python3.10/site-packages/django/db/backends/utils.py", line 103, in _execute
    return self.cursor.execute(sql)
psycopg2.errors.ForeignKeyViolation: insert or update on table "metrics_project" violates foreign key constraint "metrics_project_tenant_id_db4a1170_fk_metrics_client_id"
DETAIL:  Key (tenant_id)=(2) is not present in table "metrics_client".


The above exception was the direct cause of the following exception:

Traceback (most recent call last):
  File "/home/nadeemramli/.pyenv/versions/3.10.7/lib/python3.10/site-packages/django/test/testcases.py", line 296, in _setup_and_call
    self._post_teardown()
  File "/home/nadeemramli/.pyenv/versions/3.10.7/lib/python3.10/site-packages/django/test/testcases.py", line 1102, in _post_teardown
    self._fixture_teardown()
  File "/home/nadeemramli/.pyenv/versions/3.10.7/lib/python3.10/site-packages/django/test/testcases.py", line 1333, in _fixture_teardown
    connections[db_name].check_constraints()
  File "/home/nadeemramli/.pyenv/versions/3.10.7/lib/python3.10/site-packages/django/db/backends/postgresql/base.py", line 385, in check_constraints
    cursor.execute("SET CONSTRAINTS ALL IMMEDIATE")
  File "/home/nadeemramli/.pyenv/versions/3.10.7/lib/python3.10/site-packages/django/db/backends/utils.py", line 79, in execute
    return self._execute_with_wrappers(
  File "/home/nadeemramli/.pyenv/versions/3.10.7/lib/python3.10/site-packages/django/db/backends/utils.py", line 92, in _execute_with_wrappers
    return executor(sql, params, many, context)
  File "/home/nadeemramli/.pyenv/versions/3.10.7/lib/python3.10/site-packages/django/db/backends/utils.py", line 100, in _execute
    with self.db.wrap_database_errors:
  File "/home/nadeemramli/.pyenv/versions/3.10.7/lib/python3.10/site-packages/django/db/utils.py", line 91, in __exit__
    raise dj_exc_value.with_traceback(traceback) from exc_value
  File "/home/nadeemramli/.pyenv/versions/3.10.7/lib/python3.10/site-packages/django/db/backends/utils.py", line 103, in _execute
    return self.cursor.execute(sql)
django.db.utils.IntegrityError: insert or update on table "metrics_project" violates foreign key constraint "metrics_project_tenant_id_db4a1170_fk_metrics_client_id"
DETAIL:  Key (tenant_id)=(2) is not present in table "metrics_client".


======================================================================
ERROR: test_create_experiment (metrics.tests.test_apis.APITests)
----------------------------------------------------------------------
Traceback (most recent call last):
  File "/home/nadeemramli/workspace/github.com/nadeemramli/mapping-of-metrics/metric-map-app/backend/metricMapAPI/metrics/tests/test_apis.py", line 178, in test_create_experiment
    url = self.get_client_project_url('experiment-list')
  File "/home/nadeemramli/workspace/github.com/nadeemramli/mapping-of-metrics/metric-map-app/backend/metricMapAPI/metrics/tests/test_apis.py", line 42, in get_client_project_url
    return reverse(viewname, kwargs={'client_pk': client_pk, 'project_pk': project_pk, **kwargs})
  File "/home/nadeemramli/.pyenv/versions/3.10.7/lib/python3.10/site-packages/django/urls/base.py", line 88, in reverse
    return resolver._reverse_with_prefix(view, prefix, *args, **kwargs)
  File "/home/nadeemramli/.pyenv/versions/3.10.7/lib/python3.10/site-packages/django/urls/resolvers.py", line 851, in _reverse_with_prefix
    raise NoReverseMatch(msg)
django.urls.exceptions.NoReverseMatch: Reverse for 'experiment-list' with keyword arguments '{'client_pk': 2, 'project_pk': 5}' not found. 6 pattern(s) tried: ['api/clients/(?P<client__pk>[^/.]+)/projects/(?P<project__pk>[^/.]+)/experiments/$', 'api/clients/(?P<client__pk>[^/.]+)/projects/(?P<project__pk>[^/.]+)/experiments/$', 'api/clients/(?P<client__pk>[^/.]+)/projects/(?P<project__pk>[^/.]+)/experiments/$', 'api/clients/(?P<client__pk>[^/.]+)/projects/(?P<project__pk>[^/.]+)/experiments/$', 'api/clients/(?P<client__pk>[^/.]+)/projects/(?P<project__pk>[^/.]+)/experiments/$', 'api/clients/(?P<client__pk>[^/.]+)/projects/(?P<project__pk>[^/.]+)/experiments/$']

======================================================================
ERROR: test_create_experiment (metrics.tests.test_apis.APITests)
----------------------------------------------------------------------
Traceback (most recent call last):
  File "/home/nadeemramli/.pyenv/versions/3.10.7/lib/python3.10/site-packages/django/db/backends/utils.py", line 103, in _execute
    return self.cursor.execute(sql)
psycopg2.errors.ForeignKeyViolation: insert or update on table "metrics_project" violates foreign key constraint "metrics_project_tenant_id_db4a1170_fk_metrics_client_id"
DETAIL:  Key (tenant_id)=(2) is not present in table "metrics_client".


The above exception was the direct cause of the following exception:

Traceback (most recent call last):
  File "/home/nadeemramli/.pyenv/versions/3.10.7/lib/python3.10/site-packages/django/test/testcases.py", line 296, in _setup_and_call
    self._post_teardown()
  File "/home/nadeemramli/.pyenv/versions/3.10.7/lib/python3.10/site-packages/django/test/testcases.py", line 1102, in _post_teardown
    self._fixture_teardown()
  File "/home/nadeemramli/.pyenv/versions/3.10.7/lib/python3.10/site-packages/django/test/testcases.py", line 1333, in _fixture_teardown
    connections[db_name].check_constraints()
  File "/home/nadeemramli/.pyenv/versions/3.10.7/lib/python3.10/site-packages/django/db/backends/postgresql/base.py", line 385, in check_constraints
    cursor.execute("SET CONSTRAINTS ALL IMMEDIATE")
  File "/home/nadeemramli/.pyenv/versions/3.10.7/lib/python3.10/site-packages/django/db/backends/utils.py", line 79, in execute
    return self._execute_with_wrappers(
  File "/home/nadeemramli/.pyenv/versions/3.10.7/lib/python3.10/site-packages/django/db/backends/utils.py", line 92, in _execute_with_wrappers
    return executor(sql, params, many, context)
  File "/home/nadeemramli/.pyenv/versions/3.10.7/lib/python3.10/site-packages/django/db/backends/utils.py", line 100, in _execute
    with self.db.wrap_database_errors:
  File "/home/nadeemramli/.pyenv/versions/3.10.7/lib/python3.10/site-packages/django/db/utils.py", line 91, in __exit__
    raise dj_exc_value.with_traceback(traceback) from exc_value
  File "/home/nadeemramli/.pyenv/versions/3.10.7/lib/python3.10/site-packages/django/db/backends/utils.py", line 103, in _execute
    return self.cursor.execute(sql)
django.db.utils.IntegrityError: insert or update on table "metrics_project" violates foreign key constraint "metrics_project_tenant_id_db4a1170_fk_metrics_client_id"
DETAIL:  Key (tenant_id)=(2) is not present in table "metrics_client".


======================================================================
ERROR: test_create_metric (metrics.tests.test_apis.APITests)
----------------------------------------------------------------------
Traceback (most recent call last):
  File "/home/nadeemramli/workspace/github.com/nadeemramli/mapping-of-metrics/metric-map-app/backend/metricMapAPI/metrics/tests/test_apis.py", line 81, in test_create_metric
    url = self.get_client_project_url('metric-list')
  File "/home/nadeemramli/workspace/github.com/nadeemramli/mapping-of-metrics/metric-map-app/backend/metricMapAPI/metrics/tests/test_apis.py", line 42, in get_client_project_url
    return reverse(viewname, kwargs={'client_pk': client_pk, 'project_pk': project_pk, **kwargs})
  File "/home/nadeemramli/.pyenv/versions/3.10.7/lib/python3.10/site-packages/django/urls/base.py", line 88, in reverse
    return resolver._reverse_with_prefix(view, prefix, *args, **kwargs)
  File "/home/nadeemramli/.pyenv/versions/3.10.7/lib/python3.10/site-packages/django/urls/resolvers.py", line 851, in _reverse_with_prefix
    raise NoReverseMatch(msg)
django.urls.exceptions.NoReverseMatch: Reverse for 'metric-list' with keyword arguments '{'client_pk': 2, 'project_pk': 6}' not found. 6 pattern(s) tried: ['api/clients/(?P<client__pk>[^/.]+)/projects/(?P<project__pk>[^/.]+)/metrics/$', 'api/clients/(?P<client__pk>[^/.]+)/projects/(?P<project__pk>[^/.]+)/metrics/$', 'api/clients/(?P<client__pk>[^/.]+)/projects/(?P<project__pk>[^/.]+)/metrics/$', 'api/clients/(?P<client__pk>[^/.]+)/projects/(?P<project__pk>[^/.]+)/metrics/$', 'api/clients/(?P<client__pk>[^/.]+)/projects/(?P<project__pk>[^/.]+)/metrics/$', 'api/clients/(?P<client__pk>[^/.]+)/projects/(?P<project__pk>[^/.]+)/metrics/$']

======================================================================
ERROR: test_create_metric (metrics.tests.test_apis.APITests)
----------------------------------------------------------------------
Traceback (most recent call last):
  File "/home/nadeemramli/.pyenv/versions/3.10.7/lib/python3.10/site-packages/django/db/backends/utils.py", line 103, in _execute
    return self.cursor.execute(sql)
psycopg2.errors.ForeignKeyViolation: insert or update on table "metrics_project" violates foreign key constraint "metrics_project_tenant_id_db4a1170_fk_metrics_client_id"
DETAIL:  Key (tenant_id)=(2) is not present in table "metrics_client".


The above exception was the direct cause of the following exception:

Traceback (most recent call last):
  File "/home/nadeemramli/.pyenv/versions/3.10.7/lib/python3.10/site-packages/django/test/testcases.py", line 296, in _setup_and_call
    self._post_teardown()
  File "/home/nadeemramli/.pyenv/versions/3.10.7/lib/python3.10/site-packages/django/test/testcases.py", line 1102, in _post_teardown
    self._fixture_teardown()
  File "/home/nadeemramli/.pyenv/versions/3.10.7/lib/python3.10/site-packages/django/test/testcases.py", line 1333, in _fixture_teardown
    connections[db_name].check_constraints()
  File "/home/nadeemramli/.pyenv/versions/3.10.7/lib/python3.10/site-packages/django/db/backends/postgresql/base.py", line 385, in check_constraints
    cursor.execute("SET CONSTRAINTS ALL IMMEDIATE")
  File "/home/nadeemramli/.pyenv/versions/3.10.7/lib/python3.10/site-packages/django/db/backends/utils.py", line 79, in execute
    return self._execute_with_wrappers(
  File "/home/nadeemramli/.pyenv/versions/3.10.7/lib/python3.10/site-packages/django/db/backends/utils.py", line 92, in _execute_with_wrappers
    return executor(sql, params, many, context)
  File "/home/nadeemramli/.pyenv/versions/3.10.7/lib/python3.10/site-packages/django/db/backends/utils.py", line 100, in _execute
    with self.db.wrap_database_errors:
  File "/home/nadeemramli/.pyenv/versions/3.10.7/lib/python3.10/site-packages/django/db/utils.py", line 91, in __exit__
    raise dj_exc_value.with_traceback(traceback) from exc_value
  File "/home/nadeemramli/.pyenv/versions/3.10.7/lib/python3.10/site-packages/django/db/backends/utils.py", line 103, in _execute
    return self.cursor.execute(sql)
django.db.utils.IntegrityError: insert or update on table "metrics_project" violates foreign key constraint "metrics_project_tenant_id_db4a1170_fk_metrics_client_id"
DETAIL:  Key (tenant_id)=(2) is not present in table "metrics_client".


======================================================================
ERROR: test_delete_metric (metrics.tests.test_apis.APITests)
----------------------------------------------------------------------
Traceback (most recent call last):
  File "/home/nadeemramli/workspace/github.com/nadeemramli/mapping-of-metrics/metric-map-app/backend/metricMapAPI/metrics/tests/test_apis.py", line 109, in test_delete_metric
    url = self.get_client_project_url('metric-detail', metric_pk=self.metric.pk)
  File "/home/nadeemramli/workspace/github.com/nadeemramli/mapping-of-metrics/metric-map-app/backend/metricMapAPI/metrics/tests/test_apis.py", line 42, in get_client_project_url
    return reverse(viewname, kwargs={'client_pk': client_pk, 'project_pk': project_pk, **kwargs})
  File "/home/nadeemramli/.pyenv/versions/3.10.7/lib/python3.10/site-packages/django/urls/base.py", line 88, in reverse
    return resolver._reverse_with_prefix(view, prefix, *args, **kwargs)
  File "/home/nadeemramli/.pyenv/versions/3.10.7/lib/python3.10/site-packages/django/urls/resolvers.py", line 851, in _reverse_with_prefix
    raise NoReverseMatch(msg)
django.urls.exceptions.NoReverseMatch: Reverse for 'metric-detail' with keyword arguments '{'client_pk': 2, 'project_pk': 7, 'metric_pk': 7}' not found. 6 pattern(s) tried: ['api/clients/(?P<client__pk>[^/.]+)/projects/(?P<project__pk>[^/.]+)/metrics/(?P<pk>[^/.]+)/$', 'api/clients/(?P<client__pk>[^/.]+)/projects/(?P<project__pk>[^/.]+)/metrics/(?P<pk>[^/.]+)/$', 'api/clients/(?P<client__pk>[^/.]+)/projects/(?P<project__pk>[^/.]+)/metrics/(?P<pk>[^/.]+)/$', 'api/clients/(?P<client__pk>[^/.]+)/projects/(?P<project__pk>[^/.]+)/metrics/(?P<pk>[^/.]+)/$', 'api/clients/(?P<client__pk>[^/.]+)/projects/(?P<project__pk>[^/.]+)/metrics/(?P<pk>[^/.]+)/$', 'api/clients/(?P<client__pk>[^/.]+)/projects/(?P<project__pk>[^/.]+)/metrics/(?P<pk>[^/.]+)/$']

======================================================================
ERROR: test_delete_metric (metrics.tests.test_apis.APITests)
----------------------------------------------------------------------
Traceback (most recent call last):
  File "/home/nadeemramli/.pyenv/versions/3.10.7/lib/python3.10/site-packages/django/db/backends/utils.py", line 103, in _execute
    return self.cursor.execute(sql)
psycopg2.errors.ForeignKeyViolation: insert or update on table "metrics_project" violates foreign key constraint "metrics_project_tenant_id_db4a1170_fk_metrics_client_id"
DETAIL:  Key (tenant_id)=(2) is not present in table "metrics_client".


The above exception was the direct cause of the following exception:

Traceback (most recent call last):
  File "/home/nadeemramli/.pyenv/versions/3.10.7/lib/python3.10/site-packages/django/test/testcases.py", line 296, in _setup_and_call
    self._post_teardown()
  File "/home/nadeemramli/.pyenv/versions/3.10.7/lib/python3.10/site-packages/django/test/testcases.py", line 1102, in _post_teardown
    self._fixture_teardown()
  File "/home/nadeemramli/.pyenv/versions/3.10.7/lib/python3.10/site-packages/django/test/testcases.py", line 1333, in _fixture_teardown
    connections[db_name].check_constraints()
  File "/home/nadeemramli/.pyenv/versions/3.10.7/lib/python3.10/site-packages/django/db/backends/postgresql/base.py", line 385, in check_constraints
    cursor.execute("SET CONSTRAINTS ALL IMMEDIATE")
  File "/home/nadeemramli/.pyenv/versions/3.10.7/lib/python3.10/site-packages/django/db/backends/utils.py", line 79, in execute
    return self._execute_with_wrappers(
  File "/home/nadeemramli/.pyenv/versions/3.10.7/lib/python3.10/site-packages/django/db/backends/utils.py", line 92, in _execute_with_wrappers
    return executor(sql, params, many, context)
  File "/home/nadeemramli/.pyenv/versions/3.10.7/lib/python3.10/site-packages/django/db/backends/utils.py", line 100, in _execute
    with self.db.wrap_database_errors:
  File "/home/nadeemramli/.pyenv/versions/3.10.7/lib/python3.10/site-packages/django/db/utils.py", line 91, in __exit__
    raise dj_exc_value.with_traceback(traceback) from exc_value
  File "/home/nadeemramli/.pyenv/versions/3.10.7/lib/python3.10/site-packages/django/db/backends/utils.py", line 103, in _execute
    return self.cursor.execute(sql)
django.db.utils.IntegrityError: insert or update on table "metrics_project" violates foreign key constraint "metrics_project_tenant_id_db4a1170_fk_metrics_client_id"
DETAIL:  Key (tenant_id)=(2) is not present in table "metrics_client".


======================================================================
ERROR: test_get_categories (metrics.tests.test_apis.APITests)
----------------------------------------------------------------------
Traceback (most recent call last):
  File "/home/nadeemramli/workspace/github.com/nadeemramli/mapping-of-metrics/metric-map-app/backend/metricMapAPI/metrics/tests/test_apis.py", line 189, in test_get_categories
    url = self.get_client_project_url('category-list')
  File "/home/nadeemramli/workspace/github.com/nadeemramli/mapping-of-metrics/metric-map-app/backend/metricMapAPI/metrics/tests/test_apis.py", line 42, in get_client_project_url
    return reverse(viewname, kwargs={'client_pk': client_pk, 'project_pk': project_pk, **kwargs})
  File "/home/nadeemramli/.pyenv/versions/3.10.7/lib/python3.10/site-packages/django/urls/base.py", line 88, in reverse
    return resolver._reverse_with_prefix(view, prefix, *args, **kwargs)
  File "/home/nadeemramli/.pyenv/versions/3.10.7/lib/python3.10/site-packages/django/urls/resolvers.py", line 851, in _reverse_with_prefix
    raise NoReverseMatch(msg)
django.urls.exceptions.NoReverseMatch: Reverse for 'category-list' with keyword arguments '{'client_pk': 2, 'project_pk': 8}' not found. 6 pattern(s) tried: ['api/clients/(?P<client__pk>[^/.]+)/projects/(?P<project__pk>[^/.]+)/categories/$', 'api/clients/(?P<client__pk>[^/.]+)/projects/(?P<project__pk>[^/.]+)/categories/$', 'api/clients/(?P<client__pk>[^/.]+)/projects/(?P<project__pk>[^/.]+)/categories/$', 'api/clients/(?P<client__pk>[^/.]+)/projects/(?P<project__pk>[^/.]+)/categories/$', 'api/clients/(?P<client__pk>[^/.]+)/projects/(?P<project__pk>[^/.]+)/categories/$', 'api/clients/(?P<client__pk>[^/.]+)/projects/(?P<project__pk>[^/.]+)/categories/$']

======================================================================
ERROR: test_get_categories (metrics.tests.test_apis.APITests)
----------------------------------------------------------------------
Traceback (most recent call last):
  File "/home/nadeemramli/.pyenv/versions/3.10.7/lib/python3.10/site-packages/django/db/backends/utils.py", line 103, in _execute
    return self.cursor.execute(sql)
psycopg2.errors.ForeignKeyViolation: insert or update on table "metrics_project" violates foreign key constraint "metrics_project_tenant_id_db4a1170_fk_metrics_client_id"
DETAIL:  Key (tenant_id)=(2) is not present in table "metrics_client".


The above exception was the direct cause of the following exception:

Traceback (most recent call last):
  File "/home/nadeemramli/.pyenv/versions/3.10.7/lib/python3.10/site-packages/django/test/testcases.py", line 296, in _setup_and_call
    self._post_teardown()
  File "/home/nadeemramli/.pyenv/versions/3.10.7/lib/python3.10/site-packages/django/test/testcases.py", line 1102, in _post_teardown
    self._fixture_teardown()
  File "/home/nadeemramli/.pyenv/versions/3.10.7/lib/python3.10/site-packages/django/test/testcases.py", line 1333, in _fixture_teardown
    connections[db_name].check_constraints()
  File "/home/nadeemramli/.pyenv/versions/3.10.7/lib/python3.10/site-packages/django/db/backends/postgresql/base.py", line 385, in check_constraints
    cursor.execute("SET CONSTRAINTS ALL IMMEDIATE")
  File "/home/nadeemramli/.pyenv/versions/3.10.7/lib/python3.10/site-packages/django/db/backends/utils.py", line 79, in execute
    return self._execute_with_wrappers(
  File "/home/nadeemramli/.pyenv/versions/3.10.7/lib/python3.10/site-packages/django/db/backends/utils.py", line 92, in _execute_with_wrappers
    return executor(sql, params, many, context)
  File "/home/nadeemramli/.pyenv/versions/3.10.7/lib/python3.10/site-packages/django/db/backends/utils.py", line 100, in _execute
    with self.db.wrap_database_errors:
  File "/home/nadeemramli/.pyenv/versions/3.10.7/lib/python3.10/site-packages/django/db/utils.py", line 91, in __exit__
    raise dj_exc_value.with_traceback(traceback) from exc_value
  File "/home/nadeemramli/.pyenv/versions/3.10.7/lib/python3.10/site-packages/django/db/backends/utils.py", line 103, in _execute
    return self.cursor.execute(sql)
django.db.utils.IntegrityError: insert or update on table "metrics_project" violates foreign key constraint "metrics_project_tenant_id_db4a1170_fk_metrics_client_id"
DETAIL:  Key (tenant_id)=(2) is not present in table "metrics_client".


======================================================================
ERROR: test_get_client_detail (metrics.tests.test_apis.APITests)
----------------------------------------------------------------------
Traceback (most recent call last):
  File "/home/nadeemramli/workspace/github.com/nadeemramli/mapping-of-metrics/metric-map-app/backend/metricMapAPI/metrics/tests/test_apis.py", line 52, in test_get_client_detail
    response = self.client.get(url)
  File "/home/nadeemramli/.pyenv/versions/3.10.7/lib/python3.10/site-packages/rest_framework/test.py", line 288, in get
    response = super().get(path, data=data, **extra)
  File "/home/nadeemramli/.pyenv/versions/3.10.7/lib/python3.10/site-packages/rest_framework/test.py", line 205, in get
    return self.generic('GET', path, **r)
  File "/home/nadeemramli/.pyenv/versions/3.10.7/lib/python3.10/site-packages/django_tenants/test/client.py", line 16, in generic
    kwargs["HTTP_HOST"] = self.tenant.get_primary_domain().domain
AttributeError: 'NoneType' object has no attribute 'domain'

======================================================================
ERROR: test_get_client_detail (metrics.tests.test_apis.APITests)
----------------------------------------------------------------------
Traceback (most recent call last):
  File "/home/nadeemramli/.pyenv/versions/3.10.7/lib/python3.10/site-packages/django/db/backends/utils.py", line 103, in _execute
    return self.cursor.execute(sql)
psycopg2.errors.ForeignKeyViolation: insert or update on table "metrics_project" violates foreign key constraint "metrics_project_tenant_id_db4a1170_fk_metrics_client_id"
DETAIL:  Key (tenant_id)=(2) is not present in table "metrics_client".


The above exception was the direct cause of the following exception:

Traceback (most recent call last):
  File "/home/nadeemramli/.pyenv/versions/3.10.7/lib/python3.10/site-packages/django/test/testcases.py", line 296, in _setup_and_call
    self._post_teardown()
  File "/home/nadeemramli/.pyenv/versions/3.10.7/lib/python3.10/site-packages/django/test/testcases.py", line 1102, in _post_teardown
    self._fixture_teardown()
  File "/home/nadeemramli/.pyenv/versions/3.10.7/lib/python3.10/site-packages/django/test/testcases.py", line 1333, in _fixture_teardown
    connections[db_name].check_constraints()
  File "/home/nadeemramli/.pyenv/versions/3.10.7/lib/python3.10/site-packages/django/db/backends/postgresql/base.py", line 385, in check_constraints
    cursor.execute("SET CONSTRAINTS ALL IMMEDIATE")
  File "/home/nadeemramli/.pyenv/versions/3.10.7/lib/python3.10/site-packages/django/db/backends/utils.py", line 79, in execute
    return self._execute_with_wrappers(
  File "/home/nadeemramli/.pyenv/versions/3.10.7/lib/python3.10/site-packages/django/db/backends/utils.py", line 92, in _execute_with_wrappers
    return executor(sql, params, many, context)
  File "/home/nadeemramli/.pyenv/versions/3.10.7/lib/python3.10/site-packages/django/db/backends/utils.py", line 100, in _execute
    with self.db.wrap_database_errors:
  File "/home/nadeemramli/.pyenv/versions/3.10.7/lib/python3.10/site-packages/django/db/utils.py", line 91, in __exit__
    raise dj_exc_value.with_traceback(traceback) from exc_value
  File "/home/nadeemramli/.pyenv/versions/3.10.7/lib/python3.10/site-packages/django/db/backends/utils.py", line 103, in _execute
    return self.cursor.execute(sql)
django.db.utils.IntegrityError: insert or update on table "metrics_project" violates foreign key constraint "metrics_project_tenant_id_db4a1170_fk_metrics_client_id"
DETAIL:  Key (tenant_id)=(2) is not present in table "metrics_client".


======================================================================
ERROR: test_get_clients_list (metrics.tests.test_apis.APITests)
----------------------------------------------------------------------
Traceback (most recent call last):
  File "/home/nadeemramli/workspace/github.com/nadeemramli/mapping-of-metrics/metric-map-app/backend/metricMapAPI/metrics/tests/test_apis.py", line 46, in test_get_clients_list
    response = self.client.get(url)
  File "/home/nadeemramli/.pyenv/versions/3.10.7/lib/python3.10/site-packages/rest_framework/test.py", line 288, in get
    response = super().get(path, data=data, **extra)
  File "/home/nadeemramli/.pyenv/versions/3.10.7/lib/python3.10/site-packages/rest_framework/test.py", line 205, in get
    return self.generic('GET', path, **r)
  File "/home/nadeemramli/.pyenv/versions/3.10.7/lib/python3.10/site-packages/django_tenants/test/client.py", line 16, in generic
    kwargs["HTTP_HOST"] = self.tenant.get_primary_domain().domain
AttributeError: 'NoneType' object has no attribute 'domain'

======================================================================
ERROR: test_get_clients_list (metrics.tests.test_apis.APITests)
----------------------------------------------------------------------
Traceback (most recent call last):
  File "/home/nadeemramli/.pyenv/versions/3.10.7/lib/python3.10/site-packages/django/db/backends/utils.py", line 103, in _execute
    return self.cursor.execute(sql)
psycopg2.errors.ForeignKeyViolation: insert or update on table "metrics_project" violates foreign key constraint "metrics_project_tenant_id_db4a1170_fk_metrics_client_id"
DETAIL:  Key (tenant_id)=(2) is not present in table "metrics_client".


The above exception was the direct cause of the following exception:

Traceback (most recent call last):
  File "/home/nadeemramli/.pyenv/versions/3.10.7/lib/python3.10/site-packages/django/test/testcases.py", line 296, in _setup_and_call
    self._post_teardown()
  File "/home/nadeemramli/.pyenv/versions/3.10.7/lib/python3.10/site-packages/django/test/testcases.py", line 1102, in _post_teardown
    self._fixture_teardown()
  File "/home/nadeemramli/.pyenv/versions/3.10.7/lib/python3.10/site-packages/django/test/testcases.py", line 1333, in _fixture_teardown
    connections[db_name].check_constraints()
  File "/home/nadeemramli/.pyenv/versions/3.10.7/lib/python3.10/site-packages/django/db/backends/postgresql/base.py", line 385, in check_constraints
    cursor.execute("SET CONSTRAINTS ALL IMMEDIATE")
  File "/home/nadeemramli/.pyenv/versions/3.10.7/lib/python3.10/site-packages/django/db/backends/utils.py", line 79, in execute
    return self._execute_with_wrappers(
  File "/home/nadeemramli/.pyenv/versions/3.10.7/lib/python3.10/site-packages/django/db/backends/utils.py", line 92, in _execute_with_wrappers
    return executor(sql, params, many, context)
  File "/home/nadeemramli/.pyenv/versions/3.10.7/lib/python3.10/site-packages/django/db/backends/utils.py", line 100, in _execute
    with self.db.wrap_database_errors:
  File "/home/nadeemramli/.pyenv/versions/3.10.7/lib/python3.10/site-packages/django/db/utils.py", line 91, in __exit__
    raise dj_exc_value.with_traceback(traceback) from exc_value
  File "/home/nadeemramli/.pyenv/versions/3.10.7/lib/python3.10/site-packages/django/db/backends/utils.py", line 103, in _execute
    return self.cursor.execute(sql)
django.db.utils.IntegrityError: insert or update on table "metrics_project" violates foreign key constraint "metrics_project_tenant_id_db4a1170_fk_metrics_client_id"
DETAIL:  Key (tenant_id)=(2) is not present in table "metrics_client".


======================================================================
ERROR: test_get_connections (metrics.tests.test_apis.APITests)
----------------------------------------------------------------------
Traceback (most recent call last):
  File "/home/nadeemramli/workspace/github.com/nadeemramli/mapping-of-metrics/metric-map-app/backend/metricMapAPI/metrics/tests/test_apis.py", line 199, in test_get_connections
    url = self.get_client_project_url('connection-list')
  File "/home/nadeemramli/workspace/github.com/nadeemramli/mapping-of-metrics/metric-map-app/backend/metricMapAPI/metrics/tests/test_apis.py", line 42, in get_client_project_url
    return reverse(viewname, kwargs={'client_pk': client_pk, 'project_pk': project_pk, **kwargs})
  File "/home/nadeemramli/.pyenv/versions/3.10.7/lib/python3.10/site-packages/django/urls/base.py", line 88, in reverse
    return resolver._reverse_with_prefix(view, prefix, *args, **kwargs)
  File "/home/nadeemramli/.pyenv/versions/3.10.7/lib/python3.10/site-packages/django/urls/resolvers.py", line 851, in _reverse_with_prefix
    raise NoReverseMatch(msg)
django.urls.exceptions.NoReverseMatch: Reverse for 'connection-list' with keyword arguments '{'client_pk': 2, 'project_pk': 11}' not found. 6 pattern(s) tried: ['api/clients/(?P<client__pk>[^/.]+)/projects/(?P<project__pk>[^/.]+)/connections/$', 'api/clients/(?P<client__pk>[^/.]+)/projects/(?P<project__pk>[^/.]+)/connections/$', 'api/clients/(?P<client__pk>[^/.]+)/projects/(?P<project__pk>[^/.]+)/connections/$', 'api/clients/(?P<client__pk>[^/.]+)/projects/(?P<project__pk>[^/.]+)/connections/$', 'api/clients/(?P<client__pk>[^/.]+)/projects/(?P<project__pk>[^/.]+)/connections/$', 'api/clients/(?P<client__pk>[^/.]+)/projects/(?P<project__pk>[^/.]+)/connections/$']

======================================================================
ERROR: test_get_connections (metrics.tests.test_apis.APITests)
----------------------------------------------------------------------
Traceback (most recent call last):
  File "/home/nadeemramli/.pyenv/versions/3.10.7/lib/python3.10/site-packages/django/db/backends/utils.py", line 103, in _execute
    return self.cursor.execute(sql)
psycopg2.errors.ForeignKeyViolation: insert or update on table "metrics_project" violates foreign key constraint "metrics_project_tenant_id_db4a1170_fk_metrics_client_id"
DETAIL:  Key (tenant_id)=(2) is not present in table "metrics_client".


The above exception was the direct cause of the following exception:

Traceback (most recent call last):
  File "/home/nadeemramli/.pyenv/versions/3.10.7/lib/python3.10/site-packages/django/test/testcases.py", line 296, in _setup_and_call
    self._post_teardown()
  File "/home/nadeemramli/.pyenv/versions/3.10.7/lib/python3.10/site-packages/django/test/testcases.py", line 1102, in _post_teardown
    self._fixture_teardown()
  File "/home/nadeemramli/.pyenv/versions/3.10.7/lib/python3.10/site-packages/django/test/testcases.py", line 1333, in _fixture_teardown
    connections[db_name].check_constraints()
  File "/home/nadeemramli/.pyenv/versions/3.10.7/lib/python3.10/site-packages/django/db/backends/postgresql/base.py", line 385, in check_constraints
    cursor.execute("SET CONSTRAINTS ALL IMMEDIATE")
  File "/home/nadeemramli/.pyenv/versions/3.10.7/lib/python3.10/site-packages/django/db/backends/utils.py", line 79, in execute
    return self._execute_with_wrappers(
  File "/home/nadeemramli/.pyenv/versions/3.10.7/lib/python3.10/site-packages/django/db/backends/utils.py", line 92, in _execute_with_wrappers
    return executor(sql, params, many, context)
  File "/home/nadeemramli/.pyenv/versions/3.10.7/lib/python3.10/site-packages/django/db/backends/utils.py", line 100, in _execute
    with self.db.wrap_database_errors:
  File "/home/nadeemramli/.pyenv/versions/3.10.7/lib/python3.10/site-packages/django/db/utils.py", line 91, in __exit__
    raise dj_exc_value.with_traceback(traceback) from exc_value
  File "/home/nadeemramli/.pyenv/versions/3.10.7/lib/python3.10/site-packages/django/db/backends/utils.py", line 103, in _execute
    return self.cursor.execute(sql)
django.db.utils.IntegrityError: insert or update on table "metrics_project" violates foreign key constraint "metrics_project_tenant_id_db4a1170_fk_metrics_client_id"
DETAIL:  Key (tenant_id)=(2) is not present in table "metrics_client".


======================================================================
ERROR: test_get_dashboards (metrics.tests.test_apis.APITests)
----------------------------------------------------------------------
Traceback (most recent call last):
  File "/home/nadeemramli/workspace/github.com/nadeemramli/mapping-of-metrics/metric-map-app/backend/metricMapAPI/metrics/tests/test_apis.py", line 159, in test_get_dashboards
    url = self.get_client_project_url('dashboard-list')
  File "/home/nadeemramli/workspace/github.com/nadeemramli/mapping-of-metrics/metric-map-app/backend/metricMapAPI/metrics/tests/test_apis.py", line 42, in get_client_project_url
    return reverse(viewname, kwargs={'client_pk': client_pk, 'project_pk': project_pk, **kwargs})
  File "/home/nadeemramli/.pyenv/versions/3.10.7/lib/python3.10/site-packages/django/urls/base.py", line 88, in reverse
    return resolver._reverse_with_prefix(view, prefix, *args, **kwargs)
  File "/home/nadeemramli/.pyenv/versions/3.10.7/lib/python3.10/site-packages/django/urls/resolvers.py", line 851, in _reverse_with_prefix
    raise NoReverseMatch(msg)
django.urls.exceptions.NoReverseMatch: Reverse for 'dashboard-list' with keyword arguments '{'client_pk': 2, 'project_pk': 12}' not found. 6 pattern(s) tried: ['api/clients/(?P<client__pk>[^/.]+)/projects/(?P<project__pk>[^/.]+)/dashboards/$', 'api/clients/(?P<client__pk>[^/.]+)/projects/(?P<project__pk>[^/.]+)/dashboards/$', 'api/clients/(?P<client__pk>[^/.]+)/projects/(?P<project__pk>[^/.]+)/dashboards/$', 'api/clients/(?P<client__pk>[^/.]+)/projects/(?P<project__pk>[^/.]+)/dashboards/$', 'api/clients/(?P<client__pk>[^/.]+)/projects/(?P<project__pk>[^/.]+)/dashboards/$', 'api/clients/(?P<client__pk>[^/.]+)/projects/(?P<project__pk>[^/.]+)/dashboards/$']

======================================================================
ERROR: test_get_dashboards (metrics.tests.test_apis.APITests)
----------------------------------------------------------------------
Traceback (most recent call last):
  File "/home/nadeemramli/.pyenv/versions/3.10.7/lib/python3.10/site-packages/django/db/backends/utils.py", line 103, in _execute
    return self.cursor.execute(sql)
psycopg2.errors.ForeignKeyViolation: insert or update on table "metrics_project" violates foreign key constraint "metrics_project_tenant_id_db4a1170_fk_metrics_client_id"
DETAIL:  Key (tenant_id)=(2) is not present in table "metrics_client".


The above exception was the direct cause of the following exception:

Traceback (most recent call last):
  File "/home/nadeemramli/.pyenv/versions/3.10.7/lib/python3.10/site-packages/django/test/testcases.py", line 296, in _setup_and_call
    self._post_teardown()
  File "/home/nadeemramli/.pyenv/versions/3.10.7/lib/python3.10/site-packages/django/test/testcases.py", line 1102, in _post_teardown
    self._fixture_teardown()
  File "/home/nadeemramli/.pyenv/versions/3.10.7/lib/python3.10/site-packages/django/test/testcases.py", line 1333, in _fixture_teardown
    connections[db_name].check_constraints()
  File "/home/nadeemramli/.pyenv/versions/3.10.7/lib/python3.10/site-packages/django/db/backends/postgresql/base.py", line 385, in check_constraints
    cursor.execute("SET CONSTRAINTS ALL IMMEDIATE")
  File "/home/nadeemramli/.pyenv/versions/3.10.7/lib/python3.10/site-packages/django/db/backends/utils.py", line 79, in execute
    return self._execute_with_wrappers(
  File "/home/nadeemramli/.pyenv/versions/3.10.7/lib/python3.10/site-packages/django/db/backends/utils.py", line 92, in _execute_with_wrappers
    return executor(sql, params, many, context)
  File "/home/nadeemramli/.pyenv/versions/3.10.7/lib/python3.10/site-packages/django/db/backends/utils.py", line 100, in _execute
    with self.db.wrap_database_errors:
  File "/home/nadeemramli/.pyenv/versions/3.10.7/lib/python3.10/site-packages/django/db/utils.py", line 91, in __exit__
    raise dj_exc_value.with_traceback(traceback) from exc_value
  File "/home/nadeemramli/.pyenv/versions/3.10.7/lib/python3.10/site-packages/django/db/backends/utils.py", line 103, in _execute
    return self.cursor.execute(sql)
django.db.utils.IntegrityError: insert or update on table "metrics_project" violates foreign key constraint "metrics_project_tenant_id_db4a1170_fk_metrics_client_id"
DETAIL:  Key (tenant_id)=(2) is not present in table "metrics_client".


======================================================================
ERROR: test_get_experiments (metrics.tests.test_apis.APITests)
----------------------------------------------------------------------
Traceback (most recent call last):
  File "/home/nadeemramli/workspace/github.com/nadeemramli/mapping-of-metrics/metric-map-app/backend/metricMapAPI/metrics/tests/test_apis.py", line 173, in test_get_experiments
    url = self.get_client_project_url('experiment-list')
  File "/home/nadeemramli/workspace/github.com/nadeemramli/mapping-of-metrics/metric-map-app/backend/metricMapAPI/metrics/tests/test_apis.py", line 42, in get_client_project_url
    return reverse(viewname, kwargs={'client_pk': client_pk, 'project_pk': project_pk, **kwargs})
  File "/home/nadeemramli/.pyenv/versions/3.10.7/lib/python3.10/site-packages/django/urls/base.py", line 88, in reverse
    return resolver._reverse_with_prefix(view, prefix, *args, **kwargs)
  File "/home/nadeemramli/.pyenv/versions/3.10.7/lib/python3.10/site-packages/django/urls/resolvers.py", line 851, in _reverse_with_prefix
    raise NoReverseMatch(msg)
django.urls.exceptions.NoReverseMatch: Reverse for 'experiment-list' with keyword arguments '{'client_pk': 2, 'project_pk': 13}' not found. 6 pattern(s) tried: ['api/clients/(?P<client__pk>[^/.]+)/projects/(?P<project__pk>[^/.]+)/experiments/$', 'api/clients/(?P<client__pk>[^/.]+)/projects/(?P<project__pk>[^/.]+)/experiments/$', 'api/clients/(?P<client__pk>[^/.]+)/projects/(?P<project__pk>[^/.]+)/experiments/$', 'api/clients/(?P<client__pk>[^/.]+)/projects/(?P<project__pk>[^/.]+)/experiments/$', 'api/clients/(?P<client__pk>[^/.]+)/projects/(?P<project__pk>[^/.]+)/experiments/$', 'api/clients/(?P<client__pk>[^/.]+)/projects/(?P<project__pk>[^/.]+)/experiments/$']

======================================================================
ERROR: test_get_experiments (metrics.tests.test_apis.APITests)
----------------------------------------------------------------------
Traceback (most recent call last):
  File "/home/nadeemramli/.pyenv/versions/3.10.7/lib/python3.10/site-packages/django/db/backends/utils.py", line 103, in _execute
    return self.cursor.execute(sql)
psycopg2.errors.ForeignKeyViolation: insert or update on table "metrics_project" violates foreign key constraint "metrics_project_tenant_id_db4a1170_fk_metrics_client_id"
DETAIL:  Key (tenant_id)=(2) is not present in table "metrics_client".


The above exception was the direct cause of the following exception:

Traceback (most recent call last):
  File "/home/nadeemramli/.pyenv/versions/3.10.7/lib/python3.10/site-packages/django/test/testcases.py", line 296, in _setup_and_call
    self._post_teardown()
  File "/home/nadeemramli/.pyenv/versions/3.10.7/lib/python3.10/site-packages/django/test/testcases.py", line 1102, in _post_teardown
    self._fixture_teardown()
  File "/home/nadeemramli/.pyenv/versions/3.10.7/lib/python3.10/site-packages/django/test/testcases.py", line 1333, in _fixture_teardown
    connections[db_name].check_constraints()
  File "/home/nadeemramli/.pyenv/versions/3.10.7/lib/python3.10/site-packages/django/db/backends/postgresql/base.py", line 385, in check_constraints
    cursor.execute("SET CONSTRAINTS ALL IMMEDIATE")
  File "/home/nadeemramli/.pyenv/versions/3.10.7/lib/python3.10/site-packages/django/db/backends/utils.py", line 79, in execute
    return self._execute_with_wrappers(
  File "/home/nadeemramli/.pyenv/versions/3.10.7/lib/python3.10/site-packages/django/db/backends/utils.py", line 92, in _execute_with_wrappers
    return executor(sql, params, many, context)
  File "/home/nadeemramli/.pyenv/versions/3.10.7/lib/python3.10/site-packages/django/db/backends/utils.py", line 100, in _execute
    with self.db.wrap_database_errors:
  File "/home/nadeemramli/.pyenv/versions/3.10.7/lib/python3.10/site-packages/django/db/utils.py", line 91, in __exit__
    raise dj_exc_value.with_traceback(traceback) from exc_value
  File "/home/nadeemramli/.pyenv/versions/3.10.7/lib/python3.10/site-packages/django/db/backends/utils.py", line 103, in _execute
    return self.cursor.execute(sql)
django.db.utils.IntegrityError: insert or update on table "metrics_project" violates foreign key constraint "metrics_project_tenant_id_db4a1170_fk_metrics_client_id"
DETAIL:  Key (tenant_id)=(2) is not present in table "metrics_client".


======================================================================
ERROR: test_get_historical_data (metrics.tests.test_apis.APITests)
----------------------------------------------------------------------
Traceback (most recent call last):
  File "/home/nadeemramli/workspace/github.com/nadeemramli/mapping-of-metrics/metric-map-app/backend/metricMapAPI/metrics/tests/test_apis.py", line 115, in test_get_historical_data
    url = self.get_client_project_url('historical_data-list', metric_pk=self.metric.pk)
  File "/home/nadeemramli/workspace/github.com/nadeemramli/mapping-of-metrics/metric-map-app/backend/metricMapAPI/metrics/tests/test_apis.py", line 42, in get_client_project_url
    return reverse(viewname, kwargs={'client_pk': client_pk, 'project_pk': project_pk, **kwargs})
  File "/home/nadeemramli/.pyenv/versions/3.10.7/lib/python3.10/site-packages/django/urls/base.py", line 88, in reverse
    return resolver._reverse_with_prefix(view, prefix, *args, **kwargs)
  File "/home/nadeemramli/.pyenv/versions/3.10.7/lib/python3.10/site-packages/django/urls/resolvers.py", line 851, in _reverse_with_prefix
    raise NoReverseMatch(msg)
django.urls.exceptions.NoReverseMatch: Reverse for 'historical_data-list' with keyword arguments '{'client_pk': 2, 'project_pk': 14, 'metric_pk': 14}' not found. 8 pattern(s) tried: ['api/clients/(?P<client__pk>[^/.]+)/projects/(?P<project__pk>[^/.]+)/metrics/(?P<metric__pk>[^/.]+)/historical-data/$', 'api/clients/(?P<client__pk>[^/.]+)/projects/(?P<project__pk>[^/.]+)/metrics/(?P<metric__pk>[^/.]+)/historical-data/$', 'api/clients/(?P<client__pk>[^/.]+)/projects/(?P<project__pk>[^/.]+)/metrics/(?P<metric__pk>[^/.]+)/historical-data/$', 'api/clients/(?P<client__pk>[^/.]+)/projects/(?P<project__pk>[^/.]+)/metrics/(?P<metric__pk>[^/.]+)/historical-data/$', 'api/clients/(?P<client__pk>[^/.]+)/projects/(?P<project__pk>[^/.]+)/metrics/(?P<metric__pk>[^/.]+)/historical-data/$', 'api/clients/(?P<client__pk>[^/.]+)/projects/(?P<project__pk>[^/.]+)/metrics/(?P<metric__pk>[^/.]+)/historical-data/$', 'api/clients/(?P<client__pk>[^/.]+)/projects/(?P<project__pk>[^/.]+)/metrics/(?P<metric__pk>[^/.]+)/historical-data/$', 'api/clients/(?P<client__pk>[^/.]+)/projects/(?P<project__pk>[^/.]+)/metrics/(?P<metric__pk>[^/.]+)/historical-data/$']

======================================================================
ERROR: test_get_historical_data (metrics.tests.test_apis.APITests)
----------------------------------------------------------------------
Traceback (most recent call last):
  File "/home/nadeemramli/.pyenv/versions/3.10.7/lib/python3.10/site-packages/django/db/backends/utils.py", line 103, in _execute
    return self.cursor.execute(sql)
psycopg2.errors.ForeignKeyViolation: insert or update on table "metrics_project" violates foreign key constraint "metrics_project_tenant_id_db4a1170_fk_metrics_client_id"
DETAIL:  Key (tenant_id)=(2) is not present in table "metrics_client".


The above exception was the direct cause of the following exception:

Traceback (most recent call last):
  File "/home/nadeemramli/.pyenv/versions/3.10.7/lib/python3.10/site-packages/django/test/testcases.py", line 296, in _setup_and_call
    self._post_teardown()
  File "/home/nadeemramli/.pyenv/versions/3.10.7/lib/python3.10/site-packages/django/test/testcases.py", line 1102, in _post_teardown
    self._fixture_teardown()
  File "/home/nadeemramli/.pyenv/versions/3.10.7/lib/python3.10/site-packages/django/test/testcases.py", line 1333, in _fixture_teardown
    connections[db_name].check_constraints()
  File "/home/nadeemramli/.pyenv/versions/3.10.7/lib/python3.10/site-packages/django/db/backends/postgresql/base.py", line 385, in check_constraints
    cursor.execute("SET CONSTRAINTS ALL IMMEDIATE")
  File "/home/nadeemramli/.pyenv/versions/3.10.7/lib/python3.10/site-packages/django/db/backends/utils.py", line 79, in execute
    return self._execute_with_wrappers(
  File "/home/nadeemramli/.pyenv/versions/3.10.7/lib/python3.10/site-packages/django/db/backends/utils.py", line 92, in _execute_with_wrappers
    return executor(sql, params, many, context)
  File "/home/nadeemramli/.pyenv/versions/3.10.7/lib/python3.10/site-packages/django/db/backends/utils.py", line 100, in _execute
    with self.db.wrap_database_errors:
  File "/home/nadeemramli/.pyenv/versions/3.10.7/lib/python3.10/site-packages/django/db/utils.py", line 91, in __exit__
    raise dj_exc_value.with_traceback(traceback) from exc_value
  File "/home/nadeemramli/.pyenv/versions/3.10.7/lib/python3.10/site-packages/django/db/backends/utils.py", line 103, in _execute
    return self.cursor.execute(sql)
django.db.utils.IntegrityError: insert or update on table "metrics_project" violates foreign key constraint "metrics_project_tenant_id_db4a1170_fk_metrics_client_id"
DETAIL:  Key (tenant_id)=(2) is not present in table "metrics_client".


======================================================================
ERROR: test_get_metric_action_remarks (metrics.tests.test_apis.APITests)
----------------------------------------------------------------------
Traceback (most recent call last):
  File "/home/nadeemramli/workspace/github.com/nadeemramli/mapping-of-metrics/metric-map-app/backend/metricMapAPI/metrics/tests/test_apis.py", line 135, in test_get_metric_action_remarks
    url = self.get_client_project_url('metric-action_remarks', pk=self.metric.pk)
  File "/home/nadeemramli/workspace/github.com/nadeemramli/mapping-of-metrics/metric-map-app/backend/metricMapAPI/metrics/tests/test_apis.py", line 42, in get_client_project_url
    return reverse(viewname, kwargs={'client_pk': client_pk, 'project_pk': project_pk, **kwargs})
  File "/home/nadeemramli/.pyenv/versions/3.10.7/lib/python3.10/site-packages/django/urls/base.py", line 88, in reverse
    return resolver._reverse_with_prefix(view, prefix, *args, **kwargs)
  File "/home/nadeemramli/.pyenv/versions/3.10.7/lib/python3.10/site-packages/django/urls/resolvers.py", line 851, in _reverse_with_prefix
    raise NoReverseMatch(msg)
django.urls.exceptions.NoReverseMatch: Reverse for 'metric-action_remarks' not found. 'metric-action_remarks' is not a valid view function or pattern name.

======================================================================
ERROR: test_get_metric_action_remarks (metrics.tests.test_apis.APITests)
----------------------------------------------------------------------
Traceback (most recent call last):
  File "/home/nadeemramli/.pyenv/versions/3.10.7/lib/python3.10/site-packages/django/db/backends/utils.py", line 103, in _execute
    return self.cursor.execute(sql)
psycopg2.errors.ForeignKeyViolation: insert or update on table "metrics_project" violates foreign key constraint "metrics_project_tenant_id_db4a1170_fk_metrics_client_id"
DETAIL:  Key (tenant_id)=(2) is not present in table "metrics_client".


The above exception was the direct cause of the following exception:

Traceback (most recent call last):
  File "/home/nadeemramli/.pyenv/versions/3.10.7/lib/python3.10/site-packages/django/test/testcases.py", line 296, in _setup_and_call
    self._post_teardown()
  File "/home/nadeemramli/.pyenv/versions/3.10.7/lib/python3.10/site-packages/django/test/testcases.py", line 1102, in _post_teardown
    self._fixture_teardown()
  File "/home/nadeemramli/.pyenv/versions/3.10.7/lib/python3.10/site-packages/django/test/testcases.py", line 1333, in _fixture_teardown
    connections[db_name].check_constraints()
  File "/home/nadeemramli/.pyenv/versions/3.10.7/lib/python3.10/site-packages/django/db/backends/postgresql/base.py", line 385, in check_constraints
    cursor.execute("SET CONSTRAINTS ALL IMMEDIATE")
  File "/home/nadeemramli/.pyenv/versions/3.10.7/lib/python3.10/site-packages/django/db/backends/utils.py", line 79, in execute
    return self._execute_with_wrappers(
  File "/home/nadeemramli/.pyenv/versions/3.10.7/lib/python3.10/site-packages/django/db/backends/utils.py", line 92, in _execute_with_wrappers
    return executor(sql, params, many, context)
  File "/home/nadeemramli/.pyenv/versions/3.10.7/lib/python3.10/site-packages/django/db/backends/utils.py", line 100, in _execute
    with self.db.wrap_database_errors:
  File "/home/nadeemramli/.pyenv/versions/3.10.7/lib/python3.10/site-packages/django/db/utils.py", line 91, in __exit__
    raise dj_exc_value.with_traceback(traceback) from exc_value
  File "/home/nadeemramli/.pyenv/versions/3.10.7/lib/python3.10/site-packages/django/db/backends/utils.py", line 103, in _execute
    return self.cursor.execute(sql)
django.db.utils.IntegrityError: insert or update on table "metrics_project" violates foreign key constraint "metrics_project_tenant_id_db4a1170_fk_metrics_client_id"
DETAIL:  Key (tenant_id)=(2) is not present in table "metrics_client".


======================================================================
ERROR: test_get_metric_connections (metrics.tests.test_apis.APITests)
----------------------------------------------------------------------
Traceback (most recent call last):
  File "/home/nadeemramli/workspace/github.com/nadeemramli/mapping-of-metrics/metric-map-app/backend/metricMapAPI/metrics/tests/test_apis.py", line 130, in test_get_metric_connections
    url = self.get_client_project_url('metric-connections', pk=self.metric.pk)
  File "/home/nadeemramli/workspace/github.com/nadeemramli/mapping-of-metrics/metric-map-app/backend/metricMapAPI/metrics/tests/test_apis.py", line 42, in get_client_project_url
    return reverse(viewname, kwargs={'client_pk': client_pk, 'project_pk': project_pk, **kwargs})
  File "/home/nadeemramli/.pyenv/versions/3.10.7/lib/python3.10/site-packages/django/urls/base.py", line 88, in reverse
    return resolver._reverse_with_prefix(view, prefix, *args, **kwargs)
  File "/home/nadeemramli/.pyenv/versions/3.10.7/lib/python3.10/site-packages/django/urls/resolvers.py", line 851, in _reverse_with_prefix
    raise NoReverseMatch(msg)
django.urls.exceptions.NoReverseMatch: Reverse for 'metric-connections' with keyword arguments '{'client_pk': 2, 'project_pk': 16, 'pk': 16}' not found. 6 pattern(s) tried: ['api/clients/(?P<client__pk>[^/.]+)/projects/(?P<project__pk>[^/.]+)/metrics/(?P<pk>[^/.]+)/connections/$', 'api/clients/(?P<client__pk>[^/.]+)/projects/(?P<project__pk>[^/.]+)/metrics/(?P<pk>[^/.]+)/connections/$', 'api/clients/(?P<client__pk>[^/.]+)/projects/(?P<project__pk>[^/.]+)/metrics/(?P<pk>[^/.]+)/connections/$', 'api/clients/(?P<client__pk>[^/.]+)/projects/(?P<project__pk>[^/.]+)/metrics/(?P<pk>[^/.]+)/connections/$', 'api/clients/(?P<client__pk>[^/.]+)/projects/(?P<project__pk>[^/.]+)/metrics/(?P<pk>[^/.]+)/connections/$', 'api/clients/(?P<client__pk>[^/.]+)/projects/(?P<project__pk>[^/.]+)/metrics/(?P<pk>[^/.]+)/connections/$']

======================================================================
ERROR: test_get_metric_connections (metrics.tests.test_apis.APITests)
----------------------------------------------------------------------
Traceback (most recent call last):
  File "/home/nadeemramli/.pyenv/versions/3.10.7/lib/python3.10/site-packages/django/db/backends/utils.py", line 103, in _execute
    return self.cursor.execute(sql)
psycopg2.errors.ForeignKeyViolation: insert or update on table "metrics_project" violates foreign key constraint "metrics_project_tenant_id_db4a1170_fk_metrics_client_id"
DETAIL:  Key (tenant_id)=(2) is not present in table "metrics_client".


The above exception was the direct cause of the following exception:

Traceback (most recent call last):
  File "/home/nadeemramli/.pyenv/versions/3.10.7/lib/python3.10/site-packages/django/test/testcases.py", line 296, in _setup_and_call
    self._post_teardown()
  File "/home/nadeemramli/.pyenv/versions/3.10.7/lib/python3.10/site-packages/django/test/testcases.py", line 1102, in _post_teardown
    self._fixture_teardown()
  File "/home/nadeemramli/.pyenv/versions/3.10.7/lib/python3.10/site-packages/django/test/testcases.py", line 1333, in _fixture_teardown
    connections[db_name].check_constraints()
  File "/home/nadeemramli/.pyenv/versions/3.10.7/lib/python3.10/site-packages/django/db/backends/postgresql/base.py", line 385, in check_constraints
    cursor.execute("SET CONSTRAINTS ALL IMMEDIATE")
  File "/home/nadeemramli/.pyenv/versions/3.10.7/lib/python3.10/site-packages/django/db/backends/utils.py", line 79, in execute
    return self._execute_with_wrappers(
  File "/home/nadeemramli/.pyenv/versions/3.10.7/lib/python3.10/site-packages/django/db/backends/utils.py", line 92, in _execute_with_wrappers
    return executor(sql, params, many, context)
  File "/home/nadeemramli/.pyenv/versions/3.10.7/lib/python3.10/site-packages/django/db/backends/utils.py", line 100, in _execute
    with self.db.wrap_database_errors:
  File "/home/nadeemramli/.pyenv/versions/3.10.7/lib/python3.10/site-packages/django/db/utils.py", line 91, in __exit__
    raise dj_exc_value.with_traceback(traceback) from exc_value
  File "/home/nadeemramli/.pyenv/versions/3.10.7/lib/python3.10/site-packages/django/db/backends/utils.py", line 103, in _execute
    return self.cursor.execute(sql)
django.db.utils.IntegrityError: insert or update on table "metrics_project" violates foreign key constraint "metrics_project_tenant_id_db4a1170_fk_metrics_client_id"
DETAIL:  Key (tenant_id)=(2) is not present in table "metrics_client".


======================================================================
ERROR: test_get_metric_detail (metrics.tests.test_apis.APITests)
----------------------------------------------------------------------
Traceback (most recent call last):
  File "/home/nadeemramli/workspace/github.com/nadeemramli/mapping-of-metrics/metric-map-app/backend/metricMapAPI/metrics/tests/test_apis.py", line 75, in test_get_metric_detail
    url = self.get_client_project_url('metric-detail', metric_pk=self.metric.pk)
  File "/home/nadeemramli/workspace/github.com/nadeemramli/mapping-of-metrics/metric-map-app/backend/metricMapAPI/metrics/tests/test_apis.py", line 42, in get_client_project_url
    return reverse(viewname, kwargs={'client_pk': client_pk, 'project_pk': project_pk, **kwargs})
  File "/home/nadeemramli/.pyenv/versions/3.10.7/lib/python3.10/site-packages/django/urls/base.py", line 88, in reverse
    return resolver._reverse_with_prefix(view, prefix, *args, **kwargs)
  File "/home/nadeemramli/.pyenv/versions/3.10.7/lib/python3.10/site-packages/django/urls/resolvers.py", line 851, in _reverse_with_prefix
    raise NoReverseMatch(msg)
django.urls.exceptions.NoReverseMatch: Reverse for 'metric-detail' with keyword arguments '{'client_pk': 2, 'project_pk': 17, 'metric_pk': 17}' not found. 6 pattern(s) tried: ['api/clients/(?P<client__pk>[^/.]+)/projects/(?P<project__pk>[^/.]+)/metrics/(?P<pk>[^/.]+)/$', 'api/clients/(?P<client__pk>[^/.]+)/projects/(?P<project__pk>[^/.]+)/metrics/(?P<pk>[^/.]+)/$', 'api/clients/(?P<client__pk>[^/.]+)/projects/(?P<project__pk>[^/.]+)/metrics/(?P<pk>[^/.]+)/$', 'api/clients/(?P<client__pk>[^/.]+)/projects/(?P<project__pk>[^/.]+)/metrics/(?P<pk>[^/.]+)/$', 'api/clients/(?P<client__pk>[^/.]+)/projects/(?P<project__pk>[^/.]+)/metrics/(?P<pk>[^/.]+)/$', 'api/clients/(?P<client__pk>[^/.]+)/projects/(?P<project__pk>[^/.]+)/metrics/(?P<pk>[^/.]+)/$']

======================================================================
ERROR: test_get_metric_detail (metrics.tests.test_apis.APITests)
----------------------------------------------------------------------
Traceback (most recent call last):
  File "/home/nadeemramli/.pyenv/versions/3.10.7/lib/python3.10/site-packages/django/db/backends/utils.py", line 103, in _execute
    return self.cursor.execute(sql)
psycopg2.errors.ForeignKeyViolation: insert or update on table "metrics_project" violates foreign key constraint "metrics_project_tenant_id_db4a1170_fk_metrics_client_id"
DETAIL:  Key (tenant_id)=(2) is not present in table "metrics_client".


The above exception was the direct cause of the following exception:

Traceback (most recent call last):
  File "/home/nadeemramli/.pyenv/versions/3.10.7/lib/python3.10/site-packages/django/test/testcases.py", line 296, in _setup_and_call
    self._post_teardown()
  File "/home/nadeemramli/.pyenv/versions/3.10.7/lib/python3.10/site-packages/django/test/testcases.py", line 1102, in _post_teardown
    self._fixture_teardown()
  File "/home/nadeemramli/.pyenv/versions/3.10.7/lib/python3.10/site-packages/django/test/testcases.py", line 1333, in _fixture_teardown
    connections[db_name].check_constraints()
  File "/home/nadeemramli/.pyenv/versions/3.10.7/lib/python3.10/site-packages/django/db/backends/postgresql/base.py", line 385, in check_constraints
    cursor.execute("SET CONSTRAINTS ALL IMMEDIATE")
  File "/home/nadeemramli/.pyenv/versions/3.10.7/lib/python3.10/site-packages/django/db/backends/utils.py", line 79, in execute
    return self._execute_with_wrappers(
  File "/home/nadeemramli/.pyenv/versions/3.10.7/lib/python3.10/site-packages/django/db/backends/utils.py", line 92, in _execute_with_wrappers
    return executor(sql, params, many, context)
  File "/home/nadeemramli/.pyenv/versions/3.10.7/lib/python3.10/site-packages/django/db/backends/utils.py", line 100, in _execute
    with self.db.wrap_database_errors:
  File "/home/nadeemramli/.pyenv/versions/3.10.7/lib/python3.10/site-packages/django/db/utils.py", line 91, in __exit__
    raise dj_exc_value.with_traceback(traceback) from exc_value
  File "/home/nadeemramli/.pyenv/versions/3.10.7/lib/python3.10/site-packages/django/db/backends/utils.py", line 103, in _execute
    return self.cursor.execute(sql)
django.db.utils.IntegrityError: insert or update on table "metrics_project" violates foreign key constraint "metrics_project_tenant_id_db4a1170_fk_metrics_client_id"
DETAIL:  Key (tenant_id)=(2) is not present in table "metrics_client".


======================================================================
ERROR: test_get_metric_reports (metrics.tests.test_apis.APITests)
----------------------------------------------------------------------
Traceback (most recent call last):
  File "/home/nadeemramli/workspace/github.com/nadeemramli/mapping-of-metrics/metric-map-app/backend/metricMapAPI/metrics/tests/test_apis.py", line 154, in test_get_metric_reports
    url = self.get_client_project_url('metric-reports', pk=self.metric.pk)
  File "/home/nadeemramli/workspace/github.com/nadeemramli/mapping-of-metrics/metric-map-app/backend/metricMapAPI/metrics/tests/test_apis.py", line 42, in get_client_project_url
    return reverse(viewname, kwargs={'client_pk': client_pk, 'project_pk': project_pk, **kwargs})
  File "/home/nadeemramli/.pyenv/versions/3.10.7/lib/python3.10/site-packages/django/urls/base.py", line 88, in reverse
    return resolver._reverse_with_prefix(view, prefix, *args, **kwargs)
  File "/home/nadeemramli/.pyenv/versions/3.10.7/lib/python3.10/site-packages/django/urls/resolvers.py", line 851, in _reverse_with_prefix
    raise NoReverseMatch(msg)
django.urls.exceptions.NoReverseMatch: Reverse for 'metric-reports' with keyword arguments '{'client_pk': 2, 'project_pk': 18, 'pk': 18}' not found. 6 pattern(s) tried: ['api/clients/(?P<client__pk>[^/.]+)/projects/(?P<project__pk>[^/.]+)/metrics/(?P<pk>[^/.]+)/reports/$', 'api/clients/(?P<client__pk>[^/.]+)/projects/(?P<project__pk>[^/.]+)/metrics/(?P<pk>[^/.]+)/reports/$', 'api/clients/(?P<client__pk>[^/.]+)/projects/(?P<project__pk>[^/.]+)/metrics/(?P<pk>[^/.]+)/reports/$', 'api/clients/(?P<client__pk>[^/.]+)/projects/(?P<project__pk>[^/.]+)/metrics/(?P<pk>[^/.]+)/reports/$', 'api/clients/(?P<client__pk>[^/.]+)/projects/(?P<project__pk>[^/.]+)/metrics/(?P<pk>[^/.]+)/reports/$', 'api/clients/(?P<client__pk>[^/.]+)/projects/(?P<project__pk>[^/.]+)/metrics/(?P<pk>[^/.]+)/reports/$']

======================================================================
ERROR: test_get_metric_reports (metrics.tests.test_apis.APITests)
----------------------------------------------------------------------
Traceback (most recent call last):
  File "/home/nadeemramli/.pyenv/versions/3.10.7/lib/python3.10/site-packages/django/db/backends/utils.py", line 103, in _execute
    return self.cursor.execute(sql)
psycopg2.errors.ForeignKeyViolation: insert or update on table "metrics_project" violates foreign key constraint "metrics_project_tenant_id_db4a1170_fk_metrics_client_id"
DETAIL:  Key (tenant_id)=(2) is not present in table "metrics_client".


The above exception was the direct cause of the following exception:

Traceback (most recent call last):
  File "/home/nadeemramli/.pyenv/versions/3.10.7/lib/python3.10/site-packages/django/test/testcases.py", line 296, in _setup_and_call
    self._post_teardown()
  File "/home/nadeemramli/.pyenv/versions/3.10.7/lib/python3.10/site-packages/django/test/testcases.py", line 1102, in _post_teardown
    self._fixture_teardown()
  File "/home/nadeemramli/.pyenv/versions/3.10.7/lib/python3.10/site-packages/django/test/testcases.py", line 1333, in _fixture_teardown
    connections[db_name].check_constraints()
  File "/home/nadeemramli/.pyenv/versions/3.10.7/lib/python3.10/site-packages/django/db/backends/postgresql/base.py", line 385, in check_constraints
    cursor.execute("SET CONSTRAINTS ALL IMMEDIATE")
  File "/home/nadeemramli/.pyenv/versions/3.10.7/lib/python3.10/site-packages/django/db/backends/utils.py", line 79, in execute
    return self._execute_with_wrappers(
  File "/home/nadeemramli/.pyenv/versions/3.10.7/lib/python3.10/site-packages/django/db/backends/utils.py", line 92, in _execute_with_wrappers
    return executor(sql, params, many, context)
  File "/home/nadeemramli/.pyenv/versions/3.10.7/lib/python3.10/site-packages/django/db/backends/utils.py", line 100, in _execute
    with self.db.wrap_database_errors:
  File "/home/nadeemramli/.pyenv/versions/3.10.7/lib/python3.10/site-packages/django/db/utils.py", line 91, in __exit__
    raise dj_exc_value.with_traceback(traceback) from exc_value
  File "/home/nadeemramli/.pyenv/versions/3.10.7/lib/python3.10/site-packages/django/db/backends/utils.py", line 103, in _execute
    return self.cursor.execute(sql)
django.db.utils.IntegrityError: insert or update on table "metrics_project" violates foreign key constraint "metrics_project_tenant_id_db4a1170_fk_metrics_client_id"
DETAIL:  Key (tenant_id)=(2) is not present in table "metrics_client".

