Ran 30 tests in 19.110 seconds

=== Starting migration
Operations to perform:
  Apply all migrations: admin, auth, authtoken, contenttypes, metrics, sessions
Running migrations:
  Applying contenttypes.0001_initial...
 OK
  Applying auth.0001_initial...
 OK
  Applying admin.0001_initial...
 OK
  Applying admin.0002_logentry_remove_auto_add...
 OK
  Applying admin.0003_logentry_add_action_flag_choices...
 OK
  Applying contenttypes.0002_remove_content_type_name...
 OK
  Applying auth.0002_alter_permission_name_max_length...
 OK
  Applying auth.0003_alter_user_email_max_length...
 OK
  Applying auth.0004_alter_user_username_opts...
 OK
  Applying auth.0005_alter_user_last_login_null...
 OK
  Applying auth.0006_require_contenttypes_0002...
 OK
  Applying auth.0007_alter_validators_add_error_messages...
 OK
  Applying auth.0008_alter_user_username_max_length...
 OK
  Applying auth.0009_alter_user_last_name_max_length...
 OK
  Applying auth.0010_alter_group_name_max_length...
 OK
  Applying auth.0011_update_proxy_permissions...
 OK
  Applying auth.0012_alter_user_first_name_max_length...
 OK
  Applying authtoken.0001_initial...
 OK
  Applying authtoken.0002_auto_20160226_1747...
 OK
  Applying authtoken.0003_tokenproxy...
 OK
  Applying authtoken.0004_alter_tokenproxy_options...
 OK
  Applying metrics.0001_initial...
 OK
  Applying sessions.0001_initial...
 OK
EE=== Starting migration
Operations to perform:
  Apply all migrations: admin, auth, authtoken, contenttypes, metrics, sessions
Running migrations:
  Applying contenttypes.0001_initial...
 OK
  Applying auth.0001_initial...
 OK
  Applying admin.0001_initial...
 OK
  Applying admin.0002_logentry_remove_auto_add...
 OK
  Applying admin.0003_logentry_add_action_flag_choices...
 OK
  Applying contenttypes.0002_remove_content_type_name...
 OK
  Applying auth.0002_alter_permission_name_max_length...
 OK
  Applying auth.0003_alter_user_email_max_length...
 OK
  Applying auth.0004_alter_user_username_opts...
 OK
  Applying auth.0005_alter_user_last_login_null...
 OK
  Applying auth.0006_require_contenttypes_0002...
 OK
  Applying auth.0007_alter_validators_add_error_messages...
 OK
  Applying auth.0008_alter_user_username_max_length...
 OK
  Applying auth.0009_alter_user_last_name_max_length...
 OK
  Applying auth.0010_alter_group_name_max_length...
 OK
  Applying auth.0011_update_proxy_permissions...
 OK
  Applying auth.0012_alter_user_first_name_max_length...
 OK
  Applying authtoken.0001_initial...
 OK
  Applying authtoken.0002_auto_20160226_1747...
 OK
  Applying authtoken.0003_tokenproxy...
 OK
  Applying authtoken.0004_alter_tokenproxy_options...
 OK
  Applying metrics.0001_initial...
 OK
  Applying sessions.0001_initial...
 OK
EE=== Starting migration
Operations to perform:
  Apply all migrations: admin, auth, authtoken, contenttypes, metrics, sessions
Running migrations:
  Applying contenttypes.0001_initial...
 OK
  Applying auth.0001_initial...
 OK
  Applying admin.0001_initial...
 OK
  Applying admin.0002_logentry_remove_auto_add...
 OK
  Applying admin.0003_logentry_add_action_flag_choices...
 OK
  Applying contenttypes.0002_remove_content_type_name...
 OK
  Applying auth.0002_alter_permission_name_max_length...
 OK
  Applying auth.0003_alter_user_email_max_length...
 OK
  Applying auth.0004_alter_user_username_opts...
 OK
  Applying auth.0005_alter_user_last_login_null...
 OK
  Applying auth.0006_require_contenttypes_0002...
 OK
  Applying auth.0007_alter_validators_add_error_messages...
 OK
  Applying auth.0008_alter_user_username_max_length...
 OK
  Applying auth.0009_alter_user_last_name_max_length...
 OK
  Applying auth.0010_alter_group_name_max_length...
 OK
  Applying auth.0011_update_proxy_permissions...
 OK
  Applying auth.0012_alter_user_first_name_max_length...
 OK
  Applying authtoken.0001_initial...
 OK
  Applying authtoken.0002_auto_20160226_1747...
 OK
  Applying authtoken.0003_tokenproxy...
 OK
  Applying authtoken.0004_alter_tokenproxy_options...
 OK
  Applying metrics.0001_initial...
 OK
  Applying sessions.0001_initial...
 OK
EE=== Starting migration
Operations to perform:
  Apply all migrations: admin, auth, authtoken, contenttypes, metrics, sessions
Running migrations:
  Applying contenttypes.0001_initial...
 OK
  Applying auth.0001_initial...
 OK
  Applying admin.0001_initial...
 OK
  Applying admin.0002_logentry_remove_auto_add...
 OK
  Applying admin.0003_logentry_add_action_flag_choices...
 OK
  Applying contenttypes.0002_remove_content_type_name...
 OK
  Applying auth.0002_alter_permission_name_max_length...
 OK
  Applying auth.0003_alter_user_email_max_length...
 OK
  Applying auth.0004_alter_user_username_opts...
 OK
  Applying auth.0005_alter_user_last_login_null...
 OK
  Applying auth.0006_require_contenttypes_0002...
 OK
  Applying auth.0007_alter_validators_add_error_messages...
 OK
  Applying auth.0008_alter_user_username_max_length...
 OK
  Applying auth.0009_alter_user_last_name_max_length...
 OK
  Applying auth.0010_alter_group_name_max_length...
 OK
  Applying auth.0011_update_proxy_permissions...
 OK
  Applying auth.0012_alter_user_first_name_max_length...
 OK
  Applying authtoken.0001_initial...
 OK
  Applying authtoken.0002_auto_20160226_1747...
 OK
  Applying authtoken.0003_tokenproxy...
 OK
  Applying authtoken.0004_alter_tokenproxy_options...
 OK
  Applying metrics.0001_initial...
 OK
  Applying sessions.0001_initial...
 OK
EE=== Starting migration
Operations to perform:
  Apply all migrations: admin, auth, authtoken, contenttypes, metrics, sessions
Running migrations:
  Applying contenttypes.0001_initial...
 OK
  Applying auth.0001_initial...
 OK
  Applying admin.0001_initial...
 OK
  Applying admin.0002_logentry_remove_auto_add...
 OK
  Applying admin.0003_logentry_add_action_flag_choices...
 OK
  Applying contenttypes.0002_remove_content_type_name...
 OK
  Applying auth.0002_alter_permission_name_max_length...
 OK
  Applying auth.0003_alter_user_email_max_length...
 OK
  Applying auth.0004_alter_user_username_opts...
 OK
  Applying auth.0005_alter_user_last_login_null...
 OK
  Applying auth.0006_require_contenttypes_0002...
 OK
  Applying auth.0007_alter_validators_add_error_messages...
 OK
  Applying auth.0008_alter_user_username_max_length...
 OK
  Applying auth.0009_alter_user_last_name_max_length...
 OK
  Applying auth.0010_alter_group_name_max_length...
 OK
  Applying auth.0011_update_proxy_permissions...
 OK
  Applying auth.0012_alter_user_first_name_max_length...
 OK
  Applying authtoken.0001_initial...
 OK
  Applying authtoken.0002_auto_20160226_1747...
 OK
  Applying authtoken.0003_tokenproxy...
 OK
  Applying authtoken.0004_alter_tokenproxy_options...
 OK
  Applying metrics.0001_initial...
 OK
  Applying sessions.0001_initial...
 OK
EE=== Starting migration
Operations to perform:
  Apply all migrations: admin, auth, authtoken, contenttypes, metrics, sessions
Running migrations:
  Applying contenttypes.0001_initial...
 OK
  Applying auth.0001_initial...
 OK
  Applying admin.0001_initial...
 OK
  Applying admin.0002_logentry_remove_auto_add...
 OK
  Applying admin.0003_logentry_add_action_flag_choices...
 OK
  Applying contenttypes.0002_remove_content_type_name...
 OK
  Applying auth.0002_alter_permission_name_max_length...
 OK
  Applying auth.0003_alter_user_email_max_length...
 OK
  Applying auth.0004_alter_user_username_opts...
 OK
  Applying auth.0005_alter_user_last_login_null...
 OK
  Applying auth.0006_require_contenttypes_0002...
 OK
  Applying auth.0007_alter_validators_add_error_messages...
 OK
  Applying auth.0008_alter_user_username_max_length...
 OK
  Applying auth.0009_alter_user_last_name_max_length...
 OK
  Applying auth.0010_alter_group_name_max_length...
 OK
  Applying auth.0011_update_proxy_permissions...
 OK
  Applying auth.0012_alter_user_first_name_max_length...
 OK
  Applying authtoken.0001_initial...
 OK
  Applying authtoken.0002_auto_20160226_1747...
 OK
  Applying authtoken.0003_tokenproxy...
 OK
  Applying authtoken.0004_alter_tokenproxy_options...
 OK
  Applying metrics.0001_initial...
 OK
  Applying sessions.0001_initial...
 OK
EE=== Starting migration
Operations to perform:
  Apply all migrations: admin, auth, authtoken, contenttypes, metrics, sessions
Running migrations:
  Applying contenttypes.0001_initial...
 OK
  Applying auth.0001_initial...
 OK
  Applying admin.0001_initial...
 OK
  Applying admin.0002_logentry_remove_auto_add...
 OK
  Applying admin.0003_logentry_add_action_flag_choices...
 OK
  Applying contenttypes.0002_remove_content_type_name...
 OK
  Applying auth.0002_alter_permission_name_max_length...
 OK
  Applying auth.0003_alter_user_email_max_length...
 OK
  Applying auth.0004_alter_user_username_opts...
 OK
  Applying auth.0005_alter_user_last_login_null...
 OK
  Applying auth.0006_require_contenttypes_0002...
 OK
  Applying auth.0007_alter_validators_add_error_messages...
 OK
  Applying auth.0008_alter_user_username_max_length...
 OK
  Applying auth.0009_alter_user_last_name_max_length...
 OK
  Applying auth.0010_alter_group_name_max_length...
 OK
  Applying auth.0011_update_proxy_permissions...
 OK
  Applying auth.0012_alter_user_first_name_max_length...
 OK
  Applying authtoken.0001_initial...
 OK
  Applying authtoken.0002_auto_20160226_1747...
 OK
  Applying authtoken.0003_tokenproxy...
 OK
  Applying authtoken.0004_alter_tokenproxy_options...
 OK
  Applying metrics.0001_initial...
 OK
  Applying sessions.0001_initial...
 OK
EE=== Starting migration
Operations to perform:
  Apply all migrations: admin, auth, authtoken, contenttypes, metrics, sessions
Running migrations:
  Applying contenttypes.0001_initial...
 OK
  Applying auth.0001_initial...
 OK
  Applying admin.0001_initial...
 OK
  Applying admin.0002_logentry_remove_auto_add...
 OK
  Applying admin.0003_logentry_add_action_flag_choices...
 OK
  Applying contenttypes.0002_remove_content_type_name...
 OK
  Applying auth.0002_alter_permission_name_max_length...
 OK
  Applying auth.0003_alter_user_email_max_length...
 OK
  Applying auth.0004_alter_user_username_opts...
 OK
  Applying auth.0005_alter_user_last_login_null...
 OK
  Applying auth.0006_require_contenttypes_0002...
 OK
  Applying auth.0007_alter_validators_add_error_messages...
 OK
  Applying auth.0008_alter_user_username_max_length...
 OK
  Applying auth.0009_alter_user_last_name_max_length...
 OK
  Applying auth.0010_alter_group_name_max_length...
 OK
  Applying auth.0011_update_proxy_permissions...
 OK
  Applying auth.0012_alter_user_first_name_max_length...
 OK
  Applying authtoken.0001_initial...
 OK
  Applying authtoken.0002_auto_20160226_1747...
 OK
  Applying authtoken.0003_tokenproxy...
 OK
  Applying authtoken.0004_alter_tokenproxy_options...
 OK
  Applying metrics.0001_initial...
 OK
  Applying sessions.0001_initial...
 OK
EE=== Starting migration
Operations to perform:
  Apply all migrations: admin, auth, authtoken, contenttypes, metrics, sessions
Running migrations:
  Applying contenttypes.0001_initial...
 OK
  Applying auth.0001_initial...
 OK
  Applying admin.0001_initial...
 OK
  Applying admin.0002_logentry_remove_auto_add...
 OK
  Applying admin.0003_logentry_add_action_flag_choices...
 OK
  Applying contenttypes.0002_remove_content_type_name...
 OK
  Applying auth.0002_alter_permission_name_max_length...
 OK
  Applying auth.0003_alter_user_email_max_length...
 OK
  Applying auth.0004_alter_user_username_opts...
 OK
  Applying auth.0005_alter_user_last_login_null...
 OK
  Applying auth.0006_require_contenttypes_0002...
 OK
  Applying auth.0007_alter_validators_add_error_messages...
 OK
  Applying auth.0008_alter_user_username_max_length...
 OK
  Applying auth.0009_alter_user_last_name_max_length...
 OK
  Applying auth.0010_alter_group_name_max_length...
 OK
  Applying auth.0011_update_proxy_permissions...
 OK
  Applying auth.0012_alter_user_first_name_max_length...
 OK
  Applying authtoken.0001_initial...
 OK
  Applying authtoken.0002_auto_20160226_1747...
 OK
  Applying authtoken.0003_tokenproxy...
 OK
  Applying authtoken.0004_alter_tokenproxy_options...
 OK
  Applying metrics.0001_initial...
 OK
  Applying sessions.0001_initial...
 OK
EE=== Starting migration
Operations to perform:
  Apply all migrations: admin, auth, authtoken, contenttypes, metrics, sessions
Running migrations:
  Applying contenttypes.0001_initial...
 OK
  Applying auth.0001_initial...
 OK
  Applying admin.0001_initial...
 OK
  Applying admin.0002_logentry_remove_auto_add...
 OK
  Applying admin.0003_logentry_add_action_flag_choices...
 OK
  Applying contenttypes.0002_remove_content_type_name...
 OK
  Applying auth.0002_alter_permission_name_max_length...
 OK
  Applying auth.0003_alter_user_email_max_length...
 OK
  Applying auth.0004_alter_user_username_opts...
 OK
  Applying auth.0005_alter_user_last_login_null...
 OK
  Applying auth.0006_require_contenttypes_0002...
 OK
  Applying auth.0007_alter_validators_add_error_messages...
 OK
  Applying auth.0008_alter_user_username_max_length...
 OK
  Applying auth.0009_alter_user_last_name_max_length...
 OK
  Applying auth.0010_alter_group_name_max_length...
 OK
  Applying auth.0011_update_proxy_permissions...
 OK
  Applying auth.0012_alter_user_first_name_max_length...
 OK
  Applying authtoken.0001_initial...
 OK
  Applying authtoken.0002_auto_20160226_1747...
 OK
  Applying authtoken.0003_tokenproxy...
 OK
  Applying authtoken.0004_alter_tokenproxy_options...
 OK
  Applying metrics.0001_initial...
 OK
  Applying sessions.0001_initial...
 OK
EE=== Starting migration
Operations to perform:
  Apply all migrations: admin, auth, authtoken, contenttypes, metrics, sessions
Running migrations:
  Applying contenttypes.0001_initial...
 OK
  Applying auth.0001_initial...
 OK
  Applying admin.0001_initial...
 OK
  Applying admin.0002_logentry_remove_auto_add...
 OK
  Applying admin.0003_logentry_add_action_flag_choices...
 OK
  Applying contenttypes.0002_remove_content_type_name...
 OK
  Applying auth.0002_alter_permission_name_max_length...
 OK
  Applying auth.0003_alter_user_email_max_length...
 OK
  Applying auth.0004_alter_user_username_opts...
 OK
  Applying auth.0005_alter_user_last_login_null...
 OK
  Applying auth.0006_require_contenttypes_0002...
 OK
  Applying auth.0007_alter_validators_add_error_messages...
 OK
  Applying auth.0008_alter_user_username_max_length...
 OK
  Applying auth.0009_alter_user_last_name_max_length...
 OK
  Applying auth.0010_alter_group_name_max_length...
 OK
  Applying auth.0011_update_proxy_permissions...
 OK
  Applying auth.0012_alter_user_first_name_max_length...
 OK
  Applying authtoken.0001_initial...
 OK
  Applying authtoken.0002_auto_20160226_1747...
 OK
  Applying authtoken.0003_tokenproxy...
 OK
  Applying authtoken.0004_alter_tokenproxy_options...
 OK
  Applying metrics.0001_initial...
 OK
  Applying sessions.0001_initial...
 OK
EE=== Starting migration
Operations to perform:
  Apply all migrations: admin, auth, authtoken, contenttypes, metrics, sessions
Running migrations:
  Applying contenttypes.0001_initial...
 OK
  Applying auth.0001_initial...
 OK
  Applying admin.0001_initial...
 OK
  Applying admin.0002_logentry_remove_auto_add...
 OK
  Applying admin.0003_logentry_add_action_flag_choices...
 OK
  Applying contenttypes.0002_remove_content_type_name...
 OK
  Applying auth.0002_alter_permission_name_max_length...
 OK
  Applying auth.0003_alter_user_email_max_length...
 OK
  Applying auth.0004_alter_user_username_opts...
 OK
  Applying auth.0005_alter_user_last_login_null...
 OK
  Applying auth.0006_require_contenttypes_0002...
 OK
  Applying auth.0007_alter_validators_add_error_messages...
 OK
  Applying auth.0008_alter_user_username_max_length...
 OK
  Applying auth.0009_alter_user_last_name_max_length...
 OK
  Applying auth.0010_alter_group_name_max_length...
 OK
  Applying auth.0011_update_proxy_permissions...
 OK
  Applying auth.0012_alter_user_first_name_max_length...
 OK
  Applying authtoken.0001_initial...
 OK
  Applying authtoken.0002_auto_20160226_1747...
 OK
  Applying authtoken.0003_tokenproxy...
 OK
  Applying authtoken.0004_alter_tokenproxy_options...
 OK
  Applying metrics.0001_initial...
 OK
  Applying sessions.0001_initial...
 OK
EE=== Starting migration
Operations to perform:
  Apply all migrations: admin, auth, authtoken, contenttypes, metrics, sessions
Running migrations:
  Applying contenttypes.0001_initial...
 OK
  Applying auth.0001_initial...
 OK
  Applying admin.0001_initial...
 OK
  Applying admin.0002_logentry_remove_auto_add...
 OK
  Applying admin.0003_logentry_add_action_flag_choices...
 OK
  Applying contenttypes.0002_remove_content_type_name...
 OK
  Applying auth.0002_alter_permission_name_max_length...
 OK
  Applying auth.0003_alter_user_email_max_length...
 OK
  Applying auth.0004_alter_user_username_opts...
 OK
  Applying auth.0005_alter_user_last_login_null...
 OK
  Applying auth.0006_require_contenttypes_0002...
 OK
  Applying auth.0007_alter_validators_add_error_messages...
 OK
  Applying auth.0008_alter_user_username_max_length...
 OK
  Applying auth.0009_alter_user_last_name_max_length...
 OK
  Applying auth.0010_alter_group_name_max_length...
 OK
  Applying auth.0011_update_proxy_permissions...
 OK
  Applying auth.0012_alter_user_first_name_max_length...
 OK
  Applying authtoken.0001_initial...
 OK
  Applying authtoken.0002_auto_20160226_1747...
 OK
  Applying authtoken.0003_tokenproxy...
 OK
  Applying authtoken.0004_alter_tokenproxy_options...
 OK
  Applying metrics.0001_initial...
 OK
  Applying sessions.0001_initial...
 OK
EE=== Starting migration
Operations to perform:
  Apply all migrations: admin, auth, authtoken, contenttypes, metrics, sessions
Running migrations:
  Applying contenttypes.0001_initial...
 OK
  Applying auth.0001_initial...
 OK
  Applying admin.0001_initial...
 OK
  Applying admin.0002_logentry_remove_auto_add...
 OK
  Applying admin.0003_logentry_add_action_flag_choices...
 OK
  Applying contenttypes.0002_remove_content_type_name...
 OK
  Applying auth.0002_alter_permission_name_max_length...
 OK
  Applying auth.0003_alter_user_email_max_length...
 OK
  Applying auth.0004_alter_user_username_opts...
 OK
  Applying auth.0005_alter_user_last_login_null...
 OK
  Applying auth.0006_require_contenttypes_0002...
 OK
  Applying auth.0007_alter_validators_add_error_messages...
 OK
  Applying auth.0008_alter_user_username_max_length...
 OK
  Applying auth.0009_alter_user_last_name_max_length...
 OK
  Applying auth.0010_alter_group_name_max_length...
 OK
  Applying auth.0011_update_proxy_permissions...
 OK
  Applying auth.0012_alter_user_first_name_max_length...
 OK
  Applying authtoken.0001_initial...
 OK
  Applying authtoken.0002_auto_20160226_1747...
 OK
  Applying authtoken.0003_tokenproxy...
 OK
  Applying authtoken.0004_alter_tokenproxy_options...
 OK
  Applying metrics.0001_initial...
 OK
  Applying sessions.0001_initial...
 OK
EE=== Starting migration
Operations to perform:
  Apply all migrations: admin, auth, authtoken, contenttypes, metrics, sessions
Running migrations:
  Applying contenttypes.0001_initial...
 OK
  Applying auth.0001_initial...
 OK
  Applying admin.0001_initial...
 OK
  Applying admin.0002_logentry_remove_auto_add...
 OK
  Applying admin.0003_logentry_add_action_flag_choices...
 OK
  Applying contenttypes.0002_remove_content_type_name...
 OK
  Applying auth.0002_alter_permission_name_max_length...
 OK
  Applying auth.0003_alter_user_email_max_length...
 OK
  Applying auth.0004_alter_user_username_opts...
 OK
  Applying auth.0005_alter_user_last_login_null...
 OK
  Applying auth.0006_require_contenttypes_0002...
 OK
  Applying auth.0007_alter_validators_add_error_messages...
 OK
  Applying auth.0008_alter_user_username_max_length...
 OK
  Applying auth.0009_alter_user_last_name_max_length...
 OK
  Applying auth.0010_alter_group_name_max_length...
 OK
  Applying auth.0011_update_proxy_permissions...
 OK
  Applying auth.0012_alter_user_first_name_max_length...
 OK
  Applying authtoken.0001_initial...
 OK
  Applying authtoken.0002_auto_20160226_1747...
 OK
  Applying authtoken.0003_tokenproxy...
 OK
  Applying authtoken.0004_alter_tokenproxy_options...
 OK
  Applying metrics.0001_initial...
 OK
  Applying sessions.0001_initial...
 OK
EE=== Starting migration
Operations to perform:
  Apply all migrations: admin, auth, authtoken, contenttypes, metrics, sessions
Running migrations:
  Applying contenttypes.0001_initial...
 OK
  Applying auth.0001_initial...
 OK
  Applying admin.0001_initial...
 OK
  Applying admin.0002_logentry_remove_auto_add...
 OK
  Applying admin.0003_logentry_add_action_flag_choices...
 OK
  Applying contenttypes.0002_remove_content_type_name...
 OK
  Applying auth.0002_alter_permission_name_max_length...
 OK
  Applying auth.0003_alter_user_email_max_length...
 OK
  Applying auth.0004_alter_user_username_opts...
 OK
  Applying auth.0005_alter_user_last_login_null...
 OK
  Applying auth.0006_require_contenttypes_0002...
 OK
  Applying auth.0007_alter_validators_add_error_messages...
 OK
  Applying auth.0008_alter_user_username_max_length...
 OK
  Applying auth.0009_alter_user_last_name_max_length...
 OK
  Applying auth.0010_alter_group_name_max_length...
 OK
  Applying auth.0011_update_proxy_permissions...
 OK
  Applying auth.0012_alter_user_first_name_max_length...
 OK
  Applying authtoken.0001_initial...
 OK
  Applying authtoken.0002_auto_20160226_1747...
 OK
  Applying authtoken.0003_tokenproxy...
 OK
  Applying authtoken.0004_alter_tokenproxy_options...
 OK
  Applying metrics.0001_initial...
 OK
  Applying sessions.0001_initial...
 OK
EE=== Starting migration
Operations to perform:
  Apply all migrations: admin, auth, authtoken, contenttypes, metrics, sessions
Running migrations:
  Applying contenttypes.0001_initial...
 OK
  Applying auth.0001_initial...
 OK
  Applying admin.0001_initial...
 OK
  Applying admin.0002_logentry_remove_auto_add...
 OK
  Applying admin.0003_logentry_add_action_flag_choices...
 OK
  Applying contenttypes.0002_remove_content_type_name...
 OK
  Applying auth.0002_alter_permission_name_max_length...
 OK
  Applying auth.0003_alter_user_email_max_length...
 OK
  Applying auth.0004_alter_user_username_opts...
 OK
  Applying auth.0005_alter_user_last_login_null...
 OK
  Applying auth.0006_require_contenttypes_0002...
 OK
  Applying auth.0007_alter_validators_add_error_messages...
 OK
  Applying auth.0008_alter_user_username_max_length...
 OK
  Applying auth.0009_alter_user_last_name_max_length...
 OK
  Applying auth.0010_alter_group_name_max_length...
 OK
  Applying auth.0011_update_proxy_permissions...
 OK
  Applying auth.0012_alter_user_first_name_max_length...
 OK
  Applying authtoken.0001_initial...
 OK
  Applying authtoken.0002_auto_20160226_1747...
 OK
  Applying authtoken.0003_tokenproxy...
 OK
  Applying authtoken.0004_alter_tokenproxy_options...
 OK
  Applying metrics.0001_initial...
 OK
  Applying sessions.0001_initial...
 OK
EE=== Starting migration
Operations to perform:
  Apply all migrations: admin, auth, authtoken, contenttypes, metrics, sessions
Running migrations:
  Applying contenttypes.0001_initial...
 OK
  Applying auth.0001_initial...
 OK
  Applying admin.0001_initial...
 OK
  Applying admin.0002_logentry_remove_auto_add...
 OK
  Applying admin.0003_logentry_add_action_flag_choices...
 OK
  Applying contenttypes.0002_remove_content_type_name...
 OK
  Applying auth.0002_alter_permission_name_max_length...
 OK
  Applying auth.0003_alter_user_email_max_length...
 OK
  Applying auth.0004_alter_user_username_opts...
 OK
  Applying auth.0005_alter_user_last_login_null...
 OK
  Applying auth.0006_require_contenttypes_0002...
 OK
  Applying auth.0007_alter_validators_add_error_messages...
 OK
  Applying auth.0008_alter_user_username_max_length...
 OK
  Applying auth.0009_alter_user_last_name_max_length...
 OK
  Applying auth.0010_alter_group_name_max_length...
 OK
  Applying auth.0011_update_proxy_permissions...
 OK
  Applying auth.0012_alter_user_first_name_max_length...
 OK
  Applying authtoken.0001_initial...
 OK
  Applying authtoken.0002_auto_20160226_1747...
 OK
  Applying authtoken.0003_tokenproxy...
 OK
  Applying authtoken.0004_alter_tokenproxy_options...
 OK
  Applying metrics.0001_initial...
 OK
  Applying sessions.0001_initial...
 OK
EE=== Starting migration
Operations to perform:
  Apply all migrations: admin, auth, authtoken, contenttypes, metrics, sessions
Running migrations:
  Applying contenttypes.0001_initial...
 OK
  Applying auth.0001_initial...
 OK
  Applying admin.0001_initial...
 OK
  Applying admin.0002_logentry_remove_auto_add...
 OK
  Applying admin.0003_logentry_add_action_flag_choices...
 OK
  Applying contenttypes.0002_remove_content_type_name...
 OK
  Applying auth.0002_alter_permission_name_max_length...
 OK
  Applying auth.0003_alter_user_email_max_length...
 OK
  Applying auth.0004_alter_user_username_opts...
 OK
  Applying auth.0005_alter_user_last_login_null...
 OK
  Applying auth.0006_require_contenttypes_0002...
 OK
  Applying auth.0007_alter_validators_add_error_messages...
 OK
  Applying auth.0008_alter_user_username_max_length...
 OK
  Applying auth.0009_alter_user_last_name_max_length...
 OK
  Applying auth.0010_alter_group_name_max_length...
 OK
  Applying auth.0011_update_proxy_permissions...
 OK
  Applying auth.0012_alter_user_first_name_max_length...
 OK
  Applying authtoken.0001_initial...
 OK
  Applying authtoken.0002_auto_20160226_1747...
 OK
  Applying authtoken.0003_tokenproxy...
 OK
  Applying authtoken.0004_alter_tokenproxy_options...
 OK
  Applying metrics.0001_initial...
 OK
  Applying sessions.0001_initial...
 OK
EE=== Starting migration
Operations to perform:
  Apply all migrations: admin, auth, authtoken, contenttypes, metrics, sessions
Running migrations:
  Applying contenttypes.0001_initial...
 OK
  Applying auth.0001_initial...
 OK
  Applying admin.0001_initial...
 OK
  Applying admin.0002_logentry_remove_auto_add...
 OK
  Applying admin.0003_logentry_add_action_flag_choices...
 OK
  Applying contenttypes.0002_remove_content_type_name...
 OK
  Applying auth.0002_alter_permission_name_max_length...
 OK
  Applying auth.0003_alter_user_email_max_length...
 OK
  Applying auth.0004_alter_user_username_opts...
 OK
  Applying auth.0005_alter_user_last_login_null...
 OK
  Applying auth.0006_require_contenttypes_0002...
 OK
  Applying auth.0007_alter_validators_add_error_messages...
 OK
  Applying auth.0008_alter_user_username_max_length...
 OK
  Applying auth.0009_alter_user_last_name_max_length...
 OK
  Applying auth.0010_alter_group_name_max_length...
 OK
  Applying auth.0011_update_proxy_permissions...
 OK
  Applying auth.0012_alter_user_first_name_max_length...
 OK
  Applying authtoken.0001_initial...
 OK
  Applying authtoken.0002_auto_20160226_1747...
 OK
  Applying authtoken.0003_tokenproxy...
 OK
  Applying authtoken.0004_alter_tokenproxy_options...
 OK
  Applying metrics.0001_initial...
 OK
  Applying sessions.0001_initial...
 OK
EE=== Starting migration
Operations to perform:
  Apply all migrations: admin, auth, authtoken, contenttypes, metrics, sessions
Running migrations:
  Applying contenttypes.0001_initial...
 OK
  Applying auth.0001_initial...
 OK
  Applying admin.0001_initial...
 OK
  Applying admin.0002_logentry_remove_auto_add...
 OK
  Applying admin.0003_logentry_add_action_flag_choices...
 OK
  Applying contenttypes.0002_remove_content_type_name...
 OK
  Applying auth.0002_alter_permission_name_max_length...
 OK
  Applying auth.0003_alter_user_email_max_length...
 OK
  Applying auth.0004_alter_user_username_opts...
 OK
  Applying auth.0005_alter_user_last_login_null...
 OK
  Applying auth.0006_require_contenttypes_0002...
 OK
  Applying auth.0007_alter_validators_add_error_messages...
 OK
  Applying auth.0008_alter_user_username_max_length...
 OK
  Applying auth.0009_alter_user_last_name_max_length...
 OK
  Applying auth.0010_alter_group_name_max_length...
 OK
  Applying auth.0011_update_proxy_permissions...
 OK
  Applying auth.0012_alter_user_first_name_max_length...
 OK
  Applying authtoken.0001_initial...
 OK
  Applying authtoken.0002_auto_20160226_1747...
 OK
  Applying authtoken.0003_tokenproxy...
 OK
  Applying authtoken.0004_alter_tokenproxy_options...
 OK
  Applying metrics.0001_initial...
 OK
  Applying sessions.0001_initial...
 OK
EE=== Starting migration
Operations to perform:
  Apply all migrations: admin, auth, authtoken, contenttypes, metrics, sessions
Running migrations:
  Applying contenttypes.0001_initial...
 OK
  Applying auth.0001_initial...
 OK
  Applying admin.0001_initial...
 OK
  Applying admin.0002_logentry_remove_auto_add...
 OK
  Applying admin.0003_logentry_add_action_flag_choices...
 OK
  Applying contenttypes.0002_remove_content_type_name...
 OK
  Applying auth.0002_alter_permission_name_max_length...
 OK
  Applying auth.0003_alter_user_email_max_length...
 OK
  Applying auth.0004_alter_user_username_opts...
 OK
  Applying auth.0005_alter_user_last_login_null...
 OK
  Applying auth.0006_require_contenttypes_0002...
 OK
  Applying auth.0007_alter_validators_add_error_messages...
 OK
  Applying auth.0008_alter_user_username_max_length...
 OK
  Applying auth.0009_alter_user_last_name_max_length...
 OK
  Applying auth.0010_alter_group_name_max_length...
 OK
  Applying auth.0011_update_proxy_permissions...
 OK
  Applying auth.0012_alter_user_first_name_max_length...
 OK
  Applying authtoken.0001_initial...
 OK
  Applying authtoken.0002_auto_20160226_1747...
 OK
  Applying authtoken.0003_tokenproxy...
 OK
  Applying authtoken.0004_alter_tokenproxy_options...
 OK
  Applying metrics.0001_initial...
 OK
  Applying sessions.0001_initial...
 OK
EE=== Starting migration
Operations to perform:
  Apply all migrations: admin, auth, authtoken, contenttypes, metrics, sessions
Running migrations:
  Applying contenttypes.0001_initial...
 OK
  Applying auth.0001_initial...
 OK
  Applying admin.0001_initial...
 OK
  Applying admin.0002_logentry_remove_auto_add...
 OK
  Applying admin.0003_logentry_add_action_flag_choices...
 OK
  Applying contenttypes.0002_remove_content_type_name...
 OK
  Applying auth.0002_alter_permission_name_max_length...
 OK
  Applying auth.0003_alter_user_email_max_length...
 OK
  Applying auth.0004_alter_user_username_opts...
 OK
  Applying auth.0005_alter_user_last_login_null...
 OK
  Applying auth.0006_require_contenttypes_0002...
 OK
  Applying auth.0007_alter_validators_add_error_messages...
 OK
  Applying auth.0008_alter_user_username_max_length...
 OK
  Applying auth.0009_alter_user_last_name_max_length...
 OK
  Applying auth.0010_alter_group_name_max_length...
 OK
  Applying auth.0011_update_proxy_permissions...
 OK
  Applying auth.0012_alter_user_first_name_max_length...
 OK
  Applying authtoken.0001_initial...
 OK
  Applying authtoken.0002_auto_20160226_1747...
 OK
  Applying authtoken.0003_tokenproxy...
 OK
  Applying authtoken.0004_alter_tokenproxy_options...
 OK
  Applying metrics.0001_initial...
 OK
  Applying sessions.0001_initial...
 OK
EE=== Starting migration
Operations to perform:
  Apply all migrations: admin, auth, authtoken, contenttypes, metrics, sessions
Running migrations:
  Applying contenttypes.0001_initial...
 OK
  Applying auth.0001_initial...
 OK
  Applying admin.0001_initial...
 OK
  Applying admin.0002_logentry_remove_auto_add...
 OK
  Applying admin.0003_logentry_add_action_flag_choices...
 OK
  Applying contenttypes.0002_remove_content_type_name...
 OK
  Applying auth.0002_alter_permission_name_max_length...
 OK
  Applying auth.0003_alter_user_email_max_length...
 OK
  Applying auth.0004_alter_user_username_opts...
 OK
  Applying auth.0005_alter_user_last_login_null...
 OK
  Applying auth.0006_require_contenttypes_0002...
 OK
  Applying auth.0007_alter_validators_add_error_messages...
 OK
  Applying auth.0008_alter_user_username_max_length...
 OK
  Applying auth.0009_alter_user_last_name_max_length...
 OK
  Applying auth.0010_alter_group_name_max_length...
 OK
  Applying auth.0011_update_proxy_permissions...
 OK
  Applying auth.0012_alter_user_first_name_max_length...
 OK
  Applying authtoken.0001_initial...
 OK
  Applying authtoken.0002_auto_20160226_1747...
 OK
  Applying authtoken.0003_tokenproxy...
 OK
  Applying authtoken.0004_alter_tokenproxy_options...
 OK
  Applying metrics.0001_initial...
 OK
  Applying sessions.0001_initial...
 OK
EE=== Starting migration
Operations to perform:
  Apply all migrations: admin, auth, authtoken, contenttypes, metrics, sessions
Running migrations:
  Applying contenttypes.0001_initial...
 OK
  Applying auth.0001_initial...
 OK
  Applying admin.0001_initial...
 OK
  Applying admin.0002_logentry_remove_auto_add...
 OK
  Applying admin.0003_logentry_add_action_flag_choices...
 OK
  Applying contenttypes.0002_remove_content_type_name...
 OK
  Applying auth.0002_alter_permission_name_max_length...
 OK
  Applying auth.0003_alter_user_email_max_length...
 OK
  Applying auth.0004_alter_user_username_opts...
 OK
  Applying auth.0005_alter_user_last_login_null...
 OK
  Applying auth.0006_require_contenttypes_0002...
 OK
  Applying auth.0007_alter_validators_add_error_messages...
 OK
  Applying auth.0008_alter_user_username_max_length...
 OK
  Applying auth.0009_alter_user_last_name_max_length...
 OK
  Applying auth.0010_alter_group_name_max_length...
 OK
  Applying auth.0011_update_proxy_permissions...
 OK
  Applying auth.0012_alter_user_first_name_max_length...
 OK
  Applying authtoken.0001_initial...
 OK
  Applying authtoken.0002_auto_20160226_1747...
 OK
  Applying authtoken.0003_tokenproxy...
 OK
  Applying authtoken.0004_alter_tokenproxy_options...
 OK
  Applying metrics.0001_initial...
 OK
  Applying sessions.0001_initial...
 OK
EE=== Starting migration
Operations to perform:
  Apply all migrations: admin, auth, authtoken, contenttypes, metrics, sessions
Running migrations:
  Applying contenttypes.0001_initial...
 OK
  Applying auth.0001_initial...
 OK
  Applying admin.0001_initial...
 OK
  Applying admin.0002_logentry_remove_auto_add...
 OK
  Applying admin.0003_logentry_add_action_flag_choices...
 OK
  Applying contenttypes.0002_remove_content_type_name...
 OK
  Applying auth.0002_alter_permission_name_max_length...
 OK
  Applying auth.0003_alter_user_email_max_length...
 OK
  Applying auth.0004_alter_user_username_opts...
 OK
  Applying auth.0005_alter_user_last_login_null...
 OK
  Applying auth.0006_require_contenttypes_0002...
 OK
  Applying auth.0007_alter_validators_add_error_messages...
 OK
  Applying auth.0008_alter_user_username_max_length...
 OK
  Applying auth.0009_alter_user_last_name_max_length...
 OK
  Applying auth.0010_alter_group_name_max_length...
 OK
  Applying auth.0011_update_proxy_permissions...
 OK
  Applying auth.0012_alter_user_first_name_max_length...
 OK
  Applying authtoken.0001_initial...
 OK
  Applying authtoken.0002_auto_20160226_1747...
 OK
  Applying authtoken.0003_tokenproxy...
 OK
  Applying authtoken.0004_alter_tokenproxy_options...
 OK
  Applying metrics.0001_initial...
 OK
  Applying sessions.0001_initial...
 OK
EE=== Starting migration
Operations to perform:
  Apply all migrations: admin, auth, authtoken, contenttypes, metrics, sessions
Running migrations:
  Applying contenttypes.0001_initial...
 OK
  Applying auth.0001_initial...
 OK
  Applying admin.0001_initial...
 OK
  Applying admin.0002_logentry_remove_auto_add...
 OK
  Applying admin.0003_logentry_add_action_flag_choices...
 OK
  Applying contenttypes.0002_remove_content_type_name...
 OK
  Applying auth.0002_alter_permission_name_max_length...
 OK
  Applying auth.0003_alter_user_email_max_length...
 OK
  Applying auth.0004_alter_user_username_opts...
 OK
  Applying auth.0005_alter_user_last_login_null...
 OK
  Applying auth.0006_require_contenttypes_0002...
 OK
  Applying auth.0007_alter_validators_add_error_messages...
 OK
  Applying auth.0008_alter_user_username_max_length...
 OK
  Applying auth.0009_alter_user_last_name_max_length...
 OK
  Applying auth.0010_alter_group_name_max_length...
 OK
  Applying auth.0011_update_proxy_permissions...
 OK
  Applying auth.0012_alter_user_first_name_max_length...
 OK
  Applying authtoken.0001_initial...
 OK
  Applying authtoken.0002_auto_20160226_1747...
 OK
  Applying authtoken.0003_tokenproxy...
 OK
  Applying authtoken.0004_alter_tokenproxy_options...
 OK
  Applying metrics.0001_initial...
 OK
  Applying sessions.0001_initial...
 OK
EE=== Starting migration
Operations to perform:
  Apply all migrations: admin, auth, authtoken, contenttypes, metrics, sessions
Running migrations:
  Applying contenttypes.0001_initial...
 OK
  Applying auth.0001_initial...
 OK
  Applying admin.0001_initial...
 OK
  Applying admin.0002_logentry_remove_auto_add...
 OK
  Applying admin.0003_logentry_add_action_flag_choices...
 OK
  Applying contenttypes.0002_remove_content_type_name...
 OK
  Applying auth.0002_alter_permission_name_max_length...
 OK
  Applying auth.0003_alter_user_email_max_length...
 OK
  Applying auth.0004_alter_user_username_opts...
 OK
  Applying auth.0005_alter_user_last_login_null...
 OK
  Applying auth.0006_require_contenttypes_0002...
 OK
  Applying auth.0007_alter_validators_add_error_messages...
 OK
  Applying auth.0008_alter_user_username_max_length...
 OK
  Applying auth.0009_alter_user_last_name_max_length...
 OK
  Applying auth.0010_alter_group_name_max_length...
 OK
  Applying auth.0011_update_proxy_permissions...
 OK
  Applying auth.0012_alter_user_first_name_max_length...
 OK
  Applying authtoken.0001_initial...
 OK
  Applying authtoken.0002_auto_20160226_1747...
 OK
  Applying authtoken.0003_tokenproxy...
 OK
  Applying authtoken.0004_alter_tokenproxy_options...
 OK
  Applying metrics.0001_initial...
 OK
  Applying sessions.0001_initial...
 OK
EE=== Starting migration
Operations to perform:
  Apply all migrations: admin, auth, authtoken, contenttypes, metrics, sessions
Running migrations:
  Applying contenttypes.0001_initial...
 OK
  Applying auth.0001_initial...
 OK
  Applying admin.0001_initial...
 OK
  Applying admin.0002_logentry_remove_auto_add...
 OK
  Applying admin.0003_logentry_add_action_flag_choices...
 OK
  Applying contenttypes.0002_remove_content_type_name...
 OK
  Applying auth.0002_alter_permission_name_max_length...
 OK
  Applying auth.0003_alter_user_email_max_length...
 OK
  Applying auth.0004_alter_user_username_opts...
 OK
  Applying auth.0005_alter_user_last_login_null...
 OK
  Applying auth.0006_require_contenttypes_0002...
 OK
  Applying auth.0007_alter_validators_add_error_messages...
 OK
  Applying auth.0008_alter_user_username_max_length...
 OK
  Applying auth.0009_alter_user_last_name_max_length...
 OK
  Applying auth.0010_alter_group_name_max_length...
 OK
  Applying auth.0011_update_proxy_permissions...
 OK
  Applying auth.0012_alter_user_first_name_max_length...
 OK
  Applying authtoken.0001_initial...
 OK
  Applying authtoken.0002_auto_20160226_1747...
 OK
  Applying authtoken.0003_tokenproxy...
 OK
  Applying authtoken.0004_alter_tokenproxy_options...
 OK
  Applying metrics.0001_initial...
 OK
  Applying sessions.0001_initial...
 OK
EE=== Starting migration
Operations to perform:
  Apply all migrations: admin, auth, authtoken, contenttypes, metrics, sessions
Running migrations:
  Applying contenttypes.0001_initial...
 OK
  Applying auth.0001_initial...
 OK
  Applying admin.0001_initial...
 OK
  Applying admin.0002_logentry_remove_auto_add...
 OK
  Applying admin.0003_logentry_add_action_flag_choices...
 OK
  Applying contenttypes.0002_remove_content_type_name...
 OK
  Applying auth.0002_alter_permission_name_max_length...
 OK
  Applying auth.0003_alter_user_email_max_length...
 OK
  Applying auth.0004_alter_user_username_opts...
 OK
  Applying auth.0005_alter_user_last_login_null...
 OK
  Applying auth.0006_require_contenttypes_0002...
 OK
  Applying auth.0007_alter_validators_add_error_messages...
 OK
  Applying auth.0008_alter_user_username_max_length...
 OK
  Applying auth.0009_alter_user_last_name_max_length...
 OK
  Applying auth.0010_alter_group_name_max_length...
 OK
  Applying auth.0011_update_proxy_permissions...
 OK
  Applying auth.0012_alter_user_first_name_max_length...
 OK
  Applying authtoken.0001_initial...
 OK
  Applying authtoken.0002_auto_20160226_1747...
 OK
  Applying authtoken.0003_tokenproxy...
 OK
  Applying authtoken.0004_alter_tokenproxy_options...
 OK
  Applying metrics.0001_initial...
 OK
  Applying sessions.0001_initial...
 OK
EE
======================================================================
ERROR: test_analyze_metric (metrics.tests.test_apis.APITests)
----------------------------------------------------------------------
Traceback (most recent call last):
  File "/home/nadeemramli/workspace/github.com/nadeemramli/mapping-of-metrics/metric-map-app/backend/metricMapAPI/metrics/tests/test_apis.py", line 17, in setUp
    self.tag = Tag.objects.create(name='Test Tag', project=self.tenant, tenant=self.tenant)
  File "/home/nadeemramli/.pyenv/versions/3.10.7/lib/python3.10/site-packages/django/db/models/manager.py", line 87, in manager_method
    return getattr(self.get_queryset(), name)(*args, **kwargs)
  File "/home/nadeemramli/.pyenv/versions/3.10.7/lib/python3.10/site-packages/django/db/models/query.py", line 677, in create
    obj = self.model(**kwargs)
  File "/home/nadeemramli/.pyenv/versions/3.10.7/lib/python3.10/site-packages/django/db/models/base.py", line 543, in __init__
    _setattr(self, field.name, rel_obj)
  File "/home/nadeemramli/.pyenv/versions/3.10.7/lib/python3.10/site-packages/django/db/models/fields/related_descriptors.py", line 284, in __set__
    raise ValueError(
ValueError: Cannot assign "<Client: Test Project>": "Tag.project" must be a "Project" instance.

======================================================================
ERROR: test_analyze_metric (metrics.tests.test_apis.APITests)
----------------------------------------------------------------------
Traceback (most recent call last):
  File "/home/nadeemramli/.pyenv/versions/3.10.7/lib/python3.10/site-packages/django/db/backends/utils.py", line 103, in _execute
    return self.cursor.execute(sql)
psycopg2.errors.ForeignKeyViolation: insert or update on table "metrics_category" violates foreign key constraint "metrics_category_tenant_id_67d98cc6_fk_metrics_client_id"
DETAIL:  Key (tenant_id)=(2) is not present in table "metrics_client".


The above exception was the direct cause of the following exception:

Traceback (most recent call last):
  File "/home/nadeemramli/.pyenv/versions/3.10.7/lib/python3.10/site-packages/django/test/testcases.py", line 296, in _setup_and_call
    self._post_teardown()
  File "/home/nadeemramli/.pyenv/versions/3.10.7/lib/python3.10/site-packages/django/test/testcases.py", line 1102, in _post_teardown
    self._fixture_teardown()
  File "/home/nadeemramli/.pyenv/versions/3.10.7/lib/python3.10/site-packages/django/test/testcases.py", line 1333, in _fixture_teardown
    connections[db_name].check_constraints()
  File "/home/nadeemramli/.pyenv/versions/3.10.7/lib/python3.10/site-packages/django/db/backends/postgresql/base.py", line 385, in check_constraints
    cursor.execute("SET CONSTRAINTS ALL IMMEDIATE")
  File "/home/nadeemramli/.pyenv/versions/3.10.7/lib/python3.10/site-packages/django/db/backends/utils.py", line 79, in execute
    return self._execute_with_wrappers(
  File "/home/nadeemramli/.pyenv/versions/3.10.7/lib/python3.10/site-packages/django/db/backends/utils.py", line 92, in _execute_with_wrappers
    return executor(sql, params, many, context)
  File "/home/nadeemramli/.pyenv/versions/3.10.7/lib/python3.10/site-packages/django/db/backends/utils.py", line 100, in _execute
    with self.db.wrap_database_errors:
  File "/home/nadeemramli/.pyenv/versions/3.10.7/lib/python3.10/site-packages/django/db/utils.py", line 91, in __exit__
    raise dj_exc_value.with_traceback(traceback) from exc_value
  File "/home/nadeemramli/.pyenv/versions/3.10.7/lib/python3.10/site-packages/django/db/backends/utils.py", line 103, in _execute
    return self.cursor.execute(sql)
django.db.utils.IntegrityError: insert or update on table "metrics_category" violates foreign key constraint "metrics_category_tenant_id_67d98cc6_fk_metrics_client_id"
DETAIL:  Key (tenant_id)=(2) is not present in table "metrics_client".


======================================================================
ERROR: test_authentication_required (metrics.tests.test_apis.APITests)
----------------------------------------------------------------------
Traceback (most recent call last):
  File "/home/nadeemramli/workspace/github.com/nadeemramli/mapping-of-metrics/metric-map-app/backend/metricMapAPI/metrics/tests/test_apis.py", line 17, in setUp
    self.tag = Tag.objects.create(name='Test Tag', project=self.tenant, tenant=self.tenant)
  File "/home/nadeemramli/.pyenv/versions/3.10.7/lib/python3.10/site-packages/django/db/models/manager.py", line 87, in manager_method
    return getattr(self.get_queryset(), name)(*args, **kwargs)
  File "/home/nadeemramli/.pyenv/versions/3.10.7/lib/python3.10/site-packages/django/db/models/query.py", line 677, in create
    obj = self.model(**kwargs)
  File "/home/nadeemramli/.pyenv/versions/3.10.7/lib/python3.10/site-packages/django/db/models/base.py", line 543, in __init__
    _setattr(self, field.name, rel_obj)
  File "/home/nadeemramli/.pyenv/versions/3.10.7/lib/python3.10/site-packages/django/db/models/fields/related_descriptors.py", line 284, in __set__
    raise ValueError(
ValueError: Cannot assign "<Client: Test Project>": "Tag.project" must be a "Project" instance.

======================================================================
ERROR: test_authentication_required (metrics.tests.test_apis.APITests)
----------------------------------------------------------------------
Traceback (most recent call last):
  File "/home/nadeemramli/.pyenv/versions/3.10.7/lib/python3.10/site-packages/django/db/backends/utils.py", line 103, in _execute
    return self.cursor.execute(sql)
psycopg2.errors.ForeignKeyViolation: insert or update on table "metrics_category" violates foreign key constraint "metrics_category_tenant_id_67d98cc6_fk_metrics_client_id"
DETAIL:  Key (tenant_id)=(3) is not present in table "metrics_client".


The above exception was the direct cause of the following exception:

Traceback (most recent call last):
  File "/home/nadeemramli/.pyenv/versions/3.10.7/lib/python3.10/site-packages/django/test/testcases.py", line 296, in _setup_and_call
    self._post_teardown()
  File "/home/nadeemramli/.pyenv/versions/3.10.7/lib/python3.10/site-packages/django/test/testcases.py", line 1102, in _post_teardown
    self._fixture_teardown()
  File "/home/nadeemramli/.pyenv/versions/3.10.7/lib/python3.10/site-packages/django/test/testcases.py", line 1333, in _fixture_teardown
    connections[db_name].check_constraints()
  File "/home/nadeemramli/.pyenv/versions/3.10.7/lib/python3.10/site-packages/django/db/backends/postgresql/base.py", line 385, in check_constraints
    cursor.execute("SET CONSTRAINTS ALL IMMEDIATE")
  File "/home/nadeemramli/.pyenv/versions/3.10.7/lib/python3.10/site-packages/django/db/backends/utils.py", line 79, in execute
    return self._execute_with_wrappers(
  File "/home/nadeemramli/.pyenv/versions/3.10.7/lib/python3.10/site-packages/django/db/backends/utils.py", line 92, in _execute_with_wrappers
    return executor(sql, params, many, context)
  File "/home/nadeemramli/.pyenv/versions/3.10.7/lib/python3.10/site-packages/django/db/backends/utils.py", line 100, in _execute
    with self.db.wrap_database_errors:
  File "/home/nadeemramli/.pyenv/versions/3.10.7/lib/python3.10/site-packages/django/db/utils.py", line 91, in __exit__
    raise dj_exc_value.with_traceback(traceback) from exc_value
  File "/home/nadeemramli/.pyenv/versions/3.10.7/lib/python3.10/site-packages/django/db/backends/utils.py", line 103, in _execute
    return self.cursor.execute(sql)
django.db.utils.IntegrityError: insert or update on table "metrics_category" violates foreign key constraint "metrics_category_tenant_id_67d98cc6_fk_metrics_client_id"
DETAIL:  Key (tenant_id)=(3) is not present in table "metrics_client".


======================================================================
ERROR: test_create_action_remark (metrics.tests.test_apis.APITests)
----------------------------------------------------------------------
Traceback (most recent call last):
  File "/home/nadeemramli/workspace/github.com/nadeemramli/mapping-of-metrics/metric-map-app/backend/metricMapAPI/metrics/tests/test_apis.py", line 17, in setUp
    self.tag = Tag.objects.create(name='Test Tag', project=self.tenant, tenant=self.tenant)
  File "/home/nadeemramli/.pyenv/versions/3.10.7/lib/python3.10/site-packages/django/db/models/manager.py", line 87, in manager_method
    return getattr(self.get_queryset(), name)(*args, **kwargs)
  File "/home/nadeemramli/.pyenv/versions/3.10.7/lib/python3.10/site-packages/django/db/models/query.py", line 677, in create
    obj = self.model(**kwargs)
  File "/home/nadeemramli/.pyenv/versions/3.10.7/lib/python3.10/site-packages/django/db/models/base.py", line 543, in __init__
    _setattr(self, field.name, rel_obj)
  File "/home/nadeemramli/.pyenv/versions/3.10.7/lib/python3.10/site-packages/django/db/models/fields/related_descriptors.py", line 284, in __set__
    raise ValueError(
ValueError: Cannot assign "<Client: Test Project>": "Tag.project" must be a "Project" instance.

======================================================================
ERROR: test_create_action_remark (metrics.tests.test_apis.APITests)
----------------------------------------------------------------------
Traceback (most recent call last):
  File "/home/nadeemramli/.pyenv/versions/3.10.7/lib/python3.10/site-packages/django/db/backends/utils.py", line 103, in _execute
    return self.cursor.execute(sql)
psycopg2.errors.ForeignKeyViolation: insert or update on table "metrics_category" violates foreign key constraint "metrics_category_tenant_id_67d98cc6_fk_metrics_client_id"
DETAIL:  Key (tenant_id)=(4) is not present in table "metrics_client".


The above exception was the direct cause of the following exception:

Traceback (most recent call last):
  File "/home/nadeemramli/.pyenv/versions/3.10.7/lib/python3.10/site-packages/django/test/testcases.py", line 296, in _setup_and_call
    self._post_teardown()
  File "/home/nadeemramli/.pyenv/versions/3.10.7/lib/python3.10/site-packages/django/test/testcases.py", line 1102, in _post_teardown
    self._fixture_teardown()
  File "/home/nadeemramli/.pyenv/versions/3.10.7/lib/python3.10/site-packages/django/test/testcases.py", line 1333, in _fixture_teardown
    connections[db_name].check_constraints()
  File "/home/nadeemramli/.pyenv/versions/3.10.7/lib/python3.10/site-packages/django/db/backends/postgresql/base.py", line 385, in check_constraints
    cursor.execute("SET CONSTRAINTS ALL IMMEDIATE")
  File "/home/nadeemramli/.pyenv/versions/3.10.7/lib/python3.10/site-packages/django/db/backends/utils.py", line 79, in execute
    return self._execute_with_wrappers(
  File "/home/nadeemramli/.pyenv/versions/3.10.7/lib/python3.10/site-packages/django/db/backends/utils.py", line 92, in _execute_with_wrappers
    return executor(sql, params, many, context)
  File "/home/nadeemramli/.pyenv/versions/3.10.7/lib/python3.10/site-packages/django/db/backends/utils.py", line 100, in _execute
    with self.db.wrap_database_errors:
  File "/home/nadeemramli/.pyenv/versions/3.10.7/lib/python3.10/site-packages/django/db/utils.py", line 91, in __exit__
    raise dj_exc_value.with_traceback(traceback) from exc_value
  File "/home/nadeemramli/.pyenv/versions/3.10.7/lib/python3.10/site-packages/django/db/backends/utils.py", line 103, in _execute
    return self.cursor.execute(sql)
django.db.utils.IntegrityError: insert or update on table "metrics_category" violates foreign key constraint "metrics_category_tenant_id_67d98cc6_fk_metrics_client_id"
DETAIL:  Key (tenant_id)=(4) is not present in table "metrics_client".


======================================================================
ERROR: test_create_dashboard (metrics.tests.test_apis.APITests)
----------------------------------------------------------------------
Traceback (most recent call last):
  File "/home/nadeemramli/workspace/github.com/nadeemramli/mapping-of-metrics/metric-map-app/backend/metricMapAPI/metrics/tests/test_apis.py", line 17, in setUp
    self.tag = Tag.objects.create(name='Test Tag', project=self.tenant, tenant=self.tenant)
  File "/home/nadeemramli/.pyenv/versions/3.10.7/lib/python3.10/site-packages/django/db/models/manager.py", line 87, in manager_method
    return getattr(self.get_queryset(), name)(*args, **kwargs)
  File "/home/nadeemramli/.pyenv/versions/3.10.7/lib/python3.10/site-packages/django/db/models/query.py", line 677, in create
    obj = self.model(**kwargs)
  File "/home/nadeemramli/.pyenv/versions/3.10.7/lib/python3.10/site-packages/django/db/models/base.py", line 543, in __init__
    _setattr(self, field.name, rel_obj)
  File "/home/nadeemramli/.pyenv/versions/3.10.7/lib/python3.10/site-packages/django/db/models/fields/related_descriptors.py", line 284, in __set__
    raise ValueError(
ValueError: Cannot assign "<Client: Test Project>": "Tag.project" must be a "Project" instance.

======================================================================
ERROR: test_create_dashboard (metrics.tests.test_apis.APITests)
----------------------------------------------------------------------
Traceback (most recent call last):
  File "/home/nadeemramli/.pyenv/versions/3.10.7/lib/python3.10/site-packages/django/db/backends/utils.py", line 103, in _execute
    return self.cursor.execute(sql)
psycopg2.errors.ForeignKeyViolation: insert or update on table "metrics_category" violates foreign key constraint "metrics_category_tenant_id_67d98cc6_fk_metrics_client_id"
DETAIL:  Key (tenant_id)=(5) is not present in table "metrics_client".


The above exception was the direct cause of the following exception:

Traceback (most recent call last):
  File "/home/nadeemramli/.pyenv/versions/3.10.7/lib/python3.10/site-packages/django/test/testcases.py", line 296, in _setup_and_call
    self._post_teardown()
  File "/home/nadeemramli/.pyenv/versions/3.10.7/lib/python3.10/site-packages/django/test/testcases.py", line 1102, in _post_teardown
    self._fixture_teardown()
  File "/home/nadeemramli/.pyenv/versions/3.10.7/lib/python3.10/site-packages/django/test/testcases.py", line 1333, in _fixture_teardown
    connections[db_name].check_constraints()
  File "/home/nadeemramli/.pyenv/versions/3.10.7/lib/python3.10/site-packages/django/db/backends/postgresql/base.py", line 385, in check_constraints
    cursor.execute("SET CONSTRAINTS ALL IMMEDIATE")
  File "/home/nadeemramli/.pyenv/versions/3.10.7/lib/python3.10/site-packages/django/db/backends/utils.py", line 79, in execute
    return self._execute_with_wrappers(
  File "/home/nadeemramli/.pyenv/versions/3.10.7/lib/python3.10/site-packages/django/db/backends/utils.py", line 92, in _execute_with_wrappers
    return executor(sql, params, many, context)
  File "/home/nadeemramli/.pyenv/versions/3.10.7/lib/python3.10/site-packages/django/db/backends/utils.py", line 100, in _execute
    with self.db.wrap_database_errors:
  File "/home/nadeemramli/.pyenv/versions/3.10.7/lib/python3.10/site-packages/django/db/utils.py", line 91, in __exit__
    raise dj_exc_value.with_traceback(traceback) from exc_value
  File "/home/nadeemramli/.pyenv/versions/3.10.7/lib/python3.10/site-packages/django/db/backends/utils.py", line 103, in _execute
    return self.cursor.execute(sql)
django.db.utils.IntegrityError: insert or update on table "metrics_category" violates foreign key constraint "metrics_category_tenant_id_67d98cc6_fk_metrics_client_id"
DETAIL:  Key (tenant_id)=(5) is not present in table "metrics_client".


======================================================================
ERROR: test_create_experiment (metrics.tests.test_apis.APITests)
----------------------------------------------------------------------
Traceback (most recent call last):
  File "/home/nadeemramli/workspace/github.com/nadeemramli/mapping-of-metrics/metric-map-app/backend/metricMapAPI/metrics/tests/test_apis.py", line 17, in setUp
    self.tag = Tag.objects.create(name='Test Tag', project=self.tenant, tenant=self.tenant)
  File "/home/nadeemramli/.pyenv/versions/3.10.7/lib/python3.10/site-packages/django/db/models/manager.py", line 87, in manager_method
    return getattr(self.get_queryset(), name)(*args, **kwargs)
  File "/home/nadeemramli/.pyenv/versions/3.10.7/lib/python3.10/site-packages/django/db/models/query.py", line 677, in create
    obj = self.model(**kwargs)
  File "/home/nadeemramli/.pyenv/versions/3.10.7/lib/python3.10/site-packages/django/db/models/base.py", line 543, in __init__
    _setattr(self, field.name, rel_obj)
  File "/home/nadeemramli/.pyenv/versions/3.10.7/lib/python3.10/site-packages/django/db/models/fields/related_descriptors.py", line 284, in __set__
    raise ValueError(
ValueError: Cannot assign "<Client: Test Project>": "Tag.project" must be a "Project" instance.

======================================================================
ERROR: test_create_experiment (metrics.tests.test_apis.APITests)
----------------------------------------------------------------------
Traceback (most recent call last):
  File "/home/nadeemramli/.pyenv/versions/3.10.7/lib/python3.10/site-packages/django/db/backends/utils.py", line 103, in _execute
    return self.cursor.execute(sql)
psycopg2.errors.ForeignKeyViolation: insert or update on table "metrics_category" violates foreign key constraint "metrics_category_tenant_id_67d98cc6_fk_metrics_client_id"
DETAIL:  Key (tenant_id)=(6) is not present in table "metrics_client".


The above exception was the direct cause of the following exception:

Traceback (most recent call last):
  File "/home/nadeemramli/.pyenv/versions/3.10.7/lib/python3.10/site-packages/django/test/testcases.py", line 296, in _setup_and_call
    self._post_teardown()
  File "/home/nadeemramli/.pyenv/versions/3.10.7/lib/python3.10/site-packages/django/test/testcases.py", line 1102, in _post_teardown
    self._fixture_teardown()
  File "/home/nadeemramli/.pyenv/versions/3.10.7/lib/python3.10/site-packages/django/test/testcases.py", line 1333, in _fixture_teardown
    connections[db_name].check_constraints()
  File "/home/nadeemramli/.pyenv/versions/3.10.7/lib/python3.10/site-packages/django/db/backends/postgresql/base.py", line 385, in check_constraints
    cursor.execute("SET CONSTRAINTS ALL IMMEDIATE")
  File "/home/nadeemramli/.pyenv/versions/3.10.7/lib/python3.10/site-packages/django/db/backends/utils.py", line 79, in execute
    return self._execute_with_wrappers(
  File "/home/nadeemramli/.pyenv/versions/3.10.7/lib/python3.10/site-packages/django/db/backends/utils.py", line 92, in _execute_with_wrappers
    return executor(sql, params, many, context)
  File "/home/nadeemramli/.pyenv/versions/3.10.7/lib/python3.10/site-packages/django/db/backends/utils.py", line 100, in _execute
    with self.db.wrap_database_errors:
  File "/home/nadeemramli/.pyenv/versions/3.10.7/lib/python3.10/site-packages/django/db/utils.py", line 91, in __exit__
    raise dj_exc_value.with_traceback(traceback) from exc_value
  File "/home/nadeemramli/.pyenv/versions/3.10.7/lib/python3.10/site-packages/django/db/backends/utils.py", line 103, in _execute
    return self.cursor.execute(sql)
django.db.utils.IntegrityError: insert or update on table "metrics_category" violates foreign key constraint "metrics_category_tenant_id_67d98cc6_fk_metrics_client_id"
DETAIL:  Key (tenant_id)=(6) is not present in table "metrics_client".


======================================================================
ERROR: test_create_metric (metrics.tests.test_apis.APITests)
----------------------------------------------------------------------
Traceback (most recent call last):
  File "/home/nadeemramli/workspace/github.com/nadeemramli/mapping-of-metrics/metric-map-app/backend/metricMapAPI/metrics/tests/test_apis.py", line 17, in setUp
    self.tag = Tag.objects.create(name='Test Tag', project=self.tenant, tenant=self.tenant)
  File "/home/nadeemramli/.pyenv/versions/3.10.7/lib/python3.10/site-packages/django/db/models/manager.py", line 87, in manager_method
    return getattr(self.get_queryset(), name)(*args, **kwargs)
  File "/home/nadeemramli/.pyenv/versions/3.10.7/lib/python3.10/site-packages/django/db/models/query.py", line 677, in create
    obj = self.model(**kwargs)
  File "/home/nadeemramli/.pyenv/versions/3.10.7/lib/python3.10/site-packages/django/db/models/base.py", line 543, in __init__
    _setattr(self, field.name, rel_obj)
  File "/home/nadeemramli/.pyenv/versions/3.10.7/lib/python3.10/site-packages/django/db/models/fields/related_descriptors.py", line 284, in __set__
    raise ValueError(
ValueError: Cannot assign "<Client: Test Project>": "Tag.project" must be a "Project" instance.

======================================================================
ERROR: test_create_metric (metrics.tests.test_apis.APITests)
----------------------------------------------------------------------
Traceback (most recent call last):
  File "/home/nadeemramli/.pyenv/versions/3.10.7/lib/python3.10/site-packages/django/db/backends/utils.py", line 103, in _execute
    return self.cursor.execute(sql)
psycopg2.errors.ForeignKeyViolation: insert or update on table "metrics_category" violates foreign key constraint "metrics_category_tenant_id_67d98cc6_fk_metrics_client_id"
DETAIL:  Key (tenant_id)=(7) is not present in table "metrics_client".


The above exception was the direct cause of the following exception:

Traceback (most recent call last):
  File "/home/nadeemramli/.pyenv/versions/3.10.7/lib/python3.10/site-packages/django/test/testcases.py", line 296, in _setup_and_call
    self._post_teardown()
  File "/home/nadeemramli/.pyenv/versions/3.10.7/lib/python3.10/site-packages/django/test/testcases.py", line 1102, in _post_teardown
    self._fixture_teardown()
  File "/home/nadeemramli/.pyenv/versions/3.10.7/lib/python3.10/site-packages/django/test/testcases.py", line 1333, in _fixture_teardown
    connections[db_name].check_constraints()
  File "/home/nadeemramli/.pyenv/versions/3.10.7/lib/python3.10/site-packages/django/db/backends/postgresql/base.py", line 385, in check_constraints
    cursor.execute("SET CONSTRAINTS ALL IMMEDIATE")
  File "/home/nadeemramli/.pyenv/versions/3.10.7/lib/python3.10/site-packages/django/db/backends/utils.py", line 79, in execute
    return self._execute_with_wrappers(
  File "/home/nadeemramli/.pyenv/versions/3.10.7/lib/python3.10/site-packages/django/db/backends/utils.py", line 92, in _execute_with_wrappers
    return executor(sql, params, many, context)
  File "/home/nadeemramli/.pyenv/versions/3.10.7/lib/python3.10/site-packages/django/db/backends/utils.py", line 100, in _execute
    with self.db.wrap_database_errors:
  File "/home/nadeemramli/.pyenv/versions/3.10.7/lib/python3.10/site-packages/django/db/utils.py", line 91, in __exit__
    raise dj_exc_value.with_traceback(traceback) from exc_value
  File "/home/nadeemramli/.pyenv/versions/3.10.7/lib/python3.10/site-packages/django/db/backends/utils.py", line 103, in _execute
    return self.cursor.execute(sql)
django.db.utils.IntegrityError: insert or update on table "metrics_category" violates foreign key constraint "metrics_category_tenant_id_67d98cc6_fk_metrics_client_id"
DETAIL:  Key (tenant_id)=(7) is not present in table "metrics_client".


======================================================================
ERROR: test_delete_metric (metrics.tests.test_apis.APITests)
----------------------------------------------------------------------
Traceback (most recent call last):
  File "/home/nadeemramli/workspace/github.com/nadeemramli/mapping-of-metrics/metric-map-app/backend/metricMapAPI/metrics/tests/test_apis.py", line 17, in setUp
    self.tag = Tag.objects.create(name='Test Tag', project=self.tenant, tenant=self.tenant)
  File "/home/nadeemramli/.pyenv/versions/3.10.7/lib/python3.10/site-packages/django/db/models/manager.py", line 87, in manager_method
    return getattr(self.get_queryset(), name)(*args, **kwargs)
  File "/home/nadeemramli/.pyenv/versions/3.10.7/lib/python3.10/site-packages/django/db/models/query.py", line 677, in create
    obj = self.model(**kwargs)
  File "/home/nadeemramli/.pyenv/versions/3.10.7/lib/python3.10/site-packages/django/db/models/base.py", line 543, in __init__
    _setattr(self, field.name, rel_obj)
  File "/home/nadeemramli/.pyenv/versions/3.10.7/lib/python3.10/site-packages/django/db/models/fields/related_descriptors.py", line 284, in __set__
    raise ValueError(
ValueError: Cannot assign "<Client: Test Project>": "Tag.project" must be a "Project" instance.

======================================================================
ERROR: test_delete_metric (metrics.tests.test_apis.APITests)
----------------------------------------------------------------------
Traceback (most recent call last):
  File "/home/nadeemramli/.pyenv/versions/3.10.7/lib/python3.10/site-packages/django/db/backends/utils.py", line 103, in _execute
    return self.cursor.execute(sql)
psycopg2.errors.ForeignKeyViolation: insert or update on table "metrics_category" violates foreign key constraint "metrics_category_tenant_id_67d98cc6_fk_metrics_client_id"
DETAIL:  Key (tenant_id)=(8) is not present in table "metrics_client".


The above exception was the direct cause of the following exception:

Traceback (most recent call last):
  File "/home/nadeemramli/.pyenv/versions/3.10.7/lib/python3.10/site-packages/django/test/testcases.py", line 296, in _setup_and_call
    self._post_teardown()
  File "/home/nadeemramli/.pyenv/versions/3.10.7/lib/python3.10/site-packages/django/test/testcases.py", line 1102, in _post_teardown
    self._fixture_teardown()
  File "/home/nadeemramli/.pyenv/versions/3.10.7/lib/python3.10/site-packages/django/test/testcases.py", line 1333, in _fixture_teardown
    connections[db_name].check_constraints()
  File "/home/nadeemramli/.pyenv/versions/3.10.7/lib/python3.10/site-packages/django/db/backends/postgresql/base.py", line 385, in check_constraints
    cursor.execute("SET CONSTRAINTS ALL IMMEDIATE")
  File "/home/nadeemramli/.pyenv/versions/3.10.7/lib/python3.10/site-packages/django/db/backends/utils.py", line 79, in execute
    return self._execute_with_wrappers(
  File "/home/nadeemramli/.pyenv/versions/3.10.7/lib/python3.10/site-packages/django/db/backends/utils.py", line 92, in _execute_with_wrappers
    return executor(sql, params, many, context)
  File "/home/nadeemramli/.pyenv/versions/3.10.7/lib/python3.10/site-packages/django/db/backends/utils.py", line 100, in _execute
    with self.db.wrap_database_errors:
  File "/home/nadeemramli/.pyenv/versions/3.10.7/lib/python3.10/site-packages/django/db/utils.py", line 91, in __exit__
    raise dj_exc_value.with_traceback(traceback) from exc_value
  File "/home/nadeemramli/.pyenv/versions/3.10.7/lib/python3.10/site-packages/django/db/backends/utils.py", line 103, in _execute
    return self.cursor.execute(sql)
django.db.utils.IntegrityError: insert or update on table "metrics_category" violates foreign key constraint "metrics_category_tenant_id_67d98cc6_fk_metrics_client_id"
DETAIL:  Key (tenant_id)=(8) is not present in table "metrics_client".


======================================================================
ERROR: test_get_categories (metrics.tests.test_apis.APITests)
----------------------------------------------------------------------
Traceback (most recent call last):
  File "/home/nadeemramli/workspace/github.com/nadeemramli/mapping-of-metrics/metric-map-app/backend/metricMapAPI/metrics/tests/test_apis.py", line 17, in setUp
    self.tag = Tag.objects.create(name='Test Tag', project=self.tenant, tenant=self.tenant)
  File "/home/nadeemramli/.pyenv/versions/3.10.7/lib/python3.10/site-packages/django/db/models/manager.py", line 87, in manager_method
    return getattr(self.get_queryset(), name)(*args, **kwargs)
  File "/home/nadeemramli/.pyenv/versions/3.10.7/lib/python3.10/site-packages/django/db/models/query.py", line 677, in create
    obj = self.model(**kwargs)
  File "/home/nadeemramli/.pyenv/versions/3.10.7/lib/python3.10/site-packages/django/db/models/base.py", line 543, in __init__
    _setattr(self, field.name, rel_obj)
  File "/home/nadeemramli/.pyenv/versions/3.10.7/lib/python3.10/site-packages/django/db/models/fields/related_descriptors.py", line 284, in __set__
    raise ValueError(
ValueError: Cannot assign "<Client: Test Project>": "Tag.project" must be a "Project" instance.

======================================================================
ERROR: test_get_categories (metrics.tests.test_apis.APITests)
----------------------------------------------------------------------
Traceback (most recent call last):
  File "/home/nadeemramli/.pyenv/versions/3.10.7/lib/python3.10/site-packages/django/db/backends/utils.py", line 103, in _execute
    return self.cursor.execute(sql)
psycopg2.errors.ForeignKeyViolation: insert or update on table "metrics_category" violates foreign key constraint "metrics_category_tenant_id_67d98cc6_fk_metrics_client_id"
DETAIL:  Key (tenant_id)=(9) is not present in table "metrics_client".


The above exception was the direct cause of the following exception:

Traceback (most recent call last):
  File "/home/nadeemramli/.pyenv/versions/3.10.7/lib/python3.10/site-packages/django/test/testcases.py", line 296, in _setup_and_call
    self._post_teardown()
  File "/home/nadeemramli/.pyenv/versions/3.10.7/lib/python3.10/site-packages/django/test/testcases.py", line 1102, in _post_teardown
    self._fixture_teardown()
  File "/home/nadeemramli/.pyenv/versions/3.10.7/lib/python3.10/site-packages/django/test/testcases.py", line 1333, in _fixture_teardown
    connections[db_name].check_constraints()
  File "/home/nadeemramli/.pyenv/versions/3.10.7/lib/python3.10/site-packages/django/db/backends/postgresql/base.py", line 385, in check_constraints
    cursor.execute("SET CONSTRAINTS ALL IMMEDIATE")
  File "/home/nadeemramli/.pyenv/versions/3.10.7/lib/python3.10/site-packages/django/db/backends/utils.py", line 79, in execute
    return self._execute_with_wrappers(
  File "/home/nadeemramli/.pyenv/versions/3.10.7/lib/python3.10/site-packages/django/db/backends/utils.py", line 92, in _execute_with_wrappers
    return executor(sql, params, many, context)
  File "/home/nadeemramli/.pyenv/versions/3.10.7/lib/python3.10/site-packages/django/db/backends/utils.py", line 100, in _execute
    with self.db.wrap_database_errors:
  File "/home/nadeemramli/.pyenv/versions/3.10.7/lib/python3.10/site-packages/django/db/utils.py", line 91, in __exit__
    raise dj_exc_value.with_traceback(traceback) from exc_value
  File "/home/nadeemramli/.pyenv/versions/3.10.7/lib/python3.10/site-packages/django/db/backends/utils.py", line 103, in _execute
    return self.cursor.execute(sql)
django.db.utils.IntegrityError: insert or update on table "metrics_category" violates foreign key constraint "metrics_category_tenant_id_67d98cc6_fk_metrics_client_id"
DETAIL:  Key (tenant_id)=(9) is not present in table "metrics_client".


======================================================================
ERROR: test_get_client_detail (metrics.tests.test_apis.APITests)
----------------------------------------------------------------------
Traceback (most recent call last):
  File "/home/nadeemramli/workspace/github.com/nadeemramli/mapping-of-metrics/metric-map-app/backend/metricMapAPI/metrics/tests/test_apis.py", line 17, in setUp
    self.tag = Tag.objects.create(name='Test Tag', project=self.tenant, tenant=self.tenant)
  File "/home/nadeemramli/.pyenv/versions/3.10.7/lib/python3.10/site-packages/django/db/models/manager.py", line 87, in manager_method
    return getattr(self.get_queryset(), name)(*args, **kwargs)
  File "/home/nadeemramli/.pyenv/versions/3.10.7/lib/python3.10/site-packages/django/db/models/query.py", line 677, in create
    obj = self.model(**kwargs)
  File "/home/nadeemramli/.pyenv/versions/3.10.7/lib/python3.10/site-packages/django/db/models/base.py", line 543, in __init__
    _setattr(self, field.name, rel_obj)
  File "/home/nadeemramli/.pyenv/versions/3.10.7/lib/python3.10/site-packages/django/db/models/fields/related_descriptors.py", line 284, in __set__
    raise ValueError(
ValueError: Cannot assign "<Client: Test Project>": "Tag.project" must be a "Project" instance.

======================================================================
ERROR: test_get_client_detail (metrics.tests.test_apis.APITests)
----------------------------------------------------------------------
Traceback (most recent call last):
  File "/home/nadeemramli/.pyenv/versions/3.10.7/lib/python3.10/site-packages/django/db/backends/utils.py", line 103, in _execute
    return self.cursor.execute(sql)
psycopg2.errors.ForeignKeyViolation: insert or update on table "metrics_category" violates foreign key constraint "metrics_category_tenant_id_67d98cc6_fk_metrics_client_id"
DETAIL:  Key (tenant_id)=(10) is not present in table "metrics_client".


The above exception was the direct cause of the following exception:

Traceback (most recent call last):
  File "/home/nadeemramli/.pyenv/versions/3.10.7/lib/python3.10/site-packages/django/test/testcases.py", line 296, in _setup_and_call
    self._post_teardown()
  File "/home/nadeemramli/.pyenv/versions/3.10.7/lib/python3.10/site-packages/django/test/testcases.py", line 1102, in _post_teardown
    self._fixture_teardown()
  File "/home/nadeemramli/.pyenv/versions/3.10.7/lib/python3.10/site-packages/django/test/testcases.py", line 1333, in _fixture_teardown
    connections[db_name].check_constraints()
  File "/home/nadeemramli/.pyenv/versions/3.10.7/lib/python3.10/site-packages/django/db/backends/postgresql/base.py", line 385, in check_constraints
    cursor.execute("SET CONSTRAINTS ALL IMMEDIATE")
  File "/home/nadeemramli/.pyenv/versions/3.10.7/lib/python3.10/site-packages/django/db/backends/utils.py", line 79, in execute
    return self._execute_with_wrappers(
  File "/home/nadeemramli/.pyenv/versions/3.10.7/lib/python3.10/site-packages/django/db/backends/utils.py", line 92, in _execute_with_wrappers
    return executor(sql, params, many, context)
  File "/home/nadeemramli/.pyenv/versions/3.10.7/lib/python3.10/site-packages/django/db/backends/utils.py", line 100, in _execute
    with self.db.wrap_database_errors:
  File "/home/nadeemramli/.pyenv/versions/3.10.7/lib/python3.10/site-packages/django/db/utils.py", line 91, in __exit__
    raise dj_exc_value.with_traceback(traceback) from exc_value
  File "/home/nadeemramli/.pyenv/versions/3.10.7/lib/python3.10/site-packages/django/db/backends/utils.py", line 103, in _execute
    return self.cursor.execute(sql)
django.db.utils.IntegrityError: insert or update on table "metrics_category" violates foreign key constraint "metrics_category_tenant_id_67d98cc6_fk_metrics_client_id"
DETAIL:  Key (tenant_id)=(10) is not present in table "metrics_client".


======================================================================
ERROR: test_get_clients_list (metrics.tests.test_apis.APITests)
----------------------------------------------------------------------
Traceback (most recent call last):
  File "/home/nadeemramli/workspace/github.com/nadeemramli/mapping-of-metrics/metric-map-app/backend/metricMapAPI/metrics/tests/test_apis.py", line 17, in setUp
    self.tag = Tag.objects.create(name='Test Tag', project=self.tenant, tenant=self.tenant)
  File "/home/nadeemramli/.pyenv/versions/3.10.7/lib/python3.10/site-packages/django/db/models/manager.py", line 87, in manager_method
    return getattr(self.get_queryset(), name)(*args, **kwargs)
  File "/home/nadeemramli/.pyenv/versions/3.10.7/lib/python3.10/site-packages/django/db/models/query.py", line 677, in create
    obj = self.model(**kwargs)
  File "/home/nadeemramli/.pyenv/versions/3.10.7/lib/python3.10/site-packages/django/db/models/base.py", line 543, in __init__
    _setattr(self, field.name, rel_obj)
  File "/home/nadeemramli/.pyenv/versions/3.10.7/lib/python3.10/site-packages/django/db/models/fields/related_descriptors.py", line 284, in __set__
    raise ValueError(
ValueError: Cannot assign "<Client: Test Project>": "Tag.project" must be a "Project" instance.

======================================================================
ERROR: test_get_clients_list (metrics.tests.test_apis.APITests)
----------------------------------------------------------------------
Traceback (most recent call last):
  File "/home/nadeemramli/.pyenv/versions/3.10.7/lib/python3.10/site-packages/django/db/backends/utils.py", line 103, in _execute
    return self.cursor.execute(sql)
psycopg2.errors.ForeignKeyViolation: insert or update on table "metrics_category" violates foreign key constraint "metrics_category_tenant_id_67d98cc6_fk_metrics_client_id"
DETAIL:  Key (tenant_id)=(11) is not present in table "metrics_client".


The above exception was the direct cause of the following exception:

Traceback (most recent call last):
  File "/home/nadeemramli/.pyenv/versions/3.10.7/lib/python3.10/site-packages/django/test/testcases.py", line 296, in _setup_and_call
    self._post_teardown()
  File "/home/nadeemramli/.pyenv/versions/3.10.7/lib/python3.10/site-packages/django/test/testcases.py", line 1102, in _post_teardown
    self._fixture_teardown()
  File "/home/nadeemramli/.pyenv/versions/3.10.7/lib/python3.10/site-packages/django/test/testcases.py", line 1333, in _fixture_teardown
    connections[db_name].check_constraints()
  File "/home/nadeemramli/.pyenv/versions/3.10.7/lib/python3.10/site-packages/django/db/backends/postgresql/base.py", line 385, in check_constraints
    cursor.execute("SET CONSTRAINTS ALL IMMEDIATE")
  File "/home/nadeemramli/.pyenv/versions/3.10.7/lib/python3.10/site-packages/django/db/backends/utils.py", line 79, in execute
    return self._execute_with_wrappers(
  File "/home/nadeemramli/.pyenv/versions/3.10.7/lib/python3.10/site-packages/django/db/backends/utils.py", line 92, in _execute_with_wrappers
    return executor(sql, params, many, context)
  File "/home/nadeemramli/.pyenv/versions/3.10.7/lib/python3.10/site-packages/django/db/backends/utils.py", line 100, in _execute
    with self.db.wrap_database_errors:
  File "/home/nadeemramli/.pyenv/versions/3.10.7/lib/python3.10/site-packages/django/db/utils.py", line 91, in __exit__
    raise dj_exc_value.with_traceback(traceback) from exc_value
  File "/home/nadeemramli/.pyenv/versions/3.10.7/lib/python3.10/site-packages/django/db/backends/utils.py", line 103, in _execute
    return self.cursor.execute(sql)
django.db.utils.IntegrityError: insert or update on table "metrics_category" violates foreign key constraint "metrics_category_tenant_id_67d98cc6_fk_metrics_client_id"
DETAIL:  Key (tenant_id)=(11) is not present in table "metrics_client".


======================================================================
ERROR: test_get_connections (metrics.tests.test_apis.APITests)
----------------------------------------------------------------------
Traceback (most recent call last):
  File "/home/nadeemramli/workspace/github.com/nadeemramli/mapping-of-metrics/metric-map-app/backend/metricMapAPI/metrics/tests/test_apis.py", line 17, in setUp
    self.tag = Tag.objects.create(name='Test Tag', project=self.tenant, tenant=self.tenant)
  File "/home/nadeemramli/.pyenv/versions/3.10.7/lib/python3.10/site-packages/django/db/models/manager.py", line 87, in manager_method
    return getattr(self.get_queryset(), name)(*args, **kwargs)
  File "/home/nadeemramli/.pyenv/versions/3.10.7/lib/python3.10/site-packages/django/db/models/query.py", line 677, in create
    obj = self.model(**kwargs)
  File "/home/nadeemramli/.pyenv/versions/3.10.7/lib/python3.10/site-packages/django/db/models/base.py", line 543, in __init__
    _setattr(self, field.name, rel_obj)
  File "/home/nadeemramli/.pyenv/versions/3.10.7/lib/python3.10/site-packages/django/db/models/fields/related_descriptors.py", line 284, in __set__
    raise ValueError(
ValueError: Cannot assign "<Client: Test Project>": "Tag.project" must be a "Project" instance.

======================================================================
ERROR: test_get_connections (metrics.tests.test_apis.APITests)
----------------------------------------------------------------------
Traceback (most recent call last):
  File "/home/nadeemramli/.pyenv/versions/3.10.7/lib/python3.10/site-packages/django/db/backends/utils.py", line 103, in _execute
    return self.cursor.execute(sql)
psycopg2.errors.ForeignKeyViolation: insert or update on table "metrics_category" violates foreign key constraint "metrics_category_tenant_id_67d98cc6_fk_metrics_client_id"
DETAIL:  Key (tenant_id)=(12) is not present in table "metrics_client".


The above exception was the direct cause of the following exception:

Traceback (most recent call last):
  File "/home/nadeemramli/.pyenv/versions/3.10.7/lib/python3.10/site-packages/django/test/testcases.py", line 296, in _setup_and_call
    self._post_teardown()
  File "/home/nadeemramli/.pyenv/versions/3.10.7/lib/python3.10/site-packages/django/test/testcases.py", line 1102, in _post_teardown
    self._fixture_teardown()
  File "/home/nadeemramli/.pyenv/versions/3.10.7/lib/python3.10/site-packages/django/test/testcases.py", line 1333, in _fixture_teardown
    connections[db_name].check_constraints()
  File "/home/nadeemramli/.pyenv/versions/3.10.7/lib/python3.10/site-packages/django/db/backends/postgresql/base.py", line 385, in check_constraints
    cursor.execute("SET CONSTRAINTS ALL IMMEDIATE")
  File "/home/nadeemramli/.pyenv/versions/3.10.7/lib/python3.10/site-packages/django/db/backends/utils.py", line 79, in execute
    return self._execute_with_wrappers(
  File "/home/nadeemramli/.pyenv/versions/3.10.7/lib/python3.10/site-packages/django/db/backends/utils.py", line 92, in _execute_with_wrappers
    return executor(sql, params, many, context)
  File "/home/nadeemramli/.pyenv/versions/3.10.7/lib/python3.10/site-packages/django/db/backends/utils.py", line 100, in _execute
    with self.db.wrap_database_errors:
  File "/home/nadeemramli/.pyenv/versions/3.10.7/lib/python3.10/site-packages/django/db/utils.py", line 91, in __exit__
    raise dj_exc_value.with_traceback(traceback) from exc_value
  File "/home/nadeemramli/.pyenv/versions/3.10.7/lib/python3.10/site-packages/django/db/backends/utils.py", line 103, in _execute
    return self.cursor.execute(sql)
django.db.utils.IntegrityError: insert or update on table "metrics_category" violates foreign key constraint "metrics_category_tenant_id_67d98cc6_fk_metrics_client_id"
DETAIL:  Key (tenant_id)=(12) is not present in table "metrics_client".


======================================================================
ERROR: test_get_dashboards (metrics.tests.test_apis.APITests)
----------------------------------------------------------------------
Traceback (most recent call last):
  File "/home/nadeemramli/workspace/github.com/nadeemramli/mapping-of-metrics/metric-map-app/backend/metricMapAPI/metrics/tests/test_apis.py", line 17, in setUp
    self.tag = Tag.objects.create(name='Test Tag', project=self.tenant, tenant=self.tenant)
  File "/home/nadeemramli/.pyenv/versions/3.10.7/lib/python3.10/site-packages/django/db/models/manager.py", line 87, in manager_method
    return getattr(self.get_queryset(), name)(*args, **kwargs)
  File "/home/nadeemramli/.pyenv/versions/3.10.7/lib/python3.10/site-packages/django/db/models/query.py", line 677, in create
    obj = self.model(**kwargs)
  File "/home/nadeemramli/.pyenv/versions/3.10.7/lib/python3.10/site-packages/django/db/models/base.py", line 543, in __init__
    _setattr(self, field.name, rel_obj)
  File "/home/nadeemramli/.pyenv/versions/3.10.7/lib/python3.10/site-packages/django/db/models/fields/related_descriptors.py", line 284, in __set__
    raise ValueError(
ValueError: Cannot assign "<Client: Test Project>": "Tag.project" must be a "Project" instance.

======================================================================
ERROR: test_get_dashboards (metrics.tests.test_apis.APITests)
----------------------------------------------------------------------
Traceback (most recent call last):
  File "/home/nadeemramli/.pyenv/versions/3.10.7/lib/python3.10/site-packages/django/db/backends/utils.py", line 103, in _execute
    return self.cursor.execute(sql)
psycopg2.errors.ForeignKeyViolation: insert or update on table "metrics_category" violates foreign key constraint "metrics_category_tenant_id_67d98cc6_fk_metrics_client_id"
DETAIL:  Key (tenant_id)=(13) is not present in table "metrics_client".


The above exception was the direct cause of the following exception:

Traceback (most recent call last):
  File "/home/nadeemramli/.pyenv/versions/3.10.7/lib/python3.10/site-packages/django/test/testcases.py", line 296, in _setup_and_call
    self._post_teardown()
  File "/home/nadeemramli/.pyenv/versions/3.10.7/lib/python3.10/site-packages/django/test/testcases.py", line 1102, in _post_teardown
    self._fixture_teardown()
  File "/home/nadeemramli/.pyenv/versions/3.10.7/lib/python3.10/site-packages/django/test/testcases.py", line 1333, in _fixture_teardown
    connections[db_name].check_constraints()
  File "/home/nadeemramli/.pyenv/versions/3.10.7/lib/python3.10/site-packages/django/db/backends/postgresql/base.py", line 385, in check_constraints
    cursor.execute("SET CONSTRAINTS ALL IMMEDIATE")
  File "/home/nadeemramli/.pyenv/versions/3.10.7/lib/python3.10/site-packages/django/db/backends/utils.py", line 79, in execute
    return self._execute_with_wrappers(
  File "/home/nadeemramli/.pyenv/versions/3.10.7/lib/python3.10/site-packages/django/db/backends/utils.py", line 92, in _execute_with_wrappers
    return executor(sql, params, many, context)
  File "/home/nadeemramli/.pyenv/versions/3.10.7/lib/python3.10/site-packages/django/db/backends/utils.py", line 100, in _execute
    with self.db.wrap_database_errors:
  File "/home/nadeemramli/.pyenv/versions/3.10.7/lib/python3.10/site-packages/django/db/utils.py", line 91, in __exit__
    raise dj_exc_value.with_traceback(traceback) from exc_value
  File "/home/nadeemramli/.pyenv/versions/3.10.7/lib/python3.10/site-packages/django/db/backends/utils.py", line 103, in _execute
    return self.cursor.execute(sql)
django.db.utils.IntegrityError: insert or update on table "metrics_category" violates foreign key constraint "metrics_category_tenant_id_67d98cc6_fk_metrics_client_id"
DETAIL:  Key (tenant_id)=(13) is not present in table "metrics_client".


======================================================================
ERROR: test_get_experiments (metrics.tests.test_apis.APITests)
----------------------------------------------------------------------
Traceback (most recent call last):
  File "/home/nadeemramli/workspace/github.com/nadeemramli/mapping-of-metrics/metric-map-app/backend/metricMapAPI/metrics/tests/test_apis.py", line 17, in setUp
    self.tag = Tag.objects.create(name='Test Tag', project=self.tenant, tenant=self.tenant)
  File "/home/nadeemramli/.pyenv/versions/3.10.7/lib/python3.10/site-packages/django/db/models/manager.py", line 87, in manager_method
    return getattr(self.get_queryset(), name)(*args, **kwargs)
  File "/home/nadeemramli/.pyenv/versions/3.10.7/lib/python3.10/site-packages/django/db/models/query.py", line 677, in create
    obj = self.model(**kwargs)
  File "/home/nadeemramli/.pyenv/versions/3.10.7/lib/python3.10/site-packages/django/db/models/base.py", line 543, in __init__
    _setattr(self, field.name, rel_obj)
  File "/home/nadeemramli/.pyenv/versions/3.10.7/lib/python3.10/site-packages/django/db/models/fields/related_descriptors.py", line 284, in __set__
    raise ValueError(
ValueError: Cannot assign "<Client: Test Project>": "Tag.project" must be a "Project" instance.

======================================================================
ERROR: test_get_experiments (metrics.tests.test_apis.APITests)
----------------------------------------------------------------------
Traceback (most recent call last):
  File "/home/nadeemramli/.pyenv/versions/3.10.7/lib/python3.10/site-packages/django/db/backends/utils.py", line 103, in _execute
    return self.cursor.execute(sql)
psycopg2.errors.ForeignKeyViolation: insert or update on table "metrics_category" violates foreign key constraint "metrics_category_tenant_id_67d98cc6_fk_metrics_client_id"
DETAIL:  Key (tenant_id)=(14) is not present in table "metrics_client".


The above exception was the direct cause of the following exception:

Traceback (most recent call last):
  File "/home/nadeemramli/.pyenv/versions/3.10.7/lib/python3.10/site-packages/django/test/testcases.py", line 296, in _setup_and_call
    self._post_teardown()
  File "/home/nadeemramli/.pyenv/versions/3.10.7/lib/python3.10/site-packages/django/test/testcases.py", line 1102, in _post_teardown
    self._fixture_teardown()
  File "/home/nadeemramli/.pyenv/versions/3.10.7/lib/python3.10/site-packages/django/test/testcases.py", line 1333, in _fixture_teardown
    connections[db_name].check_constraints()
  File "/home/nadeemramli/.pyenv/versions/3.10.7/lib/python3.10/site-packages/django/db/backends/postgresql/base.py", line 385, in check_constraints
    cursor.execute("SET CONSTRAINTS ALL IMMEDIATE")
  File "/home/nadeemramli/.pyenv/versions/3.10.7/lib/python3.10/site-packages/django/db/backends/utils.py", line 79, in execute
    return self._execute_with_wrappers(
  File "/home/nadeemramli/.pyenv/versions/3.10.7/lib/python3.10/site-packages/django/db/backends/utils.py", line 92, in _execute_with_wrappers
    return executor(sql, params, many, context)
  File "/home/nadeemramli/.pyenv/versions/3.10.7/lib/python3.10/site-packages/django/db/backends/utils.py", line 100, in _execute
    with self.db.wrap_database_errors:
  File "/home/nadeemramli/.pyenv/versions/3.10.7/lib/python3.10/site-packages/django/db/utils.py", line 91, in __exit__
    raise dj_exc_value.with_traceback(traceback) from exc_value
  File "/home/nadeemramli/.pyenv/versions/3.10.7/lib/python3.10/site-packages/django/db/backends/utils.py", line 103, in _execute
    return self.cursor.execute(sql)
django.db.utils.IntegrityError: insert or update on table "metrics_category" violates foreign key constraint "metrics_category_tenant_id_67d98cc6_fk_metrics_client_id"
DETAIL:  Key (tenant_id)=(14) is not present in table "metrics_client".


======================================================================
ERROR: test_get_historical_data (metrics.tests.test_apis.APITests)
----------------------------------------------------------------------
Traceback (most recent call last):
  File "/home/nadeemramli/workspace/github.com/nadeemramli/mapping-of-metrics/metric-map-app/backend/metricMapAPI/metrics/tests/test_apis.py", line 17, in setUp
    self.tag = Tag.objects.create(name='Test Tag', project=self.tenant, tenant=self.tenant)
  File "/home/nadeemramli/.pyenv/versions/3.10.7/lib/python3.10/site-packages/django/db/models/manager.py", line 87, in manager_method
    return getattr(self.get_queryset(), name)(*args, **kwargs)
  File "/home/nadeemramli/.pyenv/versions/3.10.7/lib/python3.10/site-packages/django/db/models/query.py", line 677, in create
    obj = self.model(**kwargs)
  File "/home/nadeemramli/.pyenv/versions/3.10.7/lib/python3.10/site-packages/django/db/models/base.py", line 543, in __init__
    _setattr(self, field.name, rel_obj)
  File "/home/nadeemramli/.pyenv/versions/3.10.7/lib/python3.10/site-packages/django/db/models/fields/related_descriptors.py", line 284, in __set__
    raise ValueError(
ValueError: Cannot assign "<Client: Test Project>": "Tag.project" must be a "Project" instance.

======================================================================
ERROR: test_get_historical_data (metrics.tests.test_apis.APITests)
----------------------------------------------------------------------
Traceback (most recent call last):
  File "/home/nadeemramli/.pyenv/versions/3.10.7/lib/python3.10/site-packages/django/db/backends/utils.py", line 103, in _execute
    return self.cursor.execute(sql)
psycopg2.errors.ForeignKeyViolation: insert or update on table "metrics_category" violates foreign key constraint "metrics_category_tenant_id_67d98cc6_fk_metrics_client_id"
DETAIL:  Key (tenant_id)=(15) is not present in table "metrics_client".


The above exception was the direct cause of the following exception:

Traceback (most recent call last):
  File "/home/nadeemramli/.pyenv/versions/3.10.7/lib/python3.10/site-packages/django/test/testcases.py", line 296, in _setup_and_call
    self._post_teardown()
  File "/home/nadeemramli/.pyenv/versions/3.10.7/lib/python3.10/site-packages/django/test/testcases.py", line 1102, in _post_teardown
    self._fixture_teardown()
  File "/home/nadeemramli/.pyenv/versions/3.10.7/lib/python3.10/site-packages/django/test/testcases.py", line 1333, in _fixture_teardown
    connections[db_name].check_constraints()
  File "/home/nadeemramli/.pyenv/versions/3.10.7/lib/python3.10/site-packages/django/db/backends/postgresql/base.py", line 385, in check_constraints
    cursor.execute("SET CONSTRAINTS ALL IMMEDIATE")
  File "/home/nadeemramli/.pyenv/versions/3.10.7/lib/python3.10/site-packages/django/db/backends/utils.py", line 79, in execute
    return self._execute_with_wrappers(
  File "/home/nadeemramli/.pyenv/versions/3.10.7/lib/python3.10/site-packages/django/db/backends/utils.py", line 92, in _execute_with_wrappers
    return executor(sql, params, many, context)
  File "/home/nadeemramli/.pyenv/versions/3.10.7/lib/python3.10/site-packages/django/db/backends/utils.py", line 100, in _execute
    with self.db.wrap_database_errors:
  File "/home/nadeemramli/.pyenv/versions/3.10.7/lib/python3.10/site-packages/django/db/utils.py", line 91, in __exit__
    raise dj_exc_value.with_traceback(traceback) from exc_value
  File "/home/nadeemramli/.pyenv/versions/3.10.7/lib/python3.10/site-packages/django/db/backends/utils.py", line 103, in _execute
    return self.cursor.execute(sql)
django.db.utils.IntegrityError: insert or update on table "metrics_category" violates foreign key constraint "metrics_category_tenant_id_67d98cc6_fk_metrics_client_id"
DETAIL:  Key (tenant_id)=(15) is not present in table "metrics_client".


======================================================================
ERROR: test_get_metric_action_remarks (metrics.tests.test_apis.APITests)
----------------------------------------------------------------------
Traceback (most recent call last):
  File "/home/nadeemramli/workspace/github.com/nadeemramli/mapping-of-metrics/metric-map-app/backend/metricMapAPI/metrics/tests/test_apis.py", line 17, in setUp
    self.tag = Tag.objects.create(name='Test Tag', project=self.tenant, tenant=self.tenant)
  File "/home/nadeemramli/.pyenv/versions/3.10.7/lib/python3.10/site-packages/django/db/models/manager.py", line 87, in manager_method
    return getattr(self.get_queryset(), name)(*args, **kwargs)
  File "/home/nadeemramli/.pyenv/versions/3.10.7/lib/python3.10/site-packages/django/db/models/query.py", line 677, in create
    obj = self.model(**kwargs)
  File "/home/nadeemramli/.pyenv/versions/3.10.7/lib/python3.10/site-packages/django/db/models/base.py", line 543, in __init__
    _setattr(self, field.name, rel_obj)
  File "/home/nadeemramli/.pyenv/versions/3.10.7/lib/python3.10/site-packages/django/db/models/fields/related_descriptors.py", line 284, in __set__
    raise ValueError(
ValueError: Cannot assign "<Client: Test Project>": "Tag.project" must be a "Project" instance.

======================================================================
ERROR: test_get_metric_action_remarks (metrics.tests.test_apis.APITests)
----------------------------------------------------------------------
Traceback (most recent call last):
  File "/home/nadeemramli/.pyenv/versions/3.10.7/lib/python3.10/site-packages/django/db/backends/utils.py", line 103, in _execute
    return self.cursor.execute(sql)
psycopg2.errors.ForeignKeyViolation: insert or update on table "metrics_category" violates foreign key constraint "metrics_category_tenant_id_67d98cc6_fk_metrics_client_id"
DETAIL:  Key (tenant_id)=(16) is not present in table "metrics_client".


The above exception was the direct cause of the following exception:

Traceback (most recent call last):
  File "/home/nadeemramli/.pyenv/versions/3.10.7/lib/python3.10/site-packages/django/test/testcases.py", line 296, in _setup_and_call
    self._post_teardown()
  File "/home/nadeemramli/.pyenv/versions/3.10.7/lib/python3.10/site-packages/django/test/testcases.py", line 1102, in _post_teardown
    self._fixture_teardown()
  File "/home/nadeemramli/.pyenv/versions/3.10.7/lib/python3.10/site-packages/django/test/testcases.py", line 1333, in _fixture_teardown
    connections[db_name].check_constraints()
  File "/home/nadeemramli/.pyenv/versions/3.10.7/lib/python3.10/site-packages/django/db/backends/postgresql/base.py", line 385, in check_constraints
    cursor.execute("SET CONSTRAINTS ALL IMMEDIATE")
  File "/home/nadeemramli/.pyenv/versions/3.10.7/lib/python3.10/site-packages/django/db/backends/utils.py", line 79, in execute
    return self._execute_with_wrappers(
  File "/home/nadeemramli/.pyenv/versions/3.10.7/lib/python3.10/site-packages/django/db/backends/utils.py", line 92, in _execute_with_wrappers
    return executor(sql, params, many, context)
  File "/home/nadeemramli/.pyenv/versions/3.10.7/lib/python3.10/site-packages/django/db/backends/utils.py", line 100, in _execute
    with self.db.wrap_database_errors:
  File "/home/nadeemramli/.pyenv/versions/3.10.7/lib/python3.10/site-packages/django/db/utils.py", line 91, in __exit__
    raise dj_exc_value.with_traceback(traceback) from exc_value
  File "/home/nadeemramli/.pyenv/versions/3.10.7/lib/python3.10/site-packages/django/db/backends/utils.py", line 103, in _execute
    return self.cursor.execute(sql)
django.db.utils.IntegrityError: insert or update on table "metrics_category" violates foreign key constraint "metrics_category_tenant_id_67d98cc6_fk_metrics_client_id"
DETAIL:  Key (tenant_id)=(16) is not present in table "metrics_client".


======================================================================
ERROR: test_get_metric_connections (metrics.tests.test_apis.APITests)
----------------------------------------------------------------------
Traceback (most recent call last):
  File "/home/nadeemramli/workspace/github.com/nadeemramli/mapping-of-metrics/metric-map-app/backend/metricMapAPI/metrics/tests/test_apis.py", line 17, in setUp
    self.tag = Tag.objects.create(name='Test Tag', project=self.tenant, tenant=self.tenant)
  File "/home/nadeemramli/.pyenv/versions/3.10.7/lib/python3.10/site-packages/django/db/models/manager.py", line 87, in manager_method
    return getattr(self.get_queryset(), name)(*args, **kwargs)
  File "/home/nadeemramli/.pyenv/versions/3.10.7/lib/python3.10/site-packages/django/db/models/query.py", line 677, in create
    obj = self.model(**kwargs)
  File "/home/nadeemramli/.pyenv/versions/3.10.7/lib/python3.10/site-packages/django/db/models/base.py", line 543, in __init__
    _setattr(self, field.name, rel_obj)
  File "/home/nadeemramli/.pyenv/versions/3.10.7/lib/python3.10/site-packages/django/db/models/fields/related_descriptors.py", line 284, in __set__
    raise ValueError(
ValueError: Cannot assign "<Client: Test Project>": "Tag.project" must be a "Project" instance.

======================================================================
ERROR: test_get_metric_connections (metrics.tests.test_apis.APITests)
----------------------------------------------------------------------
Traceback (most recent call last):
  File "/home/nadeemramli/.pyenv/versions/3.10.7/lib/python3.10/site-packages/django/db/backends/utils.py", line 103, in _execute
    return self.cursor.execute(sql)
psycopg2.errors.ForeignKeyViolation: insert or update on table "metrics_category" violates foreign key constraint "metrics_category_tenant_id_67d98cc6_fk_metrics_client_id"
DETAIL:  Key (tenant_id)=(17) is not present in table "metrics_client".


The above exception was the direct cause of the following exception:

Traceback (most recent call last):
  File "/home/nadeemramli/.pyenv/versions/3.10.7/lib/python3.10/site-packages/django/test/testcases.py", line 296, in _setup_and_call
    self._post_teardown()
  File "/home/nadeemramli/.pyenv/versions/3.10.7/lib/python3.10/site-packages/django/test/testcases.py", line 1102, in _post_teardown
    self._fixture_teardown()
  File "/home/nadeemramli/.pyenv/versions/3.10.7/lib/python3.10/site-packages/django/test/testcases.py", line 1333, in _fixture_teardown
    connections[db_name].check_constraints()
  File "/home/nadeemramli/.pyenv/versions/3.10.7/lib/python3.10/site-packages/django/db/backends/postgresql/base.py", line 385, in check_constraints
    cursor.execute("SET CONSTRAINTS ALL IMMEDIATE")
  File "/home/nadeemramli/.pyenv/versions/3.10.7/lib/python3.10/site-packages/django/db/backends/utils.py", line 79, in execute
    return self._execute_with_wrappers(
  File "/home/nadeemramli/.pyenv/versions/3.10.7/lib/python3.10/site-packages/django/db/backends/utils.py", line 92, in _execute_with_wrappers
    return executor(sql, params, many, context)
  File "/home/nadeemramli/.pyenv/versions/3.10.7/lib/python3.10/site-packages/django/db/backends/utils.py", line 100, in _execute
    with self.db.wrap_database_errors:
  File "/home/nadeemramli/.pyenv/versions/3.10.7/lib/python3.10/site-packages/django/db/utils.py", line 91, in __exit__
    raise dj_exc_value.with_traceback(traceback) from exc_value
  File "/home/nadeemramli/.pyenv/versions/3.10.7/lib/python3.10/site-packages/django/db/backends/utils.py", line 103, in _execute
    return self.cursor.execute(sql)
django.db.utils.IntegrityError: insert or update on table "metrics_category" violates foreign key constraint "metrics_category_tenant_id_67d98cc6_fk_metrics_client_id"
DETAIL:  Key (tenant_id)=(17) is not present in table "metrics_client".


======================================================================
ERROR: test_get_metric_detail (metrics.tests.test_apis.APITests)
----------------------------------------------------------------------
Traceback (most recent call last):
  File "/home/nadeemramli/workspace/github.com/nadeemramli/mapping-of-metrics/metric-map-app/backend/metricMapAPI/metrics/tests/test_apis.py", line 17, in setUp
    self.tag = Tag.objects.create(name='Test Tag', project=self.tenant, tenant=self.tenant)
  File "/home/nadeemramli/.pyenv/versions/3.10.7/lib/python3.10/site-packages/django/db/models/manager.py", line 87, in manager_method
    return getattr(self.get_queryset(), name)(*args, **kwargs)
  File "/home/nadeemramli/.pyenv/versions/3.10.7/lib/python3.10/site-packages/django/db/models/query.py", line 677, in create
    obj = self.model(**kwargs)
  File "/home/nadeemramli/.pyenv/versions/3.10.7/lib/python3.10/site-packages/django/db/models/base.py", line 543, in __init__
    _setattr(self, field.name, rel_obj)
  File "/home/nadeemramli/.pyenv/versions/3.10.7/lib/python3.10/site-packages/django/db/models/fields/related_descriptors.py", line 284, in __set__
    raise ValueError(
ValueError: Cannot assign "<Client: Test Project>": "Tag.project" must be a "Project" instance.

======================================================================
ERROR: test_get_metric_detail (metrics.tests.test_apis.APITests)
----------------------------------------------------------------------
Traceback (most recent call last):
  File "/home/nadeemramli/.pyenv/versions/3.10.7/lib/python3.10/site-packages/django/db/backends/utils.py", line 103, in _execute
    return self.cursor.execute(sql)
psycopg2.errors.ForeignKeyViolation: insert or update on table "metrics_category" violates foreign key constraint "metrics_category_tenant_id_67d98cc6_fk_metrics_client_id"
DETAIL:  Key (tenant_id)=(18) is not present in table "metrics_client".


The above exception was the direct cause of the following exception:

Traceback (most recent call last):
  File "/home/nadeemramli/.pyenv/versions/3.10.7/lib/python3.10/site-packages/django/test/testcases.py", line 296, in _setup_and_call
    self._post_teardown()
  File "/home/nadeemramli/.pyenv/versions/3.10.7/lib/python3.10/site-packages/django/test/testcases.py", line 1102, in _post_teardown
    self._fixture_teardown()
  File "/home/nadeemramli/.pyenv/versions/3.10.7/lib/python3.10/site-packages/django/test/testcases.py", line 1333, in _fixture_teardown
    connections[db_name].check_constraints()
  File "/home/nadeemramli/.pyenv/versions/3.10.7/lib/python3.10/site-packages/django/db/backends/postgresql/base.py", line 385, in check_constraints
    cursor.execute("SET CONSTRAINTS ALL IMMEDIATE")
  File "/home/nadeemramli/.pyenv/versions/3.10.7/lib/python3.10/site-packages/django/db/backends/utils.py", line 79, in execute
    return self._execute_with_wrappers(
  File "/home/nadeemramli/.pyenv/versions/3.10.7/lib/python3.10/site-packages/django/db/backends/utils.py", line 92, in _execute_with_wrappers
    return executor(sql, params, many, context)
  File "/home/nadeemramli/.pyenv/versions/3.10.7/lib/python3.10/site-packages/django/db/backends/utils.py", line 100, in _execute
    with self.db.wrap_database_errors:
  File "/home/nadeemramli/.pyenv/versions/3.10.7/lib/python3.10/site-packages/django/db/utils.py", line 91, in __exit__
    raise dj_exc_value.with_traceback(traceback) from exc_value
  File "/home/nadeemramli/.pyenv/versions/3.10.7/lib/python3.10/site-packages/django/db/backends/utils.py", line 103, in _execute
    return self.cursor.execute(sql)
django.db.utils.IntegrityError: insert or update on table "metrics_category" violates foreign key constraint "metrics_category_tenant_id_67d98cc6_fk_metrics_client_id"
DETAIL:  Key (tenant_id)=(18) is not present in table "metrics_client".


======================================================================
ERROR: test_get_metric_reports (metrics.tests.test_apis.APITests)
----------------------------------------------------------------------
Traceback (most recent call last):
  File "/home/nadeemramli/workspace/github.com/nadeemramli/mapping-of-metrics/metric-map-app/backend/metricMapAPI/metrics/tests/test_apis.py", line 17, in setUp
    self.tag = Tag.objects.create(name='Test Tag', project=self.tenant, tenant=self.tenant)
  File "/home/nadeemramli/.pyenv/versions/3.10.7/lib/python3.10/site-packages/django/db/models/manager.py", line 87, in manager_method
    return getattr(self.get_queryset(), name)(*args, **kwargs)
  File "/home/nadeemramli/.pyenv/versions/3.10.7/lib/python3.10/site-packages/django/db/models/query.py", line 677, in create
    obj = self.model(**kwargs)
  File "/home/nadeemramli/.pyenv/versions/3.10.7/lib/python3.10/site-packages/django/db/models/base.py", line 543, in __init__
    _setattr(self, field.name, rel_obj)
  File "/home/nadeemramli/.pyenv/versions/3.10.7/lib/python3.10/site-packages/django/db/models/fields/related_descriptors.py", line 284, in __set__
    raise ValueError(
ValueError: Cannot assign "<Client: Test Project>": "Tag.project" must be a "Project" instance.

======================================================================
ERROR: test_get_metric_reports (metrics.tests.test_apis.APITests)
----------------------------------------------------------------------
Traceback (most recent call last):
  File "/home/nadeemramli/.pyenv/versions/3.10.7/lib/python3.10/site-packages/django/db/backends/utils.py", line 103, in _execute
    return self.cursor.execute(sql)
psycopg2.errors.ForeignKeyViolation: insert or update on table "metrics_category" violates foreign key constraint "metrics_category_tenant_id_67d98cc6_fk_metrics_client_id"
DETAIL:  Key (tenant_id)=(19) is not present in table "metrics_client".


The above exception was the direct cause of the following exception:

Traceback (most recent call last):
  File "/home/nadeemramli/.pyenv/versions/3.10.7/lib/python3.10/site-packages/django/test/testcases.py", line 296, in _setup_and_call
    self._post_teardown()
  File "/home/nadeemramli/.pyenv/versions/3.10.7/lib/python3.10/site-packages/django/test/testcases.py", line 1102, in _post_teardown
    self._fixture_teardown()
  File "/home/nadeemramli/.pyenv/versions/3.10.7/lib/python3.10/site-packages/django/test/testcases.py", line 1333, in _fixture_teardown
    connections[db_name].check_constraints()
  File "/home/nadeemramli/.pyenv/versions/3.10.7/lib/python3.10/site-packages/django/db/backends/postgresql/base.py", line 385, in check_constraints
    cursor.execute("SET CONSTRAINTS ALL IMMEDIATE")
  File "/home/nadeemramli/.pyenv/versions/3.10.7/lib/python3.10/site-packages/django/db/backends/utils.py", line 79, in execute
    return self._execute_with_wrappers(
  File "/home/nadeemramli/.pyenv/versions/3.10.7/lib/python3.10/site-packages/django/db/backends/utils.py", line 92, in _execute_with_wrappers
    return executor(sql, params, many, context)
  File "/home/nadeemramli/.pyenv/versions/3.10.7/lib/python3.10/site-packages/django/db/backends/utils.py", line 100, in _execute
    with self.db.wrap_database_errors:
  File "/home/nadeemramli/.pyenv/versions/3.10.7/lib/python3.10/site-packages/django/db/utils.py", line 91, in __exit__
    raise dj_exc_value.with_traceback(traceback) from exc_value
  File "/home/nadeemramli/.pyenv/versions/3.10.7/lib/python3.10/site-packages/django/db/backends/utils.py", line 103, in _execute
    return self.cursor.execute(sql)
django.db.utils.IntegrityError: insert or update on table "metrics_category" violates foreign key constraint "metrics_category_tenant_id_67d98cc6_fk_metrics_client_id"
DETAIL:  Key (tenant_id)=(19) is not present in table "metrics_client".


======================================================================
ERROR: test_get_metric_targets (metrics.tests.test_apis.APITests)
----------------------------------------------------------------------
Traceback (most recent call last):
  File "/home/nadeemramli/workspace/github.com/nadeemramli/mapping-of-metrics/metric-map-app/backend/metricMapAPI/metrics/tests/test_apis.py", line 17, in setUp
    self.tag = Tag.objects.create(name='Test Tag', project=self.tenant, tenant=self.tenant)
  File "/home/nadeemramli/.pyenv/versions/3.10.7/lib/python3.10/site-packages/django/db/models/manager.py", line 87, in manager_method
    return getattr(self.get_queryset(), name)(*args, **kwargs)
  File "/home/nadeemramli/.pyenv/versions/3.10.7/lib/python3.10/site-packages/django/db/models/query.py", line 677, in create
    obj = self.model(**kwargs)
  File "/home/nadeemramli/.pyenv/versions/3.10.7/lib/python3.10/site-packages/django/db/models/base.py", line 543, in __init__
    _setattr(self, field.name, rel_obj)
  File "/home/nadeemramli/.pyenv/versions/3.10.7/lib/python3.10/site-packages/django/db/models/fields/related_descriptors.py", line 284, in __set__
    raise ValueError(
ValueError: Cannot assign "<Client: Test Project>": "Tag.project" must be a "Project" instance.

======================================================================
ERROR: test_get_metric_targets (metrics.tests.test_apis.APITests)
----------------------------------------------------------------------
Traceback (most recent call last):
  File "/home/nadeemramli/.pyenv/versions/3.10.7/lib/python3.10/site-packages/django/db/backends/utils.py", line 103, in _execute
    return self.cursor.execute(sql)
psycopg2.errors.ForeignKeyViolation: insert or update on table "metrics_category" violates foreign key constraint "metrics_category_tenant_id_67d98cc6_fk_metrics_client_id"
DETAIL:  Key (tenant_id)=(20) is not present in table "metrics_client".


The above exception was the direct cause of the following exception:

Traceback (most recent call last):
  File "/home/nadeemramli/.pyenv/versions/3.10.7/lib/python3.10/site-packages/django/test/testcases.py", line 296, in _setup_and_call
    self._post_teardown()
  File "/home/nadeemramli/.pyenv/versions/3.10.7/lib/python3.10/site-packages/django/test/testcases.py", line 1102, in _post_teardown
    self._fixture_teardown()
  File "/home/nadeemramli/.pyenv/versions/3.10.7/lib/python3.10/site-packages/django/test/testcases.py", line 1333, in _fixture_teardown
    connections[db_name].check_constraints()
  File "/home/nadeemramli/.pyenv/versions/3.10.7/lib/python3.10/site-packages/django/db/backends/postgresql/base.py", line 385, in check_constraints
    cursor.execute("SET CONSTRAINTS ALL IMMEDIATE")
  File "/home/nadeemramli/.pyenv/versions/3.10.7/lib/python3.10/site-packages/django/db/backends/utils.py", line 79, in execute
    return self._execute_with_wrappers(
  File "/home/nadeemramli/.pyenv/versions/3.10.7/lib/python3.10/site-packages/django/db/backends/utils.py", line 92, in _execute_with_wrappers
    return executor(sql, params, many, context)
  File "/home/nadeemramli/.pyenv/versions/3.10.7/lib/python3.10/site-packages/django/db/backends/utils.py", line 100, in _execute
    with self.db.wrap_database_errors:
  File "/home/nadeemramli/.pyenv/versions/3.10.7/lib/python3.10/site-packages/django/db/utils.py", line 91, in __exit__
    raise dj_exc_value.with_traceback(traceback) from exc_value
  File "/home/nadeemramli/.pyenv/versions/3.10.7/lib/python3.10/site-packages/django/db/backends/utils.py", line 103, in _execute
    return self.cursor.execute(sql)
django.db.utils.IntegrityError: insert or update on table "metrics_category" violates foreign key constraint "metrics_category_tenant_id_67d98cc6_fk_metrics_client_id"
DETAIL:  Key (tenant_id)=(20) is not present in table "metrics_client".


======================================================================
ERROR: test_get_metrics_list (metrics.tests.test_apis.APITests)
----------------------------------------------------------------------
Traceback (most recent call last):
  File "/home/nadeemramli/workspace/github.com/nadeemramli/mapping-of-metrics/metric-map-app/backend/metricMapAPI/metrics/tests/test_apis.py", line 17, in setUp
    self.tag = Tag.objects.create(name='Test Tag', project=self.tenant, tenant=self.tenant)
  File "/home/nadeemramli/.pyenv/versions/3.10.7/lib/python3.10/site-packages/django/db/models/manager.py", line 87, in manager_method
    return getattr(self.get_queryset(), name)(*args, **kwargs)
  File "/home/nadeemramli/.pyenv/versions/3.10.7/lib/python3.10/site-packages/django/db/models/query.py", line 677, in create
    obj = self.model(**kwargs)
  File "/home/nadeemramli/.pyenv/versions/3.10.7/lib/python3.10/site-packages/django/db/models/base.py", line 543, in __init__
    _setattr(self, field.name, rel_obj)
  File "/home/nadeemramli/.pyenv/versions/3.10.7/lib/python3.10/site-packages/django/db/models/fields/related_descriptors.py", line 284, in __set__
    raise ValueError(
ValueError: Cannot assign "<Client: Test Project>": "Tag.project" must be a "Project" instance.

======================================================================
ERROR: test_get_metrics_list (metrics.tests.test_apis.APITests)
----------------------------------------------------------------------
Traceback (most recent call last):
  File "/home/nadeemramli/.pyenv/versions/3.10.7/lib/python3.10/site-packages/django/db/backends/utils.py", line 103, in _execute
    return self.cursor.execute(sql)
psycopg2.errors.ForeignKeyViolation: insert or update on table "metrics_category" violates foreign key constraint "metrics_category_tenant_id_67d98cc6_fk_metrics_client_id"
DETAIL:  Key (tenant_id)=(21) is not present in table "metrics_client".


The above exception was the direct cause of the following exception:

Traceback (most recent call last):
  File "/home/nadeemramli/.pyenv/versions/3.10.7/lib/python3.10/site-packages/django/test/testcases.py", line 296, in _setup_and_call
    self._post_teardown()
  File "/home/nadeemramli/.pyenv/versions/3.10.7/lib/python3.10/site-packages/django/test/testcases.py", line 1102, in _post_teardown
    self._fixture_teardown()
  File "/home/nadeemramli/.pyenv/versions/3.10.7/lib/python3.10/site-packages/django/test/testcases.py", line 1333, in _fixture_teardown
    connections[db_name].check_constraints()
  File "/home/nadeemramli/.pyenv/versions/3.10.7/lib/python3.10/site-packages/django/db/backends/postgresql/base.py", line 385, in check_constraints
    cursor.execute("SET CONSTRAINTS ALL IMMEDIATE")
  File "/home/nadeemramli/.pyenv/versions/3.10.7/lib/python3.10/site-packages/django/db/backends/utils.py", line 79, in execute
    return self._execute_with_wrappers(
  File "/home/nadeemramli/.pyenv/versions/3.10.7/lib/python3.10/site-packages/django/db/backends/utils.py", line 92, in _execute_with_wrappers
    return executor(sql, params, many, context)
  File "/home/nadeemramli/.pyenv/versions/3.10.7/lib/python3.10/site-packages/django/db/backends/utils.py", line 100, in _execute
    with self.db.wrap_database_errors:
  File "/home/nadeemramli/.pyenv/versions/3.10.7/lib/python3.10/site-packages/django/db/utils.py", line 91, in __exit__
    raise dj_exc_value.with_traceback(traceback) from exc_value
  File "/home/nadeemramli/.pyenv/versions/3.10.7/lib/python3.10/site-packages/django/db/backends/utils.py", line 103, in _execute
    return self.cursor.execute(sql)
django.db.utils.IntegrityError: insert or update on table "metrics_category" violates foreign key constraint "metrics_category_tenant_id_67d98cc6_fk_metrics_client_id"
DETAIL:  Key (tenant_id)=(21) is not present in table "metrics_client".


======================================================================
ERROR: test_get_project_detail (metrics.tests.test_apis.APITests)
----------------------------------------------------------------------
Traceback (most recent call last):
  File "/home/nadeemramli/workspace/github.com/nadeemramli/mapping-of-metrics/metric-map-app/backend/metricMapAPI/metrics/tests/test_apis.py", line 17, in setUp
    self.tag = Tag.objects.create(name='Test Tag', project=self.tenant, tenant=self.tenant)
  File "/home/nadeemramli/.pyenv/versions/3.10.7/lib/python3.10/site-packages/django/db/models/manager.py", line 87, in manager_method
    return getattr(self.get_queryset(), name)(*args, **kwargs)
  File "/home/nadeemramli/.pyenv/versions/3.10.7/lib/python3.10/site-packages/django/db/models/query.py", line 677, in create
    obj = self.model(**kwargs)
  File "/home/nadeemramli/.pyenv/versions/3.10.7/lib/python3.10/site-packages/django/db/models/base.py", line 543, in __init__
    _setattr(self, field.name, rel_obj)
  File "/home/nadeemramli/.pyenv/versions/3.10.7/lib/python3.10/site-packages/django/db/models/fields/related_descriptors.py", line 284, in __set__
    raise ValueError(
ValueError: Cannot assign "<Client: Test Project>": "Tag.project" must be a "Project" instance.

======================================================================
ERROR: test_get_project_detail (metrics.tests.test_apis.APITests)
----------------------------------------------------------------------
Traceback (most recent call last):
  File "/home/nadeemramli/.pyenv/versions/3.10.7/lib/python3.10/site-packages/django/db/backends/utils.py", line 103, in _execute
    return self.cursor.execute(sql)
psycopg2.errors.ForeignKeyViolation: insert or update on table "metrics_category" violates foreign key constraint "metrics_category_tenant_id_67d98cc6_fk_metrics_client_id"
DETAIL:  Key (tenant_id)=(22) is not present in table "metrics_client".


The above exception was the direct cause of the following exception:

Traceback (most recent call last):
  File "/home/nadeemramli/.pyenv/versions/3.10.7/lib/python3.10/site-packages/django/test/testcases.py", line 296, in _setup_and_call
    self._post_teardown()
  File "/home/nadeemramli/.pyenv/versions/3.10.7/lib/python3.10/site-packages/django/test/testcases.py", line 1102, in _post_teardown
    self._fixture_teardown()
  File "/home/nadeemramli/.pyenv/versions/3.10.7/lib/python3.10/site-packages/django/test/testcases.py", line 1333, in _fixture_teardown
    connections[db_name].check_constraints()
  File "/home/nadeemramli/.pyenv/versions/3.10.7/lib/python3.10/site-packages/django/db/backends/postgresql/base.py", line 385, in check_constraints
    cursor.execute("SET CONSTRAINTS ALL IMMEDIATE")
  File "/home/nadeemramli/.pyenv/versions/3.10.7/lib/python3.10/site-packages/django/db/backends/utils.py", line 79, in execute
    return self._execute_with_wrappers(
  File "/home/nadeemramli/.pyenv/versions/3.10.7/lib/python3.10/site-packages/django/db/backends/utils.py", line 92, in _execute_with_wrappers
    return executor(sql, params, many, context)
  File "/home/nadeemramli/.pyenv/versions/3.10.7/lib/python3.10/site-packages/django/db/backends/utils.py", line 100, in _execute
    with self.db.wrap_database_errors:
  File "/home/nadeemramli/.pyenv/versions/3.10.7/lib/python3.10/site-packages/django/db/utils.py", line 91, in __exit__
    raise dj_exc_value.with_traceback(traceback) from exc_value
  File "/home/nadeemramli/.pyenv/versions/3.10.7/lib/python3.10/site-packages/django/db/backends/utils.py", line 103, in _execute
    return self.cursor.execute(sql)
django.db.utils.IntegrityError: insert or update on table "metrics_category" violates foreign key constraint "metrics_category_tenant_id_67d98cc6_fk_metrics_client_id"
DETAIL:  Key (tenant_id)=(22) is not present in table "metrics_client".


======================================================================
ERROR: test_get_projects_list (metrics.tests.test_apis.APITests)
----------------------------------------------------------------------
Traceback (most recent call last):
  File "/home/nadeemramli/workspace/github.com/nadeemramli/mapping-of-metrics/metric-map-app/backend/metricMapAPI/metrics/tests/test_apis.py", line 17, in setUp
    self.tag = Tag.objects.create(name='Test Tag', project=self.tenant, tenant=self.tenant)
  File "/home/nadeemramli/.pyenv/versions/3.10.7/lib/python3.10/site-packages/django/db/models/manager.py", line 87, in manager_method
    return getattr(self.get_queryset(), name)(*args, **kwargs)
  File "/home/nadeemramli/.pyenv/versions/3.10.7/lib/python3.10/site-packages/django/db/models/query.py", line 677, in create
    obj = self.model(**kwargs)
  File "/home/nadeemramli/.pyenv/versions/3.10.7/lib/python3.10/site-packages/django/db/models/base.py", line 543, in __init__
    _setattr(self, field.name, rel_obj)
  File "/home/nadeemramli/.pyenv/versions/3.10.7/lib/python3.10/site-packages/django/db/models/fields/related_descriptors.py", line 284, in __set__
    raise ValueError(
ValueError: Cannot assign "<Client: Test Project>": "Tag.project" must be a "Project" instance.

======================================================================
ERROR: test_get_projects_list (metrics.tests.test_apis.APITests)
----------------------------------------------------------------------
Traceback (most recent call last):
  File "/home/nadeemramli/.pyenv/versions/3.10.7/lib/python3.10/site-packages/django/db/backends/utils.py", line 103, in _execute
    return self.cursor.execute(sql)
psycopg2.errors.ForeignKeyViolation: insert or update on table "metrics_category" violates foreign key constraint "metrics_category_tenant_id_67d98cc6_fk_metrics_client_id"
DETAIL:  Key (tenant_id)=(23) is not present in table "metrics_client".


The above exception was the direct cause of the following exception:

Traceback (most recent call last):
  File "/home/nadeemramli/.pyenv/versions/3.10.7/lib/python3.10/site-packages/django/test/testcases.py", line 296, in _setup_and_call
    self._post_teardown()
  File "/home/nadeemramli/.pyenv/versions/3.10.7/lib/python3.10/site-packages/django/test/testcases.py", line 1102, in _post_teardown
    self._fixture_teardown()
  File "/home/nadeemramli/.pyenv/versions/3.10.7/lib/python3.10/site-packages/django/test/testcases.py", line 1333, in _fixture_teardown
    connections[db_name].check_constraints()
  File "/home/nadeemramli/.pyenv/versions/3.10.7/lib/python3.10/site-packages/django/db/backends/postgresql/base.py", line 385, in check_constraints
    cursor.execute("SET CONSTRAINTS ALL IMMEDIATE")
  File "/home/nadeemramli/.pyenv/versions/3.10.7/lib/python3.10/site-packages/django/db/backends/utils.py", line 79, in execute
    return self._execute_with_wrappers(
  File "/home/nadeemramli/.pyenv/versions/3.10.7/lib/python3.10/site-packages/django/db/backends/utils.py", line 92, in _execute_with_wrappers
    return executor(sql, params, many, context)
  File "/home/nadeemramli/.pyenv/versions/3.10.7/lib/python3.10/site-packages/django/db/backends/utils.py", line 100, in _execute
    with self.db.wrap_database_errors:
  File "/home/nadeemramli/.pyenv/versions/3.10.7/lib/python3.10/site-packages/django/db/utils.py", line 91, in __exit__
    raise dj_exc_value.with_traceback(traceback) from exc_value
  File "/home/nadeemramli/.pyenv/versions/3.10.7/lib/python3.10/site-packages/django/db/backends/utils.py", line 103, in _execute
    return self.cursor.execute(sql)
django.db.utils.IntegrityError: insert or update on table "metrics_category" violates foreign key constraint "metrics_category_tenant_id_67d98cc6_fk_metrics_client_id"
DETAIL:  Key (tenant_id)=(23) is not present in table "metrics_client".


======================================================================
ERROR: test_get_reports (metrics.tests.test_apis.APITests)
----------------------------------------------------------------------
Traceback (most recent call last):
  File "/home/nadeemramli/workspace/github.com/nadeemramli/mapping-of-metrics/metric-map-app/backend/metricMapAPI/metrics/tests/test_apis.py", line 17, in setUp
    self.tag = Tag.objects.create(name='Test Tag', project=self.tenant, tenant=self.tenant)
  File "/home/nadeemramli/.pyenv/versions/3.10.7/lib/python3.10/site-packages/django/db/models/manager.py", line 87, in manager_method
    return getattr(self.get_queryset(), name)(*args, **kwargs)
  File "/home/nadeemramli/.pyenv/versions/3.10.7/lib/python3.10/site-packages/django/db/models/query.py", line 677, in create
    obj = self.model(**kwargs)
  File "/home/nadeemramli/.pyenv/versions/3.10.7/lib/python3.10/site-packages/django/db/models/base.py", line 543, in __init__
    _setattr(self, field.name, rel_obj)
  File "/home/nadeemramli/.pyenv/versions/3.10.7/lib/python3.10/site-packages/django/db/models/fields/related_descriptors.py", line 284, in __set__
    raise ValueError(
ValueError: Cannot assign "<Client: Test Project>": "Tag.project" must be a "Project" instance.

======================================================================
ERROR: test_get_reports (metrics.tests.test_apis.APITests)
----------------------------------------------------------------------
Traceback (most recent call last):
  File "/home/nadeemramli/.pyenv/versions/3.10.7/lib/python3.10/site-packages/django/db/backends/utils.py", line 103, in _execute
    return self.cursor.execute(sql)
psycopg2.errors.ForeignKeyViolation: insert or update on table "metrics_category" violates foreign key constraint "metrics_category_tenant_id_67d98cc6_fk_metrics_client_id"
DETAIL:  Key (tenant_id)=(24) is not present in table "metrics_client".


The above exception was the direct cause of the following exception:

Traceback (most recent call last):
  File "/home/nadeemramli/.pyenv/versions/3.10.7/lib/python3.10/site-packages/django/test/testcases.py", line 296, in _setup_and_call
    self._post_teardown()
  File "/home/nadeemramli/.pyenv/versions/3.10.7/lib/python3.10/site-packages/django/test/testcases.py", line 1102, in _post_teardown
    self._fixture_teardown()
  File "/home/nadeemramli/.pyenv/versions/3.10.7/lib/python3.10/site-packages/django/test/testcases.py", line 1333, in _fixture_teardown
    connections[db_name].check_constraints()
  File "/home/nadeemramli/.pyenv/versions/3.10.7/lib/python3.10/site-packages/django/db/backends/postgresql/base.py", line 385, in check_constraints
    cursor.execute("SET CONSTRAINTS ALL IMMEDIATE")
  File "/home/nadeemramli/.pyenv/versions/3.10.7/lib/python3.10/site-packages/django/db/backends/utils.py", line 79, in execute
    return self._execute_with_wrappers(
  File "/home/nadeemramli/.pyenv/versions/3.10.7/lib/python3.10/site-packages/django/db/backends/utils.py", line 92, in _execute_with_wrappers
    return executor(sql, params, many, context)
  File "/home/nadeemramli/.pyenv/versions/3.10.7/lib/python3.10/site-packages/django/db/backends/utils.py", line 100, in _execute
    with self.db.wrap_database_errors:
  File "/home/nadeemramli/.pyenv/versions/3.10.7/lib/python3.10/site-packages/django/db/utils.py", line 91, in __exit__
    raise dj_exc_value.with_traceback(traceback) from exc_value
  File "/home/nadeemramli/.pyenv/versions/3.10.7/lib/python3.10/site-packages/django/db/backends/utils.py", line 103, in _execute
    return self.cursor.execute(sql)
django.db.utils.IntegrityError: insert or update on table "metrics_category" violates foreign key constraint "metrics_category_tenant_id_67d98cc6_fk_metrics_client_id"
DETAIL:  Key (tenant_id)=(24) is not present in table "metrics_client".


======================================================================
ERROR: test_get_tags (metrics.tests.test_apis.APITests)
----------------------------------------------------------------------
Traceback (most recent call last):
  File "/home/nadeemramli/workspace/github.com/nadeemramli/mapping-of-metrics/metric-map-app/backend/metricMapAPI/metrics/tests/test_apis.py", line 17, in setUp
    self.tag = Tag.objects.create(name='Test Tag', project=self.tenant, tenant=self.tenant)
  File "/home/nadeemramli/.pyenv/versions/3.10.7/lib/python3.10/site-packages/django/db/models/manager.py", line 87, in manager_method
    return getattr(self.get_queryset(), name)(*args, **kwargs)
  File "/home/nadeemramli/.pyenv/versions/3.10.7/lib/python3.10/site-packages/django/db/models/query.py", line 677, in create
    obj = self.model(**kwargs)
  File "/home/nadeemramli/.pyenv/versions/3.10.7/lib/python3.10/site-packages/django/db/models/base.py", line 543, in __init__
    _setattr(self, field.name, rel_obj)
  File "/home/nadeemramli/.pyenv/versions/3.10.7/lib/python3.10/site-packages/django/db/models/fields/related_descriptors.py", line 284, in __set__
    raise ValueError(
ValueError: Cannot assign "<Client: Test Project>": "Tag.project" must be a "Project" instance.

======================================================================
ERROR: test_get_tags (metrics.tests.test_apis.APITests)
----------------------------------------------------------------------
Traceback (most recent call last):
  File "/home/nadeemramli/.pyenv/versions/3.10.7/lib/python3.10/site-packages/django/db/backends/utils.py", line 103, in _execute
    return self.cursor.execute(sql)
psycopg2.errors.ForeignKeyViolation: insert or update on table "metrics_category" violates foreign key constraint "metrics_category_tenant_id_67d98cc6_fk_metrics_client_id"
DETAIL:  Key (tenant_id)=(25) is not present in table "metrics_client".


The above exception was the direct cause of the following exception:

Traceback (most recent call last):
  File "/home/nadeemramli/.pyenv/versions/3.10.7/lib/python3.10/site-packages/django/test/testcases.py", line 296, in _setup_and_call
    self._post_teardown()
  File "/home/nadeemramli/.pyenv/versions/3.10.7/lib/python3.10/site-packages/django/test/testcases.py", line 1102, in _post_teardown
    self._fixture_teardown()
  File "/home/nadeemramli/.pyenv/versions/3.10.7/lib/python3.10/site-packages/django/test/testcases.py", line 1333, in _fixture_teardown
    connections[db_name].check_constraints()
  File "/home/nadeemramli/.pyenv/versions/3.10.7/lib/python3.10/site-packages/django/db/backends/postgresql/base.py", line 385, in check_constraints
    cursor.execute("SET CONSTRAINTS ALL IMMEDIATE")
  File "/home/nadeemramli/.pyenv/versions/3.10.7/lib/python3.10/site-packages/django/db/backends/utils.py", line 79, in execute
    return self._execute_with_wrappers(
  File "/home/nadeemramli/.pyenv/versions/3.10.7/lib/python3.10/site-packages/django/db/backends/utils.py", line 92, in _execute_with_wrappers
    return executor(sql, params, many, context)
  File "/home/nadeemramli/.pyenv/versions/3.10.7/lib/python3.10/site-packages/django/db/backends/utils.py", line 100, in _execute
    with self.db.wrap_database_errors:
  File "/home/nadeemramli/.pyenv/versions/3.10.7/lib/python3.10/site-packages/django/db/utils.py", line 91, in __exit__
    raise dj_exc_value.with_traceback(traceback) from exc_value
  File "/home/nadeemramli/.pyenv/versions/3.10.7/lib/python3.10/site-packages/django/db/backends/utils.py", line 103, in _execute
    return self.cursor.execute(sql)
django.db.utils.IntegrityError: insert or update on table "metrics_category" violates foreign key constraint "metrics_category_tenant_id_67d98cc6_fk_metrics_client_id"
DETAIL:  Key (tenant_id)=(25) is not present in table "metrics_client".


======================================================================
ERROR: test_get_targets (metrics.tests.test_apis.APITests)
----------------------------------------------------------------------
Traceback (most recent call last):
  File "/home/nadeemramli/workspace/github.com/nadeemramli/mapping-of-metrics/metric-map-app/backend/metricMapAPI/metrics/tests/test_apis.py", line 17, in setUp
    self.tag = Tag.objects.create(name='Test Tag', project=self.tenant, tenant=self.tenant)
  File "/home/nadeemramli/.pyenv/versions/3.10.7/lib/python3.10/site-packages/django/db/models/manager.py", line 87, in manager_method
    return getattr(self.get_queryset(), name)(*args, **kwargs)
  File "/home/nadeemramli/.pyenv/versions/3.10.7/lib/python3.10/site-packages/django/db/models/query.py", line 677, in create
    obj = self.model(**kwargs)
  File "/home/nadeemramli/.pyenv/versions/3.10.7/lib/python3.10/site-packages/django/db/models/base.py", line 543, in __init__
    _setattr(self, field.name, rel_obj)
  File "/home/nadeemramli/.pyenv/versions/3.10.7/lib/python3.10/site-packages/django/db/models/fields/related_descriptors.py", line 284, in __set__
    raise ValueError(
ValueError: Cannot assign "<Client: Test Project>": "Tag.project" must be a "Project" instance.

======================================================================
ERROR: test_get_targets (metrics.tests.test_apis.APITests)
----------------------------------------------------------------------
Traceback (most recent call last):
  File "/home/nadeemramli/.pyenv/versions/3.10.7/lib/python3.10/site-packages/django/db/backends/utils.py", line 103, in _execute
    return self.cursor.execute(sql)
psycopg2.errors.ForeignKeyViolation: insert or update on table "metrics_category" violates foreign key constraint "metrics_category_tenant_id_67d98cc6_fk_metrics_client_id"
DETAIL:  Key (tenant_id)=(26) is not present in table "metrics_client".


The above exception was the direct cause of the following exception:

Traceback (most recent call last):
  File "/home/nadeemramli/.pyenv/versions/3.10.7/lib/python3.10/site-packages/django/test/testcases.py", line 296, in _setup_and_call
    self._post_teardown()
  File "/home/nadeemramli/.pyenv/versions/3.10.7/lib/python3.10/site-packages/django/test/testcases.py", line 1102, in _post_teardown
    self._fixture_teardown()
  File "/home/nadeemramli/.pyenv/versions/3.10.7/lib/python3.10/site-packages/django/test/testcases.py", line 1333, in _fixture_teardown
    connections[db_name].check_constraints()
  File "/home/nadeemramli/.pyenv/versions/3.10.7/lib/python3.10/site-packages/django/db/backends/postgresql/base.py", line 385, in check_constraints
    cursor.execute("SET CONSTRAINTS ALL IMMEDIATE")
  File "/home/nadeemramli/.pyenv/versions/3.10.7/lib/python3.10/site-packages/django/db/backends/utils.py", line 79, in execute
    return self._execute_with_wrappers(
  File "/home/nadeemramli/.pyenv/versions/3.10.7/lib/python3.10/site-packages/django/db/backends/utils.py", line 92, in _execute_with_wrappers
    return executor(sql, params, many, context)
  File "/home/nadeemramli/.pyenv/versions/3.10.7/lib/python3.10/site-packages/django/db/backends/utils.py", line 100, in _execute
    with self.db.wrap_database_errors:
  File "/home/nadeemramli/.pyenv/versions/3.10.7/lib/python3.10/site-packages/django/db/utils.py", line 91, in __exit__
    raise dj_exc_value.with_traceback(traceback) from exc_value
  File "/home/nadeemramli/.pyenv/versions/3.10.7/lib/python3.10/site-packages/django/db/backends/utils.py", line 103, in _execute
    return self.cursor.execute(sql)
django.db.utils.IntegrityError: insert or update on table "metrics_category" violates foreign key constraint "metrics_category_tenant_id_67d98cc6_fk_metrics_client_id"
DETAIL:  Key (tenant_id)=(26) is not present in table "metrics_client".


======================================================================
ERROR: test_health_check (metrics.tests.test_apis.APITests)
----------------------------------------------------------------------
Traceback (most recent call last):
  File "/home/nadeemramli/workspace/github.com/nadeemramli/mapping-of-metrics/metric-map-app/backend/metricMapAPI/metrics/tests/test_apis.py", line 17, in setUp
    self.tag = Tag.objects.create(name='Test Tag', project=self.tenant, tenant=self.tenant)
  File "/home/nadeemramli/.pyenv/versions/3.10.7/lib/python3.10/site-packages/django/db/models/manager.py", line 87, in manager_method
    return getattr(self.get_queryset(), name)(*args, **kwargs)
  File "/home/nadeemramli/.pyenv/versions/3.10.7/lib/python3.10/site-packages/django/db/models/query.py", line 677, in create
    obj = self.model(**kwargs)
  File "/home/nadeemramli/.pyenv/versions/3.10.7/lib/python3.10/site-packages/django/db/models/base.py", line 543, in __init__
    _setattr(self, field.name, rel_obj)
  File "/home/nadeemramli/.pyenv/versions/3.10.7/lib/python3.10/site-packages/django/db/models/fields/related_descriptors.py", line 284, in __set__
    raise ValueError(
ValueError: Cannot assign "<Client: Test Project>": "Tag.project" must be a "Project" instance.

======================================================================
ERROR: test_health_check (metrics.tests.test_apis.APITests)
----------------------------------------------------------------------
Traceback (most recent call last):
  File "/home/nadeemramli/.pyenv/versions/3.10.7/lib/python3.10/site-packages/django/db/backends/utils.py", line 103, in _execute
    return self.cursor.execute(sql)
psycopg2.errors.ForeignKeyViolation: insert or update on table "metrics_category" violates foreign key constraint "metrics_category_tenant_id_67d98cc6_fk_metrics_client_id"
DETAIL:  Key (tenant_id)=(27) is not present in table "metrics_client".


The above exception was the direct cause of the following exception:

Traceback (most recent call last):
  File "/home/nadeemramli/.pyenv/versions/3.10.7/lib/python3.10/site-packages/django/test/testcases.py", line 296, in _setup_and_call
    self._post_teardown()
  File "/home/nadeemramli/.pyenv/versions/3.10.7/lib/python3.10/site-packages/django/test/testcases.py", line 1102, in _post_teardown
    self._fixture_teardown()
  File "/home/nadeemramli/.pyenv/versions/3.10.7/lib/python3.10/site-packages/django/test/testcases.py", line 1333, in _fixture_teardown
    connections[db_name].check_constraints()
  File "/home/nadeemramli/.pyenv/versions/3.10.7/lib/python3.10/site-packages/django/db/backends/postgresql/base.py", line 385, in check_constraints
    cursor.execute("SET CONSTRAINTS ALL IMMEDIATE")
  File "/home/nadeemramli/.pyenv/versions/3.10.7/lib/python3.10/site-packages/django/db/backends/utils.py", line 79, in execute
    return self._execute_with_wrappers(
  File "/home/nadeemramli/.pyenv/versions/3.10.7/lib/python3.10/site-packages/django/db/backends/utils.py", line 92, in _execute_with_wrappers
    return executor(sql, params, many, context)
  File "/home/nadeemramli/.pyenv/versions/3.10.7/lib/python3.10/site-packages/django/db/backends/utils.py", line 100, in _execute
    with self.db.wrap_database_errors:
  File "/home/nadeemramli/.pyenv/versions/3.10.7/lib/python3.10/site-packages/django/db/utils.py", line 91, in __exit__
    raise dj_exc_value.with_traceback(traceback) from exc_value
  File "/home/nadeemramli/.pyenv/versions/3.10.7/lib/python3.10/site-packages/django/db/backends/utils.py", line 103, in _execute
    return self.cursor.execute(sql)
django.db.utils.IntegrityError: insert or update on table "metrics_category" violates foreign key constraint "metrics_category_tenant_id_67d98cc6_fk_metrics_client_id"
DETAIL:  Key (tenant_id)=(27) is not present in table "metrics_client".


======================================================================
ERROR: test_metric_serializer (metrics.tests.test_apis.APITests)
----------------------------------------------------------------------
Traceback (most recent call last):
  File "/home/nadeemramli/workspace/github.com/nadeemramli/mapping-of-metrics/metric-map-app/backend/metricMapAPI/metrics/tests/test_apis.py", line 17, in setUp
    self.tag = Tag.objects.create(name='Test Tag', project=self.tenant, tenant=self.tenant)
  File "/home/nadeemramli/.pyenv/versions/3.10.7/lib/python3.10/site-packages/django/db/models/manager.py", line 87, in manager_method
    return getattr(self.get_queryset(), name)(*args, **kwargs)
  File "/home/nadeemramli/.pyenv/versions/3.10.7/lib/python3.10/site-packages/django/db/models/query.py", line 677, in create
    obj = self.model(**kwargs)
  File "/home/nadeemramli/.pyenv/versions/3.10.7/lib/python3.10/site-packages/django/db/models/base.py", line 543, in __init__
    _setattr(self, field.name, rel_obj)
  File "/home/nadeemramli/.pyenv/versions/3.10.7/lib/python3.10/site-packages/django/db/models/fields/related_descriptors.py", line 284, in __set__
    raise ValueError(
ValueError: Cannot assign "<Client: Test Project>": "Tag.project" must be a "Project" instance.

======================================================================
ERROR: test_metric_serializer (metrics.tests.test_apis.APITests)
----------------------------------------------------------------------
Traceback (most recent call last):
  File "/home/nadeemramli/.pyenv/versions/3.10.7/lib/python3.10/site-packages/django/db/backends/utils.py", line 103, in _execute
    return self.cursor.execute(sql)
psycopg2.errors.ForeignKeyViolation: insert or update on table "metrics_category" violates foreign key constraint "metrics_category_tenant_id_67d98cc6_fk_metrics_client_id"
DETAIL:  Key (tenant_id)=(28) is not present in table "metrics_client".


The above exception was the direct cause of the following exception:

Traceback (most recent call last):
  File "/home/nadeemramli/.pyenv/versions/3.10.7/lib/python3.10/site-packages/django/test/testcases.py", line 296, in _setup_and_call
    self._post_teardown()
  File "/home/nadeemramli/.pyenv/versions/3.10.7/lib/python3.10/site-packages/django/test/testcases.py", line 1102, in _post_teardown
    self._fixture_teardown()
  File "/home/nadeemramli/.pyenv/versions/3.10.7/lib/python3.10/site-packages/django/test/testcases.py", line 1333, in _fixture_teardown
    connections[db_name].check_constraints()
  File "/home/nadeemramli/.pyenv/versions/3.10.7/lib/python3.10/site-packages/django/db/backends/postgresql/base.py", line 385, in check_constraints
    cursor.execute("SET CONSTRAINTS ALL IMMEDIATE")
  File "/home/nadeemramli/.pyenv/versions/3.10.7/lib/python3.10/site-packages/django/db/backends/utils.py", line 79, in execute
    return self._execute_with_wrappers(
  File "/home/nadeemramli/.pyenv/versions/3.10.7/lib/python3.10/site-packages/django/db/backends/utils.py", line 92, in _execute_with_wrappers
    return executor(sql, params, many, context)
  File "/home/nadeemramli/.pyenv/versions/3.10.7/lib/python3.10/site-packages/django/db/backends/utils.py", line 100, in _execute
    with self.db.wrap_database_errors:
  File "/home/nadeemramli/.pyenv/versions/3.10.7/lib/python3.10/site-packages/django/db/utils.py", line 91, in __exit__
    raise dj_exc_value.with_traceback(traceback) from exc_value
  File "/home/nadeemramli/.pyenv/versions/3.10.7/lib/python3.10/site-packages/django/db/backends/utils.py", line 103, in _execute
    return self.cursor.execute(sql)
django.db.utils.IntegrityError: insert or update on table "metrics_category" violates foreign key constraint "metrics_category_tenant_id_67d98cc6_fk_metrics_client_id"
DETAIL:  Key (tenant_id)=(28) is not present in table "metrics_client".


======================================================================
ERROR: test_project_serializer (metrics.tests.test_apis.APITests)
----------------------------------------------------------------------
Traceback (most recent call last):
  File "/home/nadeemramli/workspace/github.com/nadeemramli/mapping-of-metrics/metric-map-app/backend/metricMapAPI/metrics/tests/test_apis.py", line 17, in setUp
    self.tag = Tag.objects.create(name='Test Tag', project=self.tenant, tenant=self.tenant)
  File "/home/nadeemramli/.pyenv/versions/3.10.7/lib/python3.10/site-packages/django/db/models/manager.py", line 87, in manager_method
    return getattr(self.get_queryset(), name)(*args, **kwargs)
  File "/home/nadeemramli/.pyenv/versions/3.10.7/lib/python3.10/site-packages/django/db/models/query.py", line 677, in create
    obj = self.model(**kwargs)
  File "/home/nadeemramli/.pyenv/versions/3.10.7/lib/python3.10/site-packages/django/db/models/base.py", line 543, in __init__
    _setattr(self, field.name, rel_obj)
  File "/home/nadeemramli/.pyenv/versions/3.10.7/lib/python3.10/site-packages/django/db/models/fields/related_descriptors.py", line 284, in __set__
    raise ValueError(
ValueError: Cannot assign "<Client: Test Project>": "Tag.project" must be a "Project" instance.

======================================================================
ERROR: test_project_serializer (metrics.tests.test_apis.APITests)
----------------------------------------------------------------------
Traceback (most recent call last):
  File "/home/nadeemramli/.pyenv/versions/3.10.7/lib/python3.10/site-packages/django/db/backends/utils.py", line 103, in _execute
    return self.cursor.execute(sql)
psycopg2.errors.ForeignKeyViolation: insert or update on table "metrics_category" violates foreign key constraint "metrics_category_tenant_id_67d98cc6_fk_metrics_client_id"
DETAIL:  Key (tenant_id)=(29) is not present in table "metrics_client".


The above exception was the direct cause of the following exception:

Traceback (most recent call last):
  File "/home/nadeemramli/.pyenv/versions/3.10.7/lib/python3.10/site-packages/django/test/testcases.py", line 296, in _setup_and_call
    self._post_teardown()
  File "/home/nadeemramli/.pyenv/versions/3.10.7/lib/python3.10/site-packages/django/test/testcases.py", line 1102, in _post_teardown
    self._fixture_teardown()
  File "/home/nadeemramli/.pyenv/versions/3.10.7/lib/python3.10/site-packages/django/test/testcases.py", line 1333, in _fixture_teardown
    connections[db_name].check_constraints()
  File "/home/nadeemramli/.pyenv/versions/3.10.7/lib/python3.10/site-packages/django/db/backends/postgresql/base.py", line 385, in check_constraints
    cursor.execute("SET CONSTRAINTS ALL IMMEDIATE")
  File "/home/nadeemramli/.pyenv/versions/3.10.7/lib/python3.10/site-packages/django/db/backends/utils.py", line 79, in execute
    return self._execute_with_wrappers(
  File "/home/nadeemramli/.pyenv/versions/3.10.7/lib/python3.10/site-packages/django/db/backends/utils.py", line 92, in _execute_with_wrappers
    return executor(sql, params, many, context)
  File "/home/nadeemramli/.pyenv/versions/3.10.7/lib/python3.10/site-packages/django/db/backends/utils.py", line 100, in _execute
    with self.db.wrap_database_errors:
  File "/home/nadeemramli/.pyenv/versions/3.10.7/lib/python3.10/site-packages/django/db/utils.py", line 91, in __exit__
    raise dj_exc_value.with_traceback(traceback) from exc_value
  File "/home/nadeemramli/.pyenv/versions/3.10.7/lib/python3.10/site-packages/django/db/backends/utils.py", line 103, in _execute
    return self.cursor.execute(sql)
django.db.utils.IntegrityError: insert or update on table "metrics_category" violates foreign key constraint "metrics_category_tenant_id_67d98cc6_fk_metrics_client_id"
DETAIL:  Key (tenant_id)=(29) is not present in table "metrics_client".


======================================================================
ERROR: test_update_metric (metrics.tests.test_apis.APITests)
----------------------------------------------------------------------
Traceback (most recent call last):
  File "/home/nadeemramli/workspace/github.com/nadeemramli/mapping-of-metrics/metric-map-app/backend/metricMapAPI/metrics/tests/test_apis.py", line 17, in setUp
    self.tag = Tag.objects.create(name='Test Tag', project=self.tenant, tenant=self.tenant)
  File "/home/nadeemramli/.pyenv/versions/3.10.7/lib/python3.10/site-packages/django/db/models/manager.py", line 87, in manager_method
    return getattr(self.get_queryset(), name)(*args, **kwargs)
  File "/home/nadeemramli/.pyenv/versions/3.10.7/lib/python3.10/site-packages/django/db/models/query.py", line 677, in create
    obj = self.model(**kwargs)
  File "/home/nadeemramli/.pyenv/versions/3.10.7/lib/python3.10/site-packages/django/db/models/base.py", line 543, in __init__
    _setattr(self, field.name, rel_obj)
  File "/home/nadeemramli/.pyenv/versions/3.10.7/lib/python3.10/site-packages/django/db/models/fields/related_descriptors.py", line 284, in __set__
    raise ValueError(
ValueError: Cannot assign "<Client: Test Project>": "Tag.project" must be a "Project" instance.

======================================================================
ERROR: test_update_metric (metrics.tests.test_apis.APITests)
----------------------------------------------------------------------
Traceback (most recent call last):
  File "/home/nadeemramli/.pyenv/versions/3.10.7/lib/python3.10/site-packages/django/db/backends/utils.py", line 103, in _execute
    return self.cursor.execute(sql)
psycopg2.errors.ForeignKeyViolation: insert or update on table "metrics_category" violates foreign key constraint "metrics_category_tenant_id_67d98cc6_fk_metrics_client_id"
DETAIL:  Key (tenant_id)=(30) is not present in table "metrics_client".


The above exception was the direct cause of the following exception:

Traceback (most recent call last):
  File "/home/nadeemramli/.pyenv/versions/3.10.7/lib/python3.10/site-packages/django/test/testcases.py", line 296, in _setup_and_call
    self._post_teardown()
  File "/home/nadeemramli/.pyenv/versions/3.10.7/lib/python3.10/site-packages/django/test/testcases.py", line 1102, in _post_teardown
    self._fixture_teardown()
  File "/home/nadeemramli/.pyenv/versions/3.10.7/lib/python3.10/site-packages/django/test/testcases.py", line 1333, in _fixture_teardown
    connections[db_name].check_constraints()
  File "/home/nadeemramli/.pyenv/versions/3.10.7/lib/python3.10/site-packages/django/db/backends/postgresql/base.py", line 385, in check_constraints
    cursor.execute("SET CONSTRAINTS ALL IMMEDIATE")
  File "/home/nadeemramli/.pyenv/versions/3.10.7/lib/python3.10/site-packages/django/db/backends/utils.py", line 79, in execute
    return self._execute_with_wrappers(
  File "/home/nadeemramli/.pyenv/versions/3.10.7/lib/python3.10/site-packages/django/db/backends/utils.py", line 92, in _execute_with_wrappers
    return executor(sql, params, many, context)
  File "/home/nadeemramli/.pyenv/versions/3.10.7/lib/python3.10/site-packages/django/db/backends/utils.py", line 100, in _execute
    with self.db.wrap_database_errors:
  File "/home/nadeemramli/.pyenv/versions/3.10.7/lib/python3.10/site-packages/django/db/utils.py", line 91, in __exit__
    raise dj_exc_value.with_traceback(traceback) from exc_value
  File "/home/nadeemramli/.pyenv/versions/3.10.7/lib/python3.10/site-packages/django/db/backends/utils.py", line 103, in _execute
    return self.cursor.execute(sql)
django.db.utils.IntegrityError: insert or update on table "metrics_category" violates foreign key constraint "metrics_category_tenant_id_67d98cc6_fk_metrics_client_id"
DETAIL:  Key (tenant_id)=(30) is not present in table "metrics_client".


======================================================================
ERROR: test_url_patterns (metrics.tests.test_apis.APITests)
----------------------------------------------------------------------
Traceback (most recent call last):
  File "/home/nadeemramli/workspace/github.com/nadeemramli/mapping-of-metrics/metric-map-app/backend/metricMapAPI/metrics/tests/test_apis.py", line 17, in setUp
    self.tag = Tag.objects.create(name='Test Tag', project=self.tenant, tenant=self.tenant)
  File "/home/nadeemramli/.pyenv/versions/3.10.7/lib/python3.10/site-packages/django/db/models/manager.py", line 87, in manager_method
    return getattr(self.get_queryset(), name)(*args, **kwargs)
  File "/home/nadeemramli/.pyenv/versions/3.10.7/lib/python3.10/site-packages/django/db/models/query.py", line 677, in create
    obj = self.model(**kwargs)
  File "/home/nadeemramli/.pyenv/versions/3.10.7/lib/python3.10/site-packages/django/db/models/base.py", line 543, in __init__
    _setattr(self, field.name, rel_obj)
  File "/home/nadeemramli/.pyenv/versions/3.10.7/lib/python3.10/site-packages/django/db/models/fields/related_descriptors.py", line 284, in __set__
    raise ValueError(
ValueError: Cannot assign "<Client: Test Project>": "Tag.project" must be a "Project" instance.

======================================================================
ERROR: test_url_patterns (metrics.tests.test_apis.APITests)
----------------------------------------------------------------------
Traceback (most recent call last):
  File "/home/nadeemramli/.pyenv/versions/3.10.7/lib/python3.10/site-packages/django/db/backends/utils.py", line 103, in _execute
    return self.cursor.execute(sql)
psycopg2.errors.ForeignKeyViolation: insert or update on table "metrics_category" violates foreign key constraint "metrics_category_tenant_id_67d98cc6_fk_metrics_client_id"
DETAIL:  Key (tenant_id)=(31) is not present in table "metrics_client".


The above exception was the direct cause of the following exception:

Traceback (most recent call last):
  File "/home/nadeemramli/.pyenv/versions/3.10.7/lib/python3.10/site-packages/django/test/testcases.py", line 296, in _setup_and_call
    self._post_teardown()
  File "/home/nadeemramli/.pyenv/versions/3.10.7/lib/python3.10/site-packages/django/test/testcases.py", line 1102, in _post_teardown
    self._fixture_teardown()
  File "/home/nadeemramli/.pyenv/versions/3.10.7/lib/python3.10/site-packages/django/test/testcases.py", line 1333, in _fixture_teardown
    connections[db_name].check_constraints()
  File "/home/nadeemramli/.pyenv/versions/3.10.7/lib/python3.10/site-packages/django/db/backends/postgresql/base.py", line 385, in check_constraints
    cursor.execute("SET CONSTRAINTS ALL IMMEDIATE")
  File "/home/nadeemramli/.pyenv/versions/3.10.7/lib/python3.10/site-packages/django/db/backends/utils.py", line 79, in execute
    return self._execute_with_wrappers(
  File "/home/nadeemramli/.pyenv/versions/3.10.7/lib/python3.10/site-packages/django/db/backends/utils.py", line 92, in _execute_with_wrappers
    return executor(sql, params, many, context)
  File "/home/nadeemramli/.pyenv/versions/3.10.7/lib/python3.10/site-packages/django/db/backends/utils.py", line 100, in _execute
    with self.db.wrap_database_errors:
  File "/home/nadeemramli/.pyenv/versions/3.10.7/lib/python3.10/site-packages/django/db/utils.py", line 91, in __exit__
    raise dj_exc_value.with_traceback(traceback) from exc_value
  File "/home/nadeemramli/.pyenv/versions/3.10.7/lib/python3.10/site-packages/django/db/backends/utils.py", line 103, in _execute
    return self.cursor.execute(sql)
django.db.utils.IntegrityError: insert or update on table "metrics_category" violates foreign key constraint "metrics_category_tenant_id_67d98cc6_fk_metrics_client_id"
DETAIL:  Key (tenant_id)=(31) is not present in table "metrics_client".


----------------------------------------------------------------------
Ran 30 tests in 19.109s

FAILED (errors=60)

Test Result: Failure
Errors: 60
Failures: 0
