Ran 30 tests in 5.658 seconds

EEEEEEEEEEEEEEEEEEEEEEEEEEEEEE
======================================================================
ERROR: test_analyze_metric (metrics.tests.test_apis.APITests)
----------------------------------------------------------------------
Traceback (most recent call last):
  File "/home/nadeemramli/workspace/github.com/nadeemramli/mapping-of-metrics/metric-map-app/backend/metricMapAPI/metrics/tests/test_apis.py", line 22, in setUp
    self.client.force_authenticate(user=self.user)
AttributeError: 'Client' object has no attribute 'force_authenticate'

======================================================================
ERROR: test_authentication_required (metrics.tests.test_apis.APITests)
----------------------------------------------------------------------
Traceback (most recent call last):
  File "/home/nadeemramli/workspace/github.com/nadeemramli/mapping-of-metrics/metric-map-app/backend/metricMapAPI/metrics/tests/test_apis.py", line 22, in setUp
    self.client.force_authenticate(user=self.user)
AttributeError: 'Client' object has no attribute 'force_authenticate'

======================================================================
ERROR: test_create_action_remark (metrics.tests.test_apis.APITests)
----------------------------------------------------------------------
Traceback (most recent call last):
  File "/home/nadeemramli/workspace/github.com/nadeemramli/mapping-of-metrics/metric-map-app/backend/metricMapAPI/metrics/tests/test_apis.py", line 22, in setUp
    self.client.force_authenticate(user=self.user)
AttributeError: 'Client' object has no attribute 'force_authenticate'

======================================================================
ERROR: test_create_dashboard (metrics.tests.test_apis.APITests)
----------------------------------------------------------------------
Traceback (most recent call last):
  File "/home/nadeemramli/workspace/github.com/nadeemramli/mapping-of-metrics/metric-map-app/backend/metricMapAPI/metrics/tests/test_apis.py", line 22, in setUp
    self.client.force_authenticate(user=self.user)
AttributeError: 'Client' object has no attribute 'force_authenticate'

======================================================================
ERROR: test_create_experiment (metrics.tests.test_apis.APITests)
----------------------------------------------------------------------
Traceback (most recent call last):
  File "/home/nadeemramli/workspace/github.com/nadeemramli/mapping-of-metrics/metric-map-app/backend/metricMapAPI/metrics/tests/test_apis.py", line 22, in setUp
    self.client.force_authenticate(user=self.user)
AttributeError: 'Client' object has no attribute 'force_authenticate'

======================================================================
ERROR: test_create_metric (metrics.tests.test_apis.APITests)
----------------------------------------------------------------------
Traceback (most recent call last):
  File "/home/nadeemramli/workspace/github.com/nadeemramli/mapping-of-metrics/metric-map-app/backend/metricMapAPI/metrics/tests/test_apis.py", line 22, in setUp
    self.client.force_authenticate(user=self.user)
AttributeError: 'Client' object has no attribute 'force_authenticate'

======================================================================
ERROR: test_delete_metric (metrics.tests.test_apis.APITests)
----------------------------------------------------------------------
Traceback (most recent call last):
  File "/home/nadeemramli/workspace/github.com/nadeemramli/mapping-of-metrics/metric-map-app/backend/metricMapAPI/metrics/tests/test_apis.py", line 22, in setUp
    self.client.force_authenticate(user=self.user)
AttributeError: 'Client' object has no attribute 'force_authenticate'

======================================================================
ERROR: test_get_categories (metrics.tests.test_apis.APITests)
----------------------------------------------------------------------
Traceback (most recent call last):
  File "/home/nadeemramli/workspace/github.com/nadeemramli/mapping-of-metrics/metric-map-app/backend/metricMapAPI/metrics/tests/test_apis.py", line 22, in setUp
    self.client.force_authenticate(user=self.user)
AttributeError: 'Client' object has no attribute 'force_authenticate'

======================================================================
ERROR: test_get_client_detail (metrics.tests.test_apis.APITests)
----------------------------------------------------------------------
Traceback (most recent call last):
  File "/home/nadeemramli/workspace/github.com/nadeemramli/mapping-of-metrics/metric-map-app/backend/metricMapAPI/metrics/tests/test_apis.py", line 22, in setUp
    self.client.force_authenticate(user=self.user)
AttributeError: 'Client' object has no attribute 'force_authenticate'

======================================================================
ERROR: test_get_clients_list (metrics.tests.test_apis.APITests)
----------------------------------------------------------------------
Traceback (most recent call last):
  File "/home/nadeemramli/workspace/github.com/nadeemramli/mapping-of-metrics/metric-map-app/backend/metricMapAPI/metrics/tests/test_apis.py", line 22, in setUp
    self.client.force_authenticate(user=self.user)
AttributeError: 'Client' object has no attribute 'force_authenticate'

======================================================================
ERROR: test_get_connections (metrics.tests.test_apis.APITests)
----------------------------------------------------------------------
Traceback (most recent call last):
  File "/home/nadeemramli/workspace/github.com/nadeemramli/mapping-of-metrics/metric-map-app/backend/metricMapAPI/metrics/tests/test_apis.py", line 22, in setUp
    self.client.force_authenticate(user=self.user)
AttributeError: 'Client' object has no attribute 'force_authenticate'

======================================================================
ERROR: test_get_dashboards (metrics.tests.test_apis.APITests)
----------------------------------------------------------------------
Traceback (most recent call last):
  File "/home/nadeemramli/workspace/github.com/nadeemramli/mapping-of-metrics/metric-map-app/backend/metricMapAPI/metrics/tests/test_apis.py", line 22, in setUp
    self.client.force_authenticate(user=self.user)
AttributeError: 'Client' object has no attribute 'force_authenticate'

======================================================================
ERROR: test_get_experiments (metrics.tests.test_apis.APITests)
----------------------------------------------------------------------
Traceback (most recent call last):
  File "/home/nadeemramli/workspace/github.com/nadeemramli/mapping-of-metrics/metric-map-app/backend/metricMapAPI/metrics/tests/test_apis.py", line 22, in setUp
    self.client.force_authenticate(user=self.user)
AttributeError: 'Client' object has no attribute 'force_authenticate'

======================================================================
ERROR: test_get_historical_data (metrics.tests.test_apis.APITests)
----------------------------------------------------------------------
Traceback (most recent call last):
  File "/home/nadeemramli/workspace/github.com/nadeemramli/mapping-of-metrics/metric-map-app/backend/metricMapAPI/metrics/tests/test_apis.py", line 22, in setUp
    self.client.force_authenticate(user=self.user)
AttributeError: 'Client' object has no attribute 'force_authenticate'

======================================================================
ERROR: test_get_metric_action_remarks (metrics.tests.test_apis.APITests)
----------------------------------------------------------------------
Traceback (most recent call last):
  File "/home/nadeemramli/workspace/github.com/nadeemramli/mapping-of-metrics/metric-map-app/backend/metricMapAPI/metrics/tests/test_apis.py", line 22, in setUp
    self.client.force_authenticate(user=self.user)
AttributeError: 'Client' object has no attribute 'force_authenticate'

======================================================================
ERROR: test_get_metric_connections (metrics.tests.test_apis.APITests)
----------------------------------------------------------------------
Traceback (most recent call last):
  File "/home/nadeemramli/workspace/github.com/nadeemramli/mapping-of-metrics/metric-map-app/backend/metricMapAPI/metrics/tests/test_apis.py", line 22, in setUp
    self.client.force_authenticate(user=self.user)
AttributeError: 'Client' object has no attribute 'force_authenticate'

======================================================================
ERROR: test_get_metric_detail (metrics.tests.test_apis.APITests)
----------------------------------------------------------------------
Traceback (most recent call last):
  File "/home/nadeemramli/workspace/github.com/nadeemramli/mapping-of-metrics/metric-map-app/backend/metricMapAPI/metrics/tests/test_apis.py", line 22, in setUp
    self.client.force_authenticate(user=self.user)
AttributeError: 'Client' object has no attribute 'force_authenticate'

======================================================================
ERROR: test_get_metric_reports (metrics.tests.test_apis.APITests)
----------------------------------------------------------------------
Traceback (most recent call last):
  File "/home/nadeemramli/workspace/github.com/nadeemramli/mapping-of-metrics/metric-map-app/backend/metricMapAPI/metrics/tests/test_apis.py", line 22, in setUp
    self.client.force_authenticate(user=self.user)
AttributeError: 'Client' object has no attribute 'force_authenticate'

======================================================================
ERROR: test_get_metric_targets (metrics.tests.test_apis.APITests)
----------------------------------------------------------------------
Traceback (most recent call last):
  File "/home/nadeemramli/workspace/github.com/nadeemramli/mapping-of-metrics/metric-map-app/backend/metricMapAPI/metrics/tests/test_apis.py", line 22, in setUp
    self.client.force_authenticate(user=self.user)
AttributeError: 'Client' object has no attribute 'force_authenticate'

======================================================================
ERROR: test_get_metrics_list (metrics.tests.test_apis.APITests)
----------------------------------------------------------------------
Traceback (most recent call last):
  File "/home/nadeemramli/workspace/github.com/nadeemramli/mapping-of-metrics/metric-map-app/backend/metricMapAPI/metrics/tests/test_apis.py", line 22, in setUp
    self.client.force_authenticate(user=self.user)
AttributeError: 'Client' object has no attribute 'force_authenticate'

======================================================================
ERROR: test_get_project_detail (metrics.tests.test_apis.APITests)
----------------------------------------------------------------------
Traceback (most recent call last):
  File "/home/nadeemramli/workspace/github.com/nadeemramli/mapping-of-metrics/metric-map-app/backend/metricMapAPI/metrics/tests/test_apis.py", line 22, in setUp
    self.client.force_authenticate(user=self.user)
AttributeError: 'Client' object has no attribute 'force_authenticate'

======================================================================
ERROR: test_get_projects_list (metrics.tests.test_apis.APITests)
----------------------------------------------------------------------
Traceback (most recent call last):
  File "/home/nadeemramli/workspace/github.com/nadeemramli/mapping-of-metrics/metric-map-app/backend/metricMapAPI/metrics/tests/test_apis.py", line 22, in setUp
    self.client.force_authenticate(user=self.user)
AttributeError: 'Client' object has no attribute 'force_authenticate'

======================================================================
ERROR: test_get_reports (metrics.tests.test_apis.APITests)
----------------------------------------------------------------------
Traceback (most recent call last):
  File "/home/nadeemramli/workspace/github.com/nadeemramli/mapping-of-metrics/metric-map-app/backend/metricMapAPI/metrics/tests/test_apis.py", line 22, in setUp
    self.client.force_authenticate(user=self.user)
AttributeError: 'Client' object has no attribute 'force_authenticate'

======================================================================
ERROR: test_get_tags (metrics.tests.test_apis.APITests)
----------------------------------------------------------------------
Traceback (most recent call last):
  File "/home/nadeemramli/workspace/github.com/nadeemramli/mapping-of-metrics/metric-map-app/backend/metricMapAPI/metrics/tests/test_apis.py", line 22, in setUp
    self.client.force_authenticate(user=self.user)
AttributeError: 'Client' object has no attribute 'force_authenticate'

======================================================================
ERROR: test_get_targets (metrics.tests.test_apis.APITests)
----------------------------------------------------------------------
Traceback (most recent call last):
  File "/home/nadeemramli/workspace/github.com/nadeemramli/mapping-of-metrics/metric-map-app/backend/metricMapAPI/metrics/tests/test_apis.py", line 22, in setUp
    self.client.force_authenticate(user=self.user)
AttributeError: 'Client' object has no attribute 'force_authenticate'

======================================================================
ERROR: test_health_check (metrics.tests.test_apis.APITests)
----------------------------------------------------------------------
Traceback (most recent call last):
  File "/home/nadeemramli/workspace/github.com/nadeemramli/mapping-of-metrics/metric-map-app/backend/metricMapAPI/metrics/tests/test_apis.py", line 22, in setUp
    self.client.force_authenticate(user=self.user)
AttributeError: 'Client' object has no attribute 'force_authenticate'

======================================================================
ERROR: test_metric_serializer (metrics.tests.test_apis.APITests)
----------------------------------------------------------------------
Traceback (most recent call last):
  File "/home/nadeemramli/workspace/github.com/nadeemramli/mapping-of-metrics/metric-map-app/backend/metricMapAPI/metrics/tests/test_apis.py", line 22, in setUp
    self.client.force_authenticate(user=self.user)
AttributeError: 'Client' object has no attribute 'force_authenticate'

======================================================================
ERROR: test_project_serializer (metrics.tests.test_apis.APITests)
----------------------------------------------------------------------
Traceback (most recent call last):
  File "/home/nadeemramli/workspace/github.com/nadeemramli/mapping-of-metrics/metric-map-app/backend/metricMapAPI/metrics/tests/test_apis.py", line 22, in setUp
    self.client.force_authenticate(user=self.user)
AttributeError: 'Client' object has no attribute 'force_authenticate'

======================================================================
ERROR: test_update_metric (metrics.tests.test_apis.APITests)
----------------------------------------------------------------------
Traceback (most recent call last):
  File "/home/nadeemramli/workspace/github.com/nadeemramli/mapping-of-metrics/metric-map-app/backend/metricMapAPI/metrics/tests/test_apis.py", line 22, in setUp
    self.client.force_authenticate(user=self.user)
AttributeError: 'Client' object has no attribute 'force_authenticate'

======================================================================
ERROR: test_url_patterns (metrics.tests.test_apis.APITests)
----------------------------------------------------------------------
Traceback (most recent call last):
  File "/home/nadeemramli/workspace/github.com/nadeemramli/mapping-of-metrics/metric-map-app/backend/metricMapAPI/metrics/tests/test_apis.py", line 22, in setUp
    self.client.force_authenticate(user=self.user)
AttributeError: 'Client' object has no attribute 'force_authenticate'

----------------------------------------------------------------------
Ran 30 tests in 5.658s

FAILED (errors=30)

Test Result: Failure
Errors: 30
Failures: 0
