Ran 30 tests in 0.876 seconds

=== Starting migration
Operations to perform:
  Apply all migrations: admin, auth, authtoken, contenttypes, metrics, sessions
Running migrations:
  Applying contenttypes.0001_initial...
 OK
  Applying auth.0001_initial...
 OK
  Applying admin.0001_initial...
 OK
  Applying admin.0002_logentry_remove_auto_add...
 OK
  Applying admin.0003_logentry_add_action_flag_choices...
 OK
  Applying contenttypes.0002_remove_content_type_name...
 OK
  Applying auth.0002_alter_permission_name_max_length...
 OK
  Applying auth.0003_alter_user_email_max_length...
 OK
  Applying auth.0004_alter_user_username_opts...
 OK
  Applying auth.0005_alter_user_last_login_null...
 OK
  Applying auth.0006_require_contenttypes_0002...
 OK
  Applying auth.0007_alter_validators_add_error_messages...
 OK
  Applying auth.0008_alter_user_username_max_length...
 OK
  Applying auth.0009_alter_user_last_name_max_length...
 OK
  Applying auth.0010_alter_group_name_max_length...
 OK
  Applying auth.0011_update_proxy_permissions...
 OK
  Applying auth.0012_alter_user_first_name_max_length...
 OK
  Applying authtoken.0001_initial...
 OK
  Applying authtoken.0002_auto_20160226_1747...
 OK
  Applying authtoken.0003_tokenproxy...
 OK
  Applying authtoken.0004_alter_tokenproxy_options...
 OK
  Applying metrics.0001_initial...
 OK
  Applying metrics.0002_alter_actionremark_tenant_alter_anomaly_tenant_and_more...
 OK
  Applying sessions.0001_initial...
 OK
E
======================================================================
ERROR: setUpClass (metrics.tests.test_apis.APITests)
----------------------------------------------------------------------
Traceback (most recent call last):
  File "/home/nadeemramli/.pyenv/versions/3.10.7/lib/python3.10/site-packages/django/db/backends/utils.py", line 105, in _execute
    return self.cursor.execute(sql, params)
psycopg2.errors.UniqueViolation: duplicate key value violates unique constraint "metrics_client_schema_name_key"
DETAIL:  Key (schema_name)=(test) already exists.


The above exception was the direct cause of the following exception:

Traceback (most recent call last):
  File "/home/nadeemramli/workspace/github.com/nadeemramli/mapping-of-metrics/metric-map-app/backend/metricMapAPI/metrics/tests/test_utils.py", line 80, in setUpClass
    super().setUpClass()
  File "/home/nadeemramli/.pyenv/versions/3.10.7/lib/python3.10/site-packages/django_tenants/test/cases.py", line 38, in setUpClass
    cls.tenant.save(verbosity=cls.get_verbosity())
  File "/home/nadeemramli/.pyenv/versions/3.10.7/lib/python3.10/site-packages/django_tenants/models.py", line 107, in save
    super().save(*args, **kwargs)
  File "/home/nadeemramli/.pyenv/versions/3.10.7/lib/python3.10/site-packages/django/db/models/base.py", line 822, in save
    self.save_base(
  File "/home/nadeemramli/.pyenv/versions/3.10.7/lib/python3.10/site-packages/django/db/models/base.py", line 909, in save_base
    updated = self._save_table(
  File "/home/nadeemramli/.pyenv/versions/3.10.7/lib/python3.10/site-packages/django/db/models/base.py", line 1071, in _save_table
    results = self._do_insert(
  File "/home/nadeemramli/.pyenv/versions/3.10.7/lib/python3.10/site-packages/django/db/models/base.py", line 1112, in _do_insert
    return manager._insert(
  File "/home/nadeemramli/.pyenv/versions/3.10.7/lib/python3.10/site-packages/django/db/models/manager.py", line 87, in manager_method
    return getattr(self.get_queryset(), name)(*args, **kwargs)
  File "/home/nadeemramli/.pyenv/versions/3.10.7/lib/python3.10/site-packages/django/db/models/query.py", line 1847, in _insert
    return query.get_compiler(using=using).execute_sql(returning_fields)
  File "/home/nadeemramli/.pyenv/versions/3.10.7/lib/python3.10/site-packages/django/db/models/sql/compiler.py", line 1823, in execute_sql
    cursor.execute(sql, params)
  File "/home/nadeemramli/.pyenv/versions/3.10.7/lib/python3.10/site-packages/django/db/backends/utils.py", line 79, in execute
    return self._execute_with_wrappers(
  File "/home/nadeemramli/.pyenv/versions/3.10.7/lib/python3.10/site-packages/django/db/backends/utils.py", line 92, in _execute_with_wrappers
    return executor(sql, params, many, context)
  File "/home/nadeemramli/.pyenv/versions/3.10.7/lib/python3.10/site-packages/django/db/backends/utils.py", line 100, in _execute
    with self.db.wrap_database_errors:
  File "/home/nadeemramli/.pyenv/versions/3.10.7/lib/python3.10/site-packages/django/db/utils.py", line 91, in __exit__
    raise dj_exc_value.with_traceback(traceback) from exc_value
  File "/home/nadeemramli/.pyenv/versions/3.10.7/lib/python3.10/site-packages/django/db/backends/utils.py", line 105, in _execute
    return self.cursor.execute(sql, params)
django.db.utils.IntegrityError: duplicate key value violates unique constraint "metrics_client_schema_name_key"
DETAIL:  Key (schema_name)=(test) already exists.


----------------------------------------------------------------------
Ran 0 tests in 0.876s

FAILED (errors=1)

Test Result: Failure
Errors: 1
Failures: 0
