Ran 30 tests in 8.930 seconds

FFEFFFFFFFFFFEFFFFFFEEFFFF.FFF
======================================================================
ERROR: test_create_action_remark (metrics.tests.test_apis.APITests)
----------------------------------------------------------------------
Traceback (most recent call last):
  File "/home/nadeemramli/workspace/github.com/nadeemramli/mapping-of-metrics/metric-map-app/backend/metricMapAPI/metrics/tests/test_apis.py", line 137, in test_create_action_remark
    url = self.get_client_project_url('metric-action_remarks', pk=self.metric.pk)
  File "/home/nadeemramli/workspace/github.com/nadeemramli/mapping-of-metrics/metric-map-app/backend/metricMapAPI/metrics/tests/test_apis.py", line 39, in get_client_project_url
    return reverse(viewname, kwargs={'client__pk': client_pk, 'project__pk': project_pk, **kwargs})
  File "/home/nadeemramli/.pyenv/versions/3.10.7/lib/python3.10/site-packages/django/urls/base.py", line 88, in reverse
    return resolver._reverse_with_prefix(view, prefix, *args, **kwargs)
  File "/home/nadeemramli/.pyenv/versions/3.10.7/lib/python3.10/site-packages/django/urls/resolvers.py", line 851, in _reverse_with_prefix
    raise NoReverseMatch(msg)
django.urls.exceptions.NoReverseMatch: Reverse for 'metric-action_remarks' not found. 'metric-action_remarks' is not a valid view function or pattern name.

======================================================================
ERROR: test_get_historical_data (metrics.tests.test_apis.APITests)
----------------------------------------------------------------------
Traceback (most recent call last):
  File "/home/nadeemramli/workspace/github.com/nadeemramli/mapping-of-metrics/metric-map-app/backend/metricMapAPI/metrics/tests/test_apis.py", line 112, in test_get_historical_data
    url = self.get_client_project_url('historical_data', metric_pk=self.metric.pk)
  File "/home/nadeemramli/workspace/github.com/nadeemramli/mapping-of-metrics/metric-map-app/backend/metricMapAPI/metrics/tests/test_apis.py", line 39, in get_client_project_url
    return reverse(viewname, kwargs={'client__pk': client_pk, 'project__pk': project_pk, **kwargs})
  File "/home/nadeemramli/.pyenv/versions/3.10.7/lib/python3.10/site-packages/django/urls/base.py", line 88, in reverse
    return resolver._reverse_with_prefix(view, prefix, *args, **kwargs)
  File "/home/nadeemramli/.pyenv/versions/3.10.7/lib/python3.10/site-packages/django/urls/resolvers.py", line 851, in _reverse_with_prefix
    raise NoReverseMatch(msg)
django.urls.exceptions.NoReverseMatch: Reverse for 'historical_data' not found. 'historical_data' is not a valid view function or pattern name.

======================================================================
ERROR: test_get_project_detail (metrics.tests.test_apis.APITests)
----------------------------------------------------------------------
Traceback (most recent call last):
  File "/home/nadeemramli/workspace/github.com/nadeemramli/mapping-of-metrics/metric-map-app/backend/metricMapAPI/metrics/tests/test_apis.py", line 60, in test_get_project_detail
    url = self.get_client_project_url('project-detail')
  File "/home/nadeemramli/workspace/github.com/nadeemramli/mapping-of-metrics/metric-map-app/backend/metricMapAPI/metrics/tests/test_apis.py", line 39, in get_client_project_url
    return reverse(viewname, kwargs={'client__pk': client_pk, 'project__pk': project_pk, **kwargs})
  File "/home/nadeemramli/.pyenv/versions/3.10.7/lib/python3.10/site-packages/django/urls/base.py", line 88, in reverse
    return resolver._reverse_with_prefix(view, prefix, *args, **kwargs)
  File "/home/nadeemramli/.pyenv/versions/3.10.7/lib/python3.10/site-packages/django/urls/resolvers.py", line 851, in _reverse_with_prefix
    raise NoReverseMatch(msg)
django.urls.exceptions.NoReverseMatch: Reverse for 'project-detail' with keyword arguments '{'client__pk': 22, 'project__pk': 21}' not found. 6 pattern(s) tried: ['api/clients/(?P<client__pk>[^/.]+)/projects/(?P<pk>[^/.]+)/$', 'api/clients/(?P<client__pk>[^/.]+)/projects/(?P<pk>[^/.]+)/$', 'api/clients/(?P<client__pk>[^/.]+)/projects/(?P<pk>[^/.]+)/$', 'api/clients/(?P<client__pk>[^/.]+)/projects/(?P<pk>[^/.]+)/$', 'api/clients/(?P<client__pk>[^/.]+)/projects/(?P<pk>[^/.]+)/$', 'api/clients/(?P<client__pk>[^/.]+)/projects/(?P<pk>[^/.]+)/$']

======================================================================
ERROR: test_get_projects_list (metrics.tests.test_apis.APITests)
----------------------------------------------------------------------
Traceback (most recent call last):
  File "/home/nadeemramli/workspace/github.com/nadeemramli/mapping-of-metrics/metric-map-app/backend/metricMapAPI/metrics/tests/test_apis.py", line 54, in test_get_projects_list
    url = self.get_client_project_url('project-list')
  File "/home/nadeemramli/workspace/github.com/nadeemramli/mapping-of-metrics/metric-map-app/backend/metricMapAPI/metrics/tests/test_apis.py", line 39, in get_client_project_url
    return reverse(viewname, kwargs={'client__pk': client_pk, 'project__pk': project_pk, **kwargs})
  File "/home/nadeemramli/.pyenv/versions/3.10.7/lib/python3.10/site-packages/django/urls/base.py", line 88, in reverse
    return resolver._reverse_with_prefix(view, prefix, *args, **kwargs)
  File "/home/nadeemramli/.pyenv/versions/3.10.7/lib/python3.10/site-packages/django/urls/resolvers.py", line 851, in _reverse_with_prefix
    raise NoReverseMatch(msg)
django.urls.exceptions.NoReverseMatch: Reverse for 'project-list' with keyword arguments '{'client__pk': 23, 'project__pk': 22}' not found. 6 pattern(s) tried: ['api/clients/(?P<client__pk>[^/.]+)/projects/$', 'api/clients/(?P<client__pk>[^/.]+)/projects/$', 'api/clients/(?P<client__pk>[^/.]+)/projects/$', 'api/clients/(?P<client__pk>[^/.]+)/projects/$', 'api/clients/(?P<client__pk>[^/.]+)/projects/$', 'api/clients/(?P<client__pk>[^/.]+)/projects/$']

======================================================================
FAIL: test_analyze_metric (metrics.tests.test_apis.APITests)
----------------------------------------------------------------------
Traceback (most recent call last):
  File "/home/nadeemramli/workspace/github.com/nadeemramli/mapping-of-metrics/metric-map-app/backend/metricMapAPI/metrics/tests/test_apis.py", line 122, in test_analyze_metric
    response = self.client.post(url, data)
  File "/home/nadeemramli/.pyenv/versions/3.10.7/lib/python3.10/site-packages/rest_framework/test.py", line 295, in post
    response = super().post(
  File "/home/nadeemramli/.pyenv/versions/3.10.7/lib/python3.10/site-packages/rest_framework/test.py", line 208, in post
    data, content_type = self._encode_data(data, format, content_type)
  File "/home/nadeemramli/.pyenv/versions/3.10.7/lib/python3.10/site-packages/rest_framework/test.py", line 179, in _encode_data
    ret = renderer.render(data)
  File "/home/nadeemramli/.pyenv/versions/3.10.7/lib/python3.10/site-packages/rest_framework/renderers.py", line 911, in render
    assert not isinstance(value, dict), (
AssertionError: Test data contained a dictionary value for key 'params', but multipart uploads do not support nested data. You may want to consider using format='json' in this test case.

======================================================================
FAIL: test_authentication_required (metrics.tests.test_apis.APITests)
----------------------------------------------------------------------
Traceback (most recent call last):
  File "/home/nadeemramli/workspace/github.com/nadeemramli/mapping-of-metrics/metric-map-app/backend/metricMapAPI/metrics/tests/test_apis.py", line 253, in test_authentication_required
    self.assertEqual(response.status_code, status.HTTP_401_UNAUTHORIZED)
AssertionError: 404 != 401

======================================================================
FAIL: test_create_dashboard (metrics.tests.test_apis.APITests)
----------------------------------------------------------------------
Traceback (most recent call last):
  File "/home/nadeemramli/workspace/github.com/nadeemramli/mapping-of-metrics/metric-map-app/backend/metricMapAPI/metrics/tests/test_apis.py", line 166, in test_create_dashboard
    response = self.client.post(url, data)
  File "/home/nadeemramli/.pyenv/versions/3.10.7/lib/python3.10/site-packages/rest_framework/test.py", line 295, in post
    response = super().post(
  File "/home/nadeemramli/.pyenv/versions/3.10.7/lib/python3.10/site-packages/rest_framework/test.py", line 208, in post
    data, content_type = self._encode_data(data, format, content_type)
  File "/home/nadeemramli/.pyenv/versions/3.10.7/lib/python3.10/site-packages/rest_framework/test.py", line 179, in _encode_data
    ret = renderer.render(data)
  File "/home/nadeemramli/.pyenv/versions/3.10.7/lib/python3.10/site-packages/rest_framework/renderers.py", line 911, in render
    assert not isinstance(value, dict), (
AssertionError: Test data contained a dictionary value for key 'layout', but multipart uploads do not support nested data. You may want to consider using format='json' in this test case.

======================================================================
FAIL: test_create_experiment (metrics.tests.test_apis.APITests)
----------------------------------------------------------------------
Traceback (most recent call last):
  File "/home/nadeemramli/workspace/github.com/nadeemramli/mapping-of-metrics/metric-map-app/backend/metricMapAPI/metrics/tests/test_apis.py", line 183, in test_create_experiment
    self.assertEqual(response.status_code, status.HTTP_201_CREATED)
AssertionError: 404 != 201

======================================================================
FAIL: test_create_metric (metrics.tests.test_apis.APITests)
----------------------------------------------------------------------
Traceback (most recent call last):
  File "/home/nadeemramli/workspace/github.com/nadeemramli/mapping-of-metrics/metric-map-app/backend/metricMapAPI/metrics/tests/test_apis.py", line 88, in test_create_metric
    self.assertEqual(response.status_code, status.HTTP_201_CREATED)
AssertionError: 404 != 201

======================================================================
FAIL: test_delete_metric (metrics.tests.test_apis.APITests)
----------------------------------------------------------------------
Traceback (most recent call last):
  File "/home/nadeemramli/workspace/github.com/nadeemramli/mapping-of-metrics/metric-map-app/backend/metricMapAPI/metrics/tests/test_apis.py", line 108, in test_delete_metric
    self.assertEqual(response.status_code, status.HTTP_204_NO_CONTENT)
AssertionError: 404 != 204

======================================================================
FAIL: test_get_categories (metrics.tests.test_apis.APITests)
----------------------------------------------------------------------
Traceback (most recent call last):
  File "/home/nadeemramli/workspace/github.com/nadeemramli/mapping-of-metrics/metric-map-app/backend/metricMapAPI/metrics/tests/test_apis.py", line 188, in test_get_categories
    self.assertEqual(response.status_code, status.HTTP_200_OK)
AssertionError: 404 != 200

======================================================================
FAIL: test_get_client_detail (metrics.tests.test_apis.APITests)
----------------------------------------------------------------------
Traceback (most recent call last):
  File "/home/nadeemramli/workspace/github.com/nadeemramli/mapping-of-metrics/metric-map-app/backend/metricMapAPI/metrics/tests/test_apis.py", line 50, in test_get_client_detail
    self.assertEqual(response.status_code, status.HTTP_200_OK)
AssertionError: 404 != 200

======================================================================
FAIL: test_get_clients_list (metrics.tests.test_apis.APITests)
----------------------------------------------------------------------
Traceback (most recent call last):
  File "/home/nadeemramli/workspace/github.com/nadeemramli/mapping-of-metrics/metric-map-app/backend/metricMapAPI/metrics/tests/test_apis.py", line 44, in test_get_clients_list
    self.assertEqual(response.status_code, status.HTTP_200_OK)
AssertionError: 404 != 200

======================================================================
FAIL: test_get_connections (metrics.tests.test_apis.APITests)
----------------------------------------------------------------------
Traceback (most recent call last):
  File "/home/nadeemramli/workspace/github.com/nadeemramli/mapping-of-metrics/metric-map-app/backend/metricMapAPI/metrics/tests/test_apis.py", line 198, in test_get_connections
    self.assertEqual(response.status_code, status.HTTP_200_OK)
AssertionError: 404 != 200

======================================================================
FAIL: test_get_dashboards (metrics.tests.test_apis.APITests)
----------------------------------------------------------------------
Traceback (most recent call last):
  File "/home/nadeemramli/workspace/github.com/nadeemramli/mapping-of-metrics/metric-map-app/backend/metricMapAPI/metrics/tests/test_apis.py", line 158, in test_get_dashboards
    self.assertEqual(response.status_code, status.HTTP_200_OK)
AssertionError: 404 != 200

======================================================================
FAIL: test_get_experiments (metrics.tests.test_apis.APITests)
----------------------------------------------------------------------
Traceback (most recent call last):
  File "/home/nadeemramli/workspace/github.com/nadeemramli/mapping-of-metrics/metric-map-app/backend/metricMapAPI/metrics/tests/test_apis.py", line 172, in test_get_experiments
    self.assertEqual(response.status_code, status.HTTP_200_OK)
AssertionError: 404 != 200

======================================================================
FAIL: test_get_metric_action_remarks (metrics.tests.test_apis.APITests)
----------------------------------------------------------------------
Traceback (most recent call last):
  File "/home/nadeemramli/workspace/github.com/nadeemramli/mapping-of-metrics/metric-map-app/backend/metricMapAPI/metrics/tests/test_apis.py", line 134, in test_get_metric_action_remarks
    self.assertEqual(response.status_code, status.HTTP_200_OK)
AssertionError: 404 != 200

======================================================================
FAIL: test_get_metric_connections (metrics.tests.test_apis.APITests)
----------------------------------------------------------------------
Traceback (most recent call last):
  File "/home/nadeemramli/workspace/github.com/nadeemramli/mapping-of-metrics/metric-map-app/backend/metricMapAPI/metrics/tests/test_apis.py", line 129, in test_get_metric_connections
    self.assertEqual(response.status_code, status.HTTP_200_OK)
AssertionError: 404 != 200

======================================================================
FAIL: test_get_metric_detail (metrics.tests.test_apis.APITests)
----------------------------------------------------------------------
Traceback (most recent call last):
  File "/home/nadeemramli/workspace/github.com/nadeemramli/mapping-of-metrics/metric-map-app/backend/metricMapAPI/metrics/tests/test_apis.py", line 74, in test_get_metric_detail
    self.assertEqual(response.status_code, status.HTTP_200_OK)
AssertionError: 404 != 200

======================================================================
FAIL: test_get_metric_reports (metrics.tests.test_apis.APITests)
----------------------------------------------------------------------
Traceback (most recent call last):
  File "/home/nadeemramli/workspace/github.com/nadeemramli/mapping-of-metrics/metric-map-app/backend/metricMapAPI/metrics/tests/test_apis.py", line 153, in test_get_metric_reports
    self.assertEqual(response.status_code, status.HTTP_200_OK)
AssertionError: 404 != 200

======================================================================
FAIL: test_get_metric_targets (metrics.tests.test_apis.APITests)
----------------------------------------------------------------------
Traceback (most recent call last):
  File "/home/nadeemramli/workspace/github.com/nadeemramli/mapping-of-metrics/metric-map-app/backend/metricMapAPI/metrics/tests/test_apis.py", line 148, in test_get_metric_targets
    self.assertEqual(response.status_code, status.HTTP_200_OK)
AssertionError: 404 != 200

======================================================================
FAIL: test_get_metrics_list (metrics.tests.test_apis.APITests)
----------------------------------------------------------------------
Traceback (most recent call last):
  File "/home/nadeemramli/workspace/github.com/nadeemramli/mapping-of-metrics/metric-map-app/backend/metricMapAPI/metrics/tests/test_apis.py", line 68, in test_get_metrics_list
    self.assertEqual(response.status_code, status.HTTP_200_OK)
AssertionError: 404 != 200

======================================================================
FAIL: test_get_reports (metrics.tests.test_apis.APITests)
----------------------------------------------------------------------
Traceback (most recent call last):
  File "/home/nadeemramli/workspace/github.com/nadeemramli/mapping-of-metrics/metric-map-app/backend/metricMapAPI/metrics/tests/test_apis.py", line 208, in test_get_reports
    self.assertEqual(response.status_code, status.HTTP_200_OK)
AssertionError: 404 != 200

======================================================================
FAIL: test_get_tags (metrics.tests.test_apis.APITests)
----------------------------------------------------------------------
Traceback (most recent call last):
  File "/home/nadeemramli/workspace/github.com/nadeemramli/mapping-of-metrics/metric-map-app/backend/metricMapAPI/metrics/tests/test_apis.py", line 193, in test_get_tags
    self.assertEqual(response.status_code, status.HTTP_200_OK)
AssertionError: 404 != 200

======================================================================
FAIL: test_get_targets (metrics.tests.test_apis.APITests)
----------------------------------------------------------------------
Traceback (most recent call last):
  File "/home/nadeemramli/workspace/github.com/nadeemramli/mapping-of-metrics/metric-map-app/backend/metricMapAPI/metrics/tests/test_apis.py", line 203, in test_get_targets
    self.assertEqual(response.status_code, status.HTTP_200_OK)
AssertionError: 404 != 200

======================================================================
FAIL: test_health_check (metrics.tests.test_apis.APITests)
----------------------------------------------------------------------
Traceback (most recent call last):
  File "/home/nadeemramli/workspace/github.com/nadeemramli/mapping-of-metrics/metric-map-app/backend/metricMapAPI/metrics/tests/test_apis.py", line 213, in test_health_check
    self.assertEqual(response.status_code, status.HTTP_200_OK)
AssertionError: 404 != 200

======================================================================
FAIL: test_project_serializer (metrics.tests.test_apis.APITests)
----------------------------------------------------------------------
Traceback (most recent call last):
  File "/home/nadeemramli/workspace/github.com/nadeemramli/mapping-of-metrics/metric-map-app/backend/metricMapAPI/metrics/tests/test_apis.py", line 229, in test_project_serializer
    self.assertEqual(data['tenant'], self.tenant.id)
AssertionError: 29 != 1

======================================================================
FAIL: test_update_metric (metrics.tests.test_apis.APITests)
----------------------------------------------------------------------
Traceback (most recent call last):
  File "/home/nadeemramli/workspace/github.com/nadeemramli/mapping-of-metrics/metric-map-app/backend/metricMapAPI/metrics/tests/test_apis.py", line 102, in test_update_metric
    self.assertEqual(response.status_code, status.HTTP_200_OK)
AssertionError: 404 != 200

======================================================================
FAIL: test_url_patterns (metrics.tests.test_apis.APITests)
----------------------------------------------------------------------
Traceback (most recent call last):
  File "/home/nadeemramli/workspace/github.com/nadeemramli/mapping-of-metrics/metric-map-app/backend/metricMapAPI/metrics/tests/test_apis.py", line 232, in test_url_patterns
    self.assertEqual(
AssertionError: '/api/clients/31/projects/30/metrics/' != '/api/clients/1/projects/30/metrics/'
- /api/clients/31/projects/30/metrics/
?              -
+ /api/clients/1/projects/30/metrics/


----------------------------------------------------------------------
Ran 30 tests in 8.930s

FAILED (failures=25, errors=4)

Test Result: Failure
Errors: 4
Failures: 25
